Workbook
Name Large_scale_classification: [1]Sheet3!$C$4:$C$10

Sheet 통장내역(환율표)
B2: 통장 일자 | C2: 지급 | F2: 송금액 | I2: 입금 | K2: 출금 | M2: 잔액
C3: 지급시 환율 | D3: 환산요율 | E3: 전표번호 | F3: USD | G3: 수수료 | H3: RMB | I3: USD | J3: RMB | K3: USD | L3: RMB | M3: USD | N3: RMB
B4: 44630 | M4: 0.07 | N4: 0.15
F5: 9850.62 | N5: =N4+H5+J5-L5 -> 0.15
B6: 44631 | C6: 1234.5 | D6: =-H6/F6 -> 6.3620454 | E6: 2000003023 | F6: -9820.62 | H6: 62479.23 | K6: 30 | N6: =N5+H6+J6-L6 -> 62479.38
B7: 44635 | L7: 55440 | N7: =N6+H7+J7-L7 -> 7039.38
B8: 44641 | I8: 0.055013754 | J8: 0.35 | N8: =N7+H8+J8-L8 -> 7039.73
B9: 44648 | I9: 4274.5 | J9: 27194.532 | N9: =N8+H9+J9-L9 -> 34234.262
B10: 44648 | L10: 4654.536 | N10: =N9+H10+J10-L10 -> 29579.726
B11: 44649 | F11: 8777 | N11: =N10+H11+J11-L11 -> 29579.726
B12: 44649 | C12: 1218.3 | D12: =-H12/F12 -> 6.3468001 | E12: 2000003673 | F12: -8719 | H12: 55337.75 | K12: 58 | N12: =N11+H12+J12-L12 -> 84917.476
B13: 44650 | L13: 1680 | N13: =N12+H13+J13-L13 -> 83237.476
N14: =N13 -> 83237.476
B15: 44671 | L15: 19440 | N15: =N14+H15+J15-L15 -> 63797.476
B16: 44675 | L16: 18226.67 | N16: =N15+H16+J16-L16 -> 45570.806
N17: =N16 -> 45570.806
B18: 44692 | C18: 1274.6 | D18: =-H18/F18 -> 6.7025994 | E18: 2000006339 | F18: -2459.78 | H18: 16486.92 | K18: 28 | N18: =N17+H18+J18-L18 -> 62057.726
B19: 44692 | L19: 97 | N19: =N18+H19+J19-L19 -> 61960.726
B20: 44705 | L20: 44055.69 | N20: =N19+H20+J20-L20 -> 17905.036
B21: 44706 | L21: 1418.4423 | N21: =N20+H21+J21-L21 -> 16486.594
B22: 44706 | L22: 12240.488 | N22: =N21+H22+J22-L22 -> 4246.106
N23: =N22 -> 4246.106
B24: 44725 | C24: 1257.6 | F24: 20524.31 | N24: =N23+H24+J24-L24 -> 4246.106
B25: 44725 | D25: =-H25/F25 -> 6.7188954 | E25: 2000007883 | F25: -20498.31 | H25: 137726 | K25: 26 | N25: =N24+H25+J25-L25 -> 141972.11
B26: 44733 | J26: 19.83 | N26: =N25+H26+J26-L26 -> 141991.94
B27: 44737 | L27: 4266.2623 | N27: =N26+H27+J27-L27 -> 137725.67
B28: 44737 | L28: 111230.26 | N28: =N27+H28+J28-L28 -> 26495.416
B29: 44739 | L29: 25271.2 | N29: =N28+H29+J29-L29 -> 1224.216
B30: 44740 | L30: 503.6 | N30: =N29+H30+J30-L30 -> 720.61599
N31: =N30 -> 720.61599
B32: 44754 | C32: 1299.3 | F32: 35786.57 | N32: =N31+H32+J32-L32 -> 720.61599
B33: 44754 | D33: =-H33/F33 -> 6.7115049 | E33: 2000009582 | F33: -35760.57 | H33: 240007.24 | K33: 26 | N33: =N32+H33+J33-L33 -> 240727.86
B34: 44756 | L34: 719.1937 | N34: =N33+H34+J34-L34 -> 240008.66
B35: 44756 | L35: 10664.826 | N35: =N34+H35+J35-L35 -> 229343.84
B36: 44757 | L36: 137638.72 | N36: =N35+H36+J36-L36 -> 91705.116
B37: 44760 | L37: 51267.92 | N37: =N36+H37+J37-L37 -> 40437.196
B38: 44763 | L38: 24157.11 | N38: =N37+H38+J38-L38 -> 16280.086
N39: =N38 -> 16280.086
B40: 44784 | C40: 1305.1 | F40: 23963.94 | N40: =N39+H40+J40-L40 -> 16280.086
B41: 44784 | D41: =-H41/F41 -> 6.7186759 | E41: 2000011142 | F41: -23937.94 | H41: 160831.26 | K41: 26 | N41: =N40+H41+J41-L41 -> 177111.35
...

Sheet 내역_22.03
A1: 3월 전도금 사용 내역 | K1: 100066029
A2: 3/10 송금 환율(1234.5) | E2: 100014054 | G2: 3/28 보증금 입금(1,274.6) | K2: 100014040 | L2: 1200000696 | M2: 3/28 송금 환율(1218.3) | Q2: 100014046
A3: 대계정 | B3: 소계정 | C3: 금액 (RMB) | D3: 금액 (USD) | E3: 금액 (KRW) | G3: 대계정 | H3: 소계정 | I3: 금액 (RMB) | J3: 금액 (USD) | K3: 금액 (KRW) | M3: 대계정 | N3: 소계정 | O3: 금액 (RMB) | P3: 금액 (USD) | Q3: 금액 (KRW)
A4: 소모품비 | G4: 소모품비 | M4: 소모품비
A5: 업무추진비 | B5: 일반 | F5: 51131050 | G5: 업무추진비 | H5: 일반 | M5: 업무추진비 | N5: 일반
A6: 여비교통비 | B6: 해외 | F6: 51061030 | G6: 여비교통비 | H6: 해외 | M6: 여비교통비 | N6: 해외
A7: 지급임차료 | B7: 사무실관리 | C7: 19440 | D7: 3055.6211 | E7: 3772163 | F7: 51201020 | G7: 지급임차료 | H7: 사무실관리 | M7: 지급임차료 | N7: 사무실관리
A8: 지급임차료 | B8: 차량임차료 | F8: 51201030 | G8: 지급임차료 | H8: 차량임차료 | M8: 지급임차료 | N8: 차량임차료
A9: 통신비 | B9: 기타 | F9: 51071700 | G9: 통신비 | H9: 기타 | L9: 89500 | M9: 통신비 | N9: 기타
A10: 해외지사비 | C10: 1680 | D10: 294.06602 | E10: 363029 | F10: 51321010 | G10: 해외지사비 | I10: 4654.536 | J10: 731.61 | K10: 903173 | M10: 해외지사비 | P10: 58 | Q10: 70661
A11: 보증금 | C11: 36000 | D11: 5658.5576 | E11: 6985492
A12: Total | C12: =SUM(C4:C11) -> 57120 | D12: =SUM(D4:D11) -> 9008.2447 | E12: =SUM(E4:E11) -> 11120684 | F12: 52981010 | G12: Total | I12: =SUM(I4:I10) -> 4654.536 | J12: =SUM(J4:J10) -> 731.61 | K12: =SUM(K4:K10) -> 903173 | M12: Total | O12: =SUM(O4:O10) -> 0 | P12: =SUM(P4:P10) -> 58 | Q12: =SUM(Q4:Q10) -> 70661
C13: =C12+I12++O12 -> 61774.536 | D13: =D12+J12++P12 -> 9797.8547 | E13: =E12+K12++Q12 -> 12094518
A14: 보증금 | B14: 13081010 | H14: =SUBTOTAL(9,H17:H39) -> 35164.135 | I14: =SUBTOTAL(9,I18:I39) -> 61774.536 | J14: =SUBTOTAL(9,J18:J39) -> 9797.8547
A15: 날짜 | B15: 내역 | D15: 증빙번호 | E15: 대계정 | F15: 소계정 | G15: 입금 | I15: 출금 | K15: 잔액 | M15: 비고
G16: RMB | H16: USD | I16: RMB | J16: USD | K16: RMB | L16: USD
A17: 44630 | B17: 기존 잔고 | E17: 잡이익 | H17: 0.07 | K17: 0.15 | L17: 0.07
A18: 44631 | B18: USD 입금 | D18: 은행 내역 참고 | G18: 62479.23 | H18: 9850.62 | K18: =K17+G18-I18 -> 62479.38 | L18: =L17+H18-J18 -> 9850.69 | M18: USD 입금 | N18: 9850.69
A19: 44635 | B19: 송금 수수료 | D19: 은행 내역 참고 | E19: 해외지사비 | J19: 30 | K19: =K18+G19-I19 -> 62479.38 | L19: =L18+H19-J19 -> 9820.69 | M19: USD->RMB 입금 | N19: =N18-J19 -> 9820.69
A20: 44635 | B20: 사무실 Rent Deposit비용 선 지불 건 | C20: 1 | D20: 계약서, 영수증 차월 제공 | E20: 보증금 | I20: 5000 | J20: =I20/'통장내역(환율표)'!$D$6 -> 785.91077 | K20: =K19+G20-I20 -> 57479.38 | L20: =L19+H20-J20 -> 9034.7792 | M20: 사무실 Rent Deposit비용 선 지불 건 | N20: =N19-J20 -> 9034.7792
A21: 44635 | B21: 사무실 Rent Deposit 잔액 | C21: 1 | D21: 계약서, 영수증 차월 제공 | E21: 보증금 | I21: 31000 | J21: =I21/'통장내역(환율표)'!$D$6 -> 4872.6468 | K21: =K20+G21-I21 -> 26479.38 | L21: =L20+H21-J21 -> 4162.1324 | M21: 사무실 Rent Deposit 잔액 | N21: =N20-J21 -> 4162.1324
A22: 44635 | B22: 사무실 Rent 비용 | C22: 1 | D22: 계약서, 영수증 차월 제공 | E22: 지급임차료 | F22: 사무실 | I22: 19440 | J22: =I22/'통장내역(환율표)'!$D$6 -> 3055.6211 | K22: =K21+G22-I22 -> 7039.38 | L22: =L21+H22-J22 -> 1106.5113 | M22: 사무실 Rent 비용 | N22: =N21-J22 -> 1106.5113
A23: 44641 | B23: 이자 | D23: 은행 내역 참고 | E23: 잡이익 | G23: 0.35 | H23: =G23/'통장내역(환율표)'!$D$6 -> 0.055013754 | K23: =K22+G23-I23 -> 7039.73 | L23: =L22+H23-J23 -> 1106.5664 | M23: 이자 | N23: =N22+H23 -> 1106.5664
A24: 44648 | B24: Deposit 입금 | G24: 27194.532 | H24: 4274.5 | K24: =K23+G24-I24 -> 34234.262 | L24: =L23+H24-J24 -> 5381.0664 | N24: =N23+H24 -> 5381.0664
A25: 44648 | B25: 주택 지원비 | E25: 해외지사비 | I25: =J25*'통장내역(환율표)'!$D$6 -> 4654.536 | J25: 731.61 | K25: =K24+G25-I25 -> 29579.726 | L25: =L24+H25-J25 -> 4649.4564 | M25: 신순연 책임 주택 지원금 | N25: =N24+H25 -> 5381.0664 | O25: =H24-J25 -> 3542.89
A26: 44649 | B26: USD 입금 | D26: 은행 내역 참고 | G26: 55337.75 | H26: 8777 | K26: =K25+G26-I26 -> 84917.476 | L26: =L25+H26-J26 -> 13426.456 | M26: USD 입금
A27: 44649 | B27: 송금 수수료 | D27: 은행 내역 참고 | E27: 해외지사비 | J27: 58 | K27: =K26+G27-I27 -> 84917.476 | L27: =L26+H27-J27 -> 13368.456 | M27: USD->RMB 입금
A28: 44650 | B28: 사무실 명판 제작 금액 | C28: 2 | D28: 첨부 영수증 참고 | E28: 해외지사비 | I28: 1680 | J28: =I28/'통장내역(환율표)'!$D$6 -> 264.06602 | K28: =K27+G28-I28 -> 83237.476 | L28: =L27+H28-J28 -> 13104.39 | M28: 사무실 명판 제작 금액 | N28: =N23-J28 -> 842.50033
H30: =H24-J25 -> 3542.89
H31: =H26-J27 -> 8719

Sheet 내역_22.04
A1: 4월 전도금 사용 내역 | K1: 100066029
A2: 3/10 송금 환율(1234.5) | E2: 100021243 | G2: 3/28 보증금 입금(1234.5) | K2: 100021244 | L2: 1200000696 | M2: 3/28 송금 환율(1218.3) | Q2: 100021246
A3: 대계정 | B3: 소계정 | C3: 금액 (RMB) | D3: 금액 (USD) | E3: 금액 (KRW) | G3: 대계정 | H3: 소계정 | I3: 금액 (RMB) | J3: 금액 (USD) | K3: 금액 (KRW) | M3: 대계정 | N3: 소계정 | O3: 금액 (RMB) | P3: 금액 (USD) | Q3: 금액 (KRW)
A4: 소모품비 | G4: 소모품비 | M4: 소모품비
A5: 업무추진비 | B5: 일반 | F5: 51131050 | G5: 업무추진비 | H5: 일반 | M5: 업무추진비 | N5: 일반
A6: 여비교통비 | B6: 해외 | F6: 51061030 | G6: 여비교통비 | H6: 해외 | M6: 여비교통비 | N6: 해외
A7: 지급임차료 | B7: 사무실관리 | C7: 5360.0253 | D7: 842.50033 | E7: 1040066 | F7: 51201020 | G7: 지급임차료 | H7: 사무실관리 | I7: 14079.975 | J7: 2213.1208 | K7: 2732097 | M7: 지급임차료 | N7: 사무실관리
A8: 지급임차료 | B8: 차량임차료 | F8: 51201030 | G8: 지급임차료 | H8: 차량임차료 | M8: 지급임차료 | N8: 차량임차료
A9: 통신비 | B9: 기타 | F9: 51071700 | G9: 통신비 | H9: 기타 | L9: 89500 | M9: 통신비 | N9: 기타
A10: 해외지사비 | F10: 51321010 | G10: 해외지사비 | I10: 8460.0523 | J10: 1329.7692 | K10: 1641601 | M10: 해외지사비 | O10: 9766.6177 | P10: 1535.138 | Q10: 1870261
A11: 보증금
A12: Total | C12: =SUM(C4:C11) -> 5360.0253 | D12: =SUM(D4:D11) -> 842.50033 | E12: =SUM(E4:E11) -> 1040066 | F12: 52981010 | G12: Total | I12: =SUM(I4:I10) -> 22540.027 | J12: =SUM(J4:J10) -> 3542.89 | K12: =SUM(K4:K10) -> 4373698 | M12: Total | O12: =SUM(O4:O10) -> 9766.6177 | P12: =SUM(P4:P10) -> 1535.138 | Q12: =SUM(Q4:Q10) -> 1870261
C13: =C12+I12++O12 -> 37666.67 | D13: =D12+J12++P12 -> 5920.5284 | E13: =E12+K12++Q12 -> 7284025
A14: 보증금 | B14: 13081010 | H14: =SUBTOTAL(9,H17:H41) -> 0 | I14: =SUBTOTAL(9,I18:I41) -> 37666.67 | J14: =SUBTOTAL(9,J18:J41) -> 5920.5284
A15: 날짜 | B15: 내역 | D15: 증빙번호 | E15: 대계정 | F15: 소계정 | G15: 입금 | I15: 출금 | K15: 잔액 | M15: 비고
G16: RMB | H16: USD | I16: RMB | J16: USD | K16: RMB | L16: USD
A17: 44650 | B17: 기존 잔고 | K17: 83237.476 | L17: 13104.39 | N17: 842.50033
A18: 4월 20일 | B18: 4월 사무실 Rent비_3/10 송금 | D18: 1 | E18: 지급임차료 | F18: 사무실관리 | I18: =J18*'통장내역(환율표)'!$D$6 -> 5360.0253 | J18: 842.50033 | K18: =K17+G18-I18 -> 77877.451 | L18: =L17+H18-J18 -> 12261.89 | M18: 4월 사무실 Rent비 | N18: =N17-J18 -> 0
A19: 4월 20일 | B19: 4월 사무실 Rent비_3/28 보증금 송금 | D19: 1 | E19: 지급임차료 | F19: 사무실관리 | I19: =19440-I18 -> 14079.975 | J19: =I19/'통장내역(환율표)'!$D$6 -> 2213.1208 | K19: =K18+G19-I19 -> 63797.476 | L19: =L18+H19-J19 -> 10048.769 | M19: 4월 사무실 Rent비 | N19: =3542.89-J19 -> 1329.7692
A20: 4월 24일 | B20: 3~4월 사무실 관리비 미납 금액 | D20: 2 | E20: 해외지사비 | I20: 1038.04 | J20: =I20/'통장내역(환율표)'!$D$6 -> 163.16136 | K20: =K19+G20-I20 -> 62759.436 | L20: =L19+H20-J20 -> 9885.6079 | M20: 3~4월 사무실 관리비 미납 금액 | N20: =N19-J20 -> 1166.6079
A21: 4월 24일 | B21: 전화기 | D21: 3 | E21: 해외지사비 | I21: 299 | J21: =I21/'통장내역(환율표)'!$D$6 -> 46.997464 | K21: =K20+G21-I21 -> 62460.436 | L21: =L20+H21-J21 -> 9838.6104 | M21: 전화기 | N21: =N20-J21 -> 1119.6104
A22: 4월 24일 | B22: Hot Pot | D22: 4 | E22: 해외지사비 | I22: 227.9 | J22: =I22/'통장내역(환율표)'!$D$6 -> 35.821813 | K22: =K21+G22-I22 -> 62232.536 | L22: =L21+H22-J22 -> 9802.7886 | M22: Hot Pot | N22: =N21-J22 -> 1083.7886
A23: 4월 24일 | B23: A4용지 및 생수 등 | D23: 5 | E23: 해외지사비 | I23: 212.41 | J23: =I23/'통장내역(환율표)'!$D$6 -> 33.387061 | K23: =K22+G23-I23 -> 62020.126 | L23: =L22+H23-J23 -> 9769.4015 | M23: A4용지 및 생수 등 | N23: =N22-J23 -> 1050.4015
A24: 4월 24일 | B24: 냉장고 | D24: 6 | E24: 해외지사비 | I24: 1798.9 | J24: =I24/'통장내역(환율표)'!$D$6 -> 282.75498 | K24: =K23+G24-I24 -> 60221.226 | L24: =L23+H24-J24 -> 9486.6466 | M24: 냉장고 | N24: =N23-J24 -> 767.64656
A25: 4월 24일 | B25: 빈프로젝트 및 막 & 막 설치 | D25: 7 | E25: 해외지사비 | I25: 3334 | J25: =I25/'통장내역(환율표)'!$D$6 -> 524.0453 | K25: =K24+G25-I25 -> 56887.226 | L25: =L24+H25-J25 -> 8962.6013 | M25: 빈프로젝트 및 막 & 막 설치 | N25: =N24-J25 -> 243.60126
A26: 4월 24일 | B26: 회의실 Table | D26: 8 | E26: 해외지사비 | I26: =J26*'통장내역(환율표)'!$D$6 -> 1549.8023 | J26: 243.60126 | K26: =K25+G26-I26 -> 55337.424 | L26: =L25+H26-J26 -> 8719 | M26: 회의실 Table | N26: =N25-J26 -> 0
A27: 4월 24일 | B27: 회의실 Table | D27: 8 | E27: 해외지사비 | I27: =2446-I26 -> 896.19774 | J27: =I27/'통장내역(환율표)'!$D$6 -> 140.86629 | K27: =K26+G27-I27 -> 54441.226 | L27: =L26+H27-J27 -> 8578.1337 | N27: =8719-J27 -> 8578.1337
A28: 4월 24일 | B28: 의자 | D28: 9 | E28: 해외지사비 | I28: 1578 | J28: =I28/'통장내역(환율표)'!$D$6 -> 248.03344 | K28: =K27+G28-I28 -> 52863.226 | L28: =L27+H28-J28 -> 8330.1003 | M28: 의자 | N28: =N27-J28 -> 8330.1003
A29: 4월 24일 | B29: 모니터(3대) | D29: 10 | E29: 해외지사비 | I29: 3747 | J29: =I29/'통장내역(환율표)'!$D$6 -> 588.96153 | K29: =K28+G29-I29 -> 49116.226 | L29: =L28+H29-J29 -> 7741.1387 | M29: 모니터(3대) | N29: =N28-J29 -> 7741.1387
A30: 4월 24일 | B30: Print기 | D30: 11 | E30: 해외지사비 | I30: 3200 | J30: =I30/'통장내역(환율표)'!$D$6 -> 502.9829 | K30: =K29+G30-I30 -> 45916.226 | L30: =L29+H30-J30 -> 7238.1558 | M30: Print기 | N30: =N29-J30 -> 7238.1558
A31: 4월 24일 | B31: 작은 책장 | D31: 12 | E31: 해외지사비 | I31: 345.42 | J31: =I31/'통장내역(환율표)'!$D$6 -> 54.29386 | K31: =K30+G31-I31 -> 45570.806 | L31: =L30+H31-J31 -> 7183.862 | M31: 작은 책장 | N31: =N30-J31 -> 7183.862

Sheet 내역_22.05
A1: 5월 전도금 사용 내역 | K1: 100066029
A2: 3/28 송금 환율(1218.3) | E2: 100027949 | G2: 4/10 송금 환율(1,274.6) | K2: 100027950 | L2: 1200000696
A3: 대계정 | B3: 소계정 | C3: 금액 (RMB) | D3: 금액 (USD) | E3: 금액 (KRW) | G3: 대계정 | H3: 소계정 | I3: 금액 (RMB) | J3: 금액 (USD) | K3: 금액 (KRW)
A4: 소모품비 | G4: 소모품비
A5: 업무추진비 | B5: 일반 | F5: 51131050 | G5: 업무추진비 | H5: 일반 | I5: 1449 | J5: 216.18478 | K5: 275543
A6: 여비교통비 | B6: 해외 | F6: 51061030 | G6: 여비교통비 | H6: 해외 | I6: 7166 | J6: 1069.1374 | K6: 1362726
A7: 지급임차료 | B7: 사무실관리 | F7: 51201020 | G7: 지급임차료 | H7: 사무실관리
A8: 지급임차료 | B8: 차량임차료 | F8: 51201030 | G8: 지급임차료 | H8: 차량임차료
A9: 통신비 | B9: 기타 | C9: 1014.56 | D9: 159.85378 | E9: 194745 | F9: 51071700 | G9: 통신비 | H9: 기타 | L9: 89500
A10: 해외지사비 | C10: 44556.572 | D10: 7024.0082 | E10: 8557351 | F10: 51321010 | G10: 해외지사비 | I10: 3625.4877 | J10: 568.90771 | K10: 725133
A11: 보증금
A12: Total | C12: =SUM(C4:C11) -> 45571.132 | D12: =SUM(D4:D11) -> 7183.862 | E12: =SUM(E4:E11) -> 8752096 | F12: 52981010 | G12: Total | I12: =SUM(I4:I10) -> 12240.488 | J12: =SUM(J4:J10) -> 1854.2299 | K12: =SUM(K4:K10) -> 2363402
C13: =C12+I12++O12 -> 57811.62 | D13: =D12+J12++P12 -> 9038.0919 | E13: =E12+K12++Q12 -> 11115498
A14: 보증금 | B14: 13081010 | H14: =SUBTOTAL(9,H17:H47) -> 2487.78 | I14: =SUBTOTAL(9,I17:I55) -> 57811.62 | J14: =SUBTOTAL(9,J17:J55) -> 9038.0919
A15: 날짜 | B15: 내역 | D15: 증빙번호 | E15: 대계정 | F15: 소계정 | G15: 입금 | I15: 출금 | K15: 잔액 | M15: 비고
G16: RMB | H16: USD | I16: RMB | J16: USD | K16: RMB | L16: USD
A17: 44681 | B17: 기존 잔고 | K17: 45570.806 | L17: 7183.862 | N17: 7183.862
B18: 4월 환율 차이 | E18: 해외지사비 | J18: 3.6874654 | K18: =K17+G18-I18 -> 45570.806 | L18: =L17+H18-J18 -> 7180.1745 | N18: =N17-J18 -> 7180.1745
B19: 기존통장 5월 외화송금 | G19: 16486.92 | H19: 2487.78 | K19: =K18+G19-I19 -> 62057.726 | L19: =L18+H19-J19 -> 9667.9545
B20: 송금수수료 | E20: 해외지사비 | J20: 28 | K20: =K19+G20-I20 -> 62057.726 | L20: =L19+H20-J20 -> 9639.9545
A21: 44692 | B21: 은행 수수료 | E21: 해외지사비 | I21: 17 | J21: =I21/'통장내역(환율표)'!$D$12 -> 2.6785151 | K21: =K20+G21-I21 -> 62040.726 | L21: =L20+H21-J21 -> 9637.276 | M21: OTP 도구 비용 | N21: =N18-J21 -> 7177.496
A22: 44692 | B22: 은행 수수료 | E22: 해외지사비 | I22: 80 | J22: =I22/'통장내역(환율표)'!$D$12 -> 12.604777 | K22: =K21+G22-I22 -> 61960.726 | L22: =L21+H22-J22 -> 9624.6712 | M22: 인증서 | N22: =N21-J22 -> 7164.8912
A23: 44705 | B23: 주재원 대행 수수료 | D23: 1 | E23: 해외지사비 | I23: 300 | J23: =I23/'통장내역(환율표)'!$D$12 -> 47.267914 | K23: =K22+G23-I23 -> 61660.726 | L23: =L22+H23-J23 -> 9577.4033 | N23: =N22-J23 -> 7117.6233
A24: 44705 | B24: 주재원 5대보험 | D24: 2 | E24: 해외지사비 | I24: 7703.4 | J24: =I24/'통장내역(환율표)'!$D$12 -> 1213.7455 | K24: =K23+G24-I24 -> 53957.326 | L24: =L23+H24-J24 -> 8363.6578 | N24: =N23-J24 -> 5903.8778
A25: 44705 | B25: 주재원 수당 | D25: 2 | E25: 해외지사비 | I25: 13500 | J25: =I25/'통장내역(환율표)'!$D$12 -> 2127.0561 | K25: =K24+G25-I25 -> 40457.326 | L25: =L24+H25-J25 -> 6236.6017 | N25: =N24-J25 -> 3776.8217
A26: 44705 | B26: 주재원 개인소득세 | D26: 2 | E26: 해외지사비 | I26: 2552.29 | J26: =I26/'통장내역(환율표)'!$D$12 -> 402.13808 | K26: =K25+G26-I26 -> 37905.036 | L26: =L25+H26-J26 -> 5834.4636 | N26: =N25-J26 -> 3374.6836
A27: 44705 | B27: 주재원 주택 수당 | D27: 2 | E27: 해외지사비 | I27: 20000 | J27: =I27/'통장내역(환율표)'!$D$12 -> 3151.1943 | K27: =K26+G27-I27 -> 17905.036 | L27: =L26+H27-J27 -> 2683.2694 | N27: =N26-J27 -> 223.48936
A28: 44706 | B28: 은행 수수료 | E28: 해외지사비 | I28: 7.2 | J28: =I28/'통장내역(환율표)'!$D$12 -> 1.1344299 | K28: =K27+G28-I28 -> 17897.836 | L28: =L27+H28-J28 -> 2682.1349 | N28: =N27-J28 -> 222.35493
A29: 44706 | B29: 통신비 | D29: 3 | E29: 통신비 | F29: 기타 | I29: 500 | J29: =I29/'통장내역(환율표)'!$D$12 -> 78.779856 | K29: =K28+G29-I29 -> 17397.836 | L29: =L28+H29-J29 -> 2603.3551 | N29: =N28-J29 -> 143.57507
A30: 44706 | B30: 은행 수수료 | E30: 해외지사비 | I30: 3.6 | J30: =I30/'통장내역(환율표)'!$D$12 -> 0.56721497 | K30: =K29+G30-I30 -> 17394.236 | L30: =L29+H30-J30 -> 2602.7879 | N30: =N29-J30 -> 143.00785
A31: 44706 | B31: 사무실 Wifi비용(3월) | D31: 4 | E31: 통신비 | F31: 기타 | I31: 115.56 | J31: =I31/'통장내역(환율표)'!$D$12 -> 18.2076 | K31: =K30+G31-I31 -> 17278.676 | L31: =L30+H31-J31 -> 2584.5803 | N31: =N30-J31 -> 124.80025
A32: 44706 | B32: 은행 수수료 | E32: 해외지사비 | I32: 3.6 | J32: =I32/'통장내역(환율표)'!$D$12 -> 0.56721497 | K32: =K31+G32-I32 -> 17275.076 | L32: =L31+H32-J32 -> 2584.013 | N32: =N31-J32 -> 124.23304
A33: 44706 | B33: 사무실 Wifi비용(4월) | D33: 5 | E33: 통신비 | F33: 기타 | I33: 399 | J33: =I33/'통장내역(환율표)'!$D$12 -> 62.866325 | K33: =K32+G33-I33 -> 16876.076 | L33: =L32+H33-J33 -> 2521.1467 | N33: =N32-J33 -> 61.366714
A34: 44706 | B34: 은행 수수료 | E34: 해외지사비 | I34: 3.6 | J34: =I34/'통장내역(환율표)'!$D$12 -> 0.56721497 | K34: =K33+G34-I34 -> 16872.476 | L34: =L33+H34-J34 -> 2520.5795 | N34: =N33-J34 -> 60.799499
A35: 44706 | B35: 사무실 물/전기/에어컨 비용(4월) | D35: 6 | E35: 해외지사비 | I35: 368.47 | J35: =I35/'통장내역(환율표)'!$D$12 -> 58.056027 | K35: =K34+G35-I35 -> 16504.006 | L35: =L34+H35-J35 -> 2462.5235 | N35: =N34-J35 -> 2.7434712
A36: 44706 | B36: 은행 수수료 | E36: 해외지사비 | I36: 3.6 | J36: =I36/'통장내역(환율표)'!$D$12 -> 0.56721497 | K36: =K35+G36-I36 -> 16500.406 | L36: =L35+H36-J36 -> 2461.9563 | N36: =N35-J36 -> 2.1762563
A37: 44706 | B37: 사무실 청소비(5월)_3월 환율 | D37: 7 | E37: 해외지사비 | I37: =J37*'통장내역(환율표)'!$D$12 -> 13.812264 | J37: 2.1762563 | K37: =K36+G37-I37 -> 16486.594 | L37: =L36+H37-J37 -> 2459.78 | N37: =N36-J37 -> 0
A38: 44706 | B38: 사무실 청소비(5월)_5월 환율 | D38: 7 | E38: 해외지사비 | I38: =300-I37 -> 286.18774 | J38: =I38/'통장내역(환율표)'!$D$18 -> 42.698022 | K38: =K37+G38-I38 -> 16200.406 | L38: =L37+H38-J38 -> 2417.082 | N38: =2459.78-J38 -> 2417.082
A39: 44706 | B39: 은행 수수료 | E39: 해외지사비 | I39: 3.6 | J39: =I39/'통장내역(환율표)'!$D$18 -> 0.53710505 | K39: =K38+G39-I39 -> 16196.806 | L39: =L38+H39-J39 -> 2416.5449 | N39: =N38-J39 -> 2416.5449
A40: 44706 | B40: 인터넷 Recruiting비용 | D40: 8 | E40: 해외지사비 | I40: 1674 | J40: =I40/'통장내역(환율표)'!$D$18 -> 249.75385 | K40: =K39+G40-I40 -> 14522.806 | L40: =L39+H40-J40 -> 2166.791 | M40: 신규 인력 채용 | N40: =N39-J40 -> 2166.791
...

Sheet 내역_22.06
A1: 6월 전도금 사용 내역 | K1: 100066029
A2: 5/10 송금 환율(1,274.6) | E2: 100034688 | G2: 6/10 송금 환율(1,257.6) | K2: 100034689 | L2: 1200000696
A3: 대계정 | B3: 소계정 | C3: 금액 (RMB) | D3: 금액 (USD) | E3: 금액 (KRW) | G3: 대계정 | H3: 소계정 | I3: 금액 (RMB) | J3: 금액 (USD) | K3: 금액 (KRW)
A4: 소모품비 | G4: 소모품비
A5: 업무추진비 | B5: 일반 | F5: 51131050 | G5: 업무추진비 | H5: 일반
A6: 여비교통비 | B6: 해외 | F6: 51061030 | G6: 여비교통비 | H6: 해외 | I6: 7533 | J6: 1121.1664 | K6: 1409983
A7: 지급임차료 | B7: 사무실관리 | F7: 51201020 | G7: 지급임차료 | H7: 사무실관리 | I7: 38880 | J7: 5786.6655 | K7: 7277316
A8: 지급임차료 | B8: 차량임차료 | F8: 51201030 | G8: 지급임차료 | H8: 차량임차료 | I8: 16500 | J8: 2455.7608 | K8: 3088364
A9: 통신비 | B9: 기타 | F9: 51071700 | G9: 통신비 | H9: 기타 | I9: 899 | J9: 133.80176 | K9: 168267 | L9: 89500
A10: 해외지사비 | C10: 4266.2623 | D10: 636.50861 | E10: 811296 | F10: 51321010 | G10: 해외지사비 | I10: 73193.058 | J10: 10919.615 | K10: 13732502
A11: 보증금
A12: Total | C12: =SUM(C4:C11) -> 4266.2623 | D12: =SUM(D4:D11) -> 636.50861 | E12: =SUM(E4:E11) -> 811296 | F12: 52981010 | G12: Total | I12: =SUM(I4:I10) -> 137005.06 | J12: =SUM(J4:J10) -> 20417.009 | K12: =SUM(K4:K10) -> 25676432
C13: =C12+I12++O12 -> 141271.32 | D13: =D12+J12++P12 -> 21053.518 | E13: =E12+K12++Q12 -> 26487728
A14: 보증금 | B14: 13081010 | H14: =SUBTOTAL(9,H17:H62) -> 20527.269 | I14: =SUBTOTAL(9,I17:I62) -> 141271.32 | J14: =SUBTOTAL(9,J17:J62) -> 21053.518
A15: 날짜 | B15: 내역 | D15: 증빙번호 | E15: 대계정 | F15: 소계정 | G15: 입금 | I15: 출금 | K15: 잔액 | M15: 비고
G16: RMB | H16: USD | I16: RMB | J16: USD | K16: RMB | L16: USD
A17: 44712 | B17: 기존 잔고 | K17: 4246.106 | L17: 633.55006 | N17: 633.55006
A18: 44725 | B18: 입금 | D18: 1 | G18: 137726 | H18: 20524.31 | K18: =K17+G18-I18 -> 141972.11 | L18: =L17+H18-J18 -> 21157.86
A19: 44725 | B19: 송금수수료 | E19: 해외지사비 | J19: 26 | K19: =K18+G19-I19 -> 141972.11 | L19: =L18+H19-J19 -> 21131.86
A20: 44733 | B20: 이자 입금 | D20: 2 | E20: 잡이익 | G20: 19.83 | H20: =G20/'통장내역(환율표)'!$D$18 -> 2.9585537 | J20: =I20/'통장내역(환율표)'!$D$18 -> 0 | K20: =K19+G20-I20 -> 141991.94 | L20: =L19+H20-J20 -> 21134.819 | N20: =N17-J20+H20 -> 636.50861
A21: 44737 | B21: 주재원 대행 수수료 | D21: 3 | E21: 해외지사비 | I21: 300 | J21: =I21/'통장내역(환율표)'!$D$18 -> 44.758754 | K21: =K20+G21-I21 -> 141691.94 | L21: =L20+H21-J21 -> 21090.06 | M21: 신순연 | N21: =N20-J21+H21 -> 591.74986
A22: 44737 | B22: 주재원 5대보험_5월 | D22: 3 | E22: 해외지사비 | I22: =J22*'통장내역(환율표)'!$D$18 -> 3966.2623 | J22: 591.74986 | K22: =K21+G22-I22 -> 137725.67 | L22: =L21+H22-J22 -> 20498.31 | M22: 신순연 | N22: =N21-J22+H22 -> 0
A23: 44737 | B23: 주재원 5대보험_6월 | D23: 3 | E23: 해외지사비 | I23: =7703.4-I22 -> 3737.1377 | J23: =I23/'통장내역(환율표)'!$D$25 -> 556.21312 | K23: =K22+G23-I23 -> 133988.54 | L23: =L22+H23-J23 -> 19942.097 | N23: =20498.31-J23 -> 19942.097
A24: 44737 | B24: 주재원 수당 | D24: 3 | E24: 해외지사비 | I24: 13500 | J24: =I24/'통장내역(환율표)'!$D$25 -> 2009.2589 | K24: =K23+G24-I24 -> 120488.54 | L24: =L23+H24-J24 -> 17932.838 | M24: 신순연 | N24: =N23-J24+H24 -> 17932.838
A25: 44737 | B25: 주재원 개인소득세 | D25: 3 | E25: 해외지사비 | I25: 2552.29 | J25: =I25/'통장내역(환율표)'!$D$25 -> 379.8675 | K25: =K24+G25-I25 -> 117936.25 | L25: =L24+H25-J25 -> 17552.971 | M25: 신순연 | N25: =N24-J25+H25 -> 17552.971
A26: 44737 | B26: 주재원 주택 수당 | D26: 3 | E26: 해외지사비 | I26: 20000 | J26: =I26/'통장내역(환율표)'!$D$25 -> 2976.6798 | K26: =K25+G26-I26 -> 97936.246 | L26: =L25+H26-J26 -> 14576.291 | M26: 신순연 | N26: =N25-J26+H26 -> 14576.291
A27: 44737 | B27: 은행 수수료 | D27: 3 | E27: 해외지사비 | I27: 7.2 | J27: =I27/'통장내역(환율표)'!$D$25 -> 1.0716047 | K27: =K26+G27-I27 -> 97929.046 | L27: =L26+H27-J27 -> 14575.219 | N27: =N26-J27+H27 -> 14575.219
A28: 44737 | B28: 주재원 대행 수수료 | D28: 4 | E28: 해외지사비 | I28: 300 | J28: =I28/'통장내역(환율표)'!$D$25 -> 44.650197 | K28: =K27+G28-I28 -> 97629.046 | L28: =L27+H28-J28 -> 14530.569 | M28: 김명관 | N28: =N27-J28+H28 -> 14530.569
A29: 44737 | B29: 주재원 개인소득세 | D29: 4 | E29: 해외지사비 | I29: 427.5 | J29: =I29/'통장내역(환율표)'!$D$25 -> 63.62653 | K29: =K28+G29-I29 -> 97201.546 | L29: =L28+H29-J29 -> 14466.942 | M29: 김명관 | N29: =N28-J29+H29 -> 14466.942
A30: 44737 | B30: 주재원 수당 | D30: 4 | E30: 해외지사비 | I30: 9450 | J30: =I30/'통장내역(환율표)'!$D$25 -> 1406.4812 | K30: =K29+G30-I30 -> 87751.546 | L30: =L29+H30-J30 -> 13060.461 | M30: 김명관 | N30: =N29-J30+H30 -> 13060.461
A31: 44737 | B31: 주재원 주택 수당 | D31: 4 | E31: 해외지사비 | I31: 9800 | J31: =I31/'통장내역(환율표)'!$D$25 -> 1458.5731 | K31: =K30+G31-I31 -> 77951.546 | L31: =L30+H31-J31 -> 11601.888 | M31: 김명관 | N31: =N30-J31+H31 -> 11601.888
A32: 44737 | B32: 은행 수수료 | D32: 4 | E32: 해외지사비 | I32: 7.2 | J32: =I32/'통장내역(환율표)'!$D$25 -> 1.0716047 | K32: =K31+G32-I32 -> 77944.346 | L32: =L31+H32-J32 -> 11600.817 | N32: =N31-J32+H32 -> 11600.817
A33: 44737 | B33: 5월 사무실 Rent비 | D33: 5 | E33: 지급임차료 | F33: 사무실관리 | I33: 19440 | J33: =I33/'통장내역(환율표)'!$D$25 -> 2893.3328 | K33: =K32+G33-I33 -> 58504.346 | L33: =L32+H33-J33 -> 8707.4838 | N33: =N32-J33+H33 -> 8707.4838
A34: 44737 | B34: 은행 수수료 | D34: 5 | E34: 해외지사비 | I34: 7.2 | J34: =I34/'통장내역(환율표)'!$D$25 -> 1.0716047 | K34: =K33+G34-I34 -> 58497.146 | L34: =L33+H34-J34 -> 8706.4122 | N34: =N33-J34+H34 -> 8706.4122
A35: 44737 | B35: 6월 사무실 Rent비 | D35: 6 | E35: 지급임차료 | F35: 사무실관리 | I35: 19440 | J35: =I35/'통장내역(환율표)'!$D$25 -> 2893.3328 | K35: =K34+G35-I35 -> 39057.146 | L35: =L34+H35-J35 -> 5813.0794 | N35: =N34-J35+H35 -> 5813.0794
A36: 44737 | B36: 은행 수수료 | D36: 6 | E36: 해외지사비 | I36: 7.2 | J36: =I36/'통장내역(환율표)'!$D$25 -> 1.0716047 | K36: =K35+G36-I36 -> 39049.946 | L36: =L35+H36-J36 -> 5812.0078 | N36: =N35-J36+H36 -> 5812.0078
A37: 44737 | B37: 사무실 에어컨 및 전기/물 비용 | D37: 7 | E37: 해외지사비 | I37: 422.63 | J37: =I37/'통장내역(환율표)'!$D$25 -> 62.901709 | K37: =K36+G37-I37 -> 38627.316 | L37: =L36+H37-J37 -> 5749.1061 | N37: =N36-J37+H37 -> 5749.1061
A38: 44737 | B38: 은행 수수료 | D38: 7 | E38: 해외지사비 | I38: 3.6 | J38: =I38/'통장내역(환율표)'!$D$25 -> 0.53580236 | K38: =K37+G38-I38 -> 38623.716 | L38: =L37+H38-J38 -> 5748.5703 | N38: =N37-J38+H38 -> 5748.5703
A39: 44737 | B39: 중연-4.5월 기장비 | D39: 8 | E39: 해외지사비 | I39: 2000 | J39: =I39/'통장내역(환율표)'!$D$25 -> 297.66798 | K39: =K38+G39-I39 -> 36623.716 | L39: =L38+H39-J39 -> 5450.9023 | N39: =N38-J39+H39 -> 5450.9023
A40: 44737 | B40: 중연-22년 사무용품비 | D40: 8 | E40: 해외지사비 | I40: 300 | J40: =I40/'통장내역(환율표)'!$D$25 -> 44.650197 | K40: =K39+G40-I40 -> 36323.716 | L40: =L39+H40-J40 -> 5406.2521 | N40: =N39-J40+H40 -> 5406.2521
...

Sheet 내역_22.07
A1: 7월 전도금 사용 내역 | K1: 100066029
A2: 6/10 송금 환율(1,257.6) | E2: 100041588 | G2: 7/10 송금 환율(1,299.3) | K2: 100041589 | L2: 1200000696
A3: 대계정 | B3: 소계정 | C3: 금액 (RMB) | D3: 금액 (USD) | E3: 금액 (KRW) | G3: 대계정 | H3: 소계정 | I3: 금액 (RMB) | J3: 금액 (USD) | K3: 금액 (KRW)
A4: 소모품비 | G4: 소모품비
A5: 업무추진비 | B5: 일반 | F5: 51131050 | G5: 업무추진비 | H5: 일반 | I5: 4707.69 | J5: 701.44 | K5: 911381 | L5: =K5+E5 -> 911381
A6: 여비교통비 | B6: 해외 | F6: 51061030 | G6: 여비교통비 | H6: 해외 | I6: 28305.6 | J6: 4217.4744 | K6: 5479759 | L6: =K6+E6 -> 5479759
A7: 지급임차료 | B7: 사무실관리 | F7: 51201020 | G7: 지급임차료 | H7: 사무실관리 | I7: 19440 | J7: 2896.5188 | K7: 3763448 | L7: =K7+E7 -> 3763448
A8: 지급임차료 | B8: 차량임차료 | F8: 51201030 | G8: 지급임차료 | H8: 차량임차료 | I8: 16500 | J8: 2458.465 | K8: 3194290 | L8: =K8+E8 -> 3194290
A9: 통신비 | B9: 기타 | F9: 51071700 | G9: 통신비 | H9: 기타 | I9: 1799 | J9: 268.04719 | K9: 348277 | L9: =K9+E9 -> 348277
A10: 해외지사비 | C10: 719.1937 | D10: 107.30071 | E10: 134940 | F10: 51321010 | G10: 해외지사비 | I10: 124976.29 | J10: 18647.202 | K10: 24228307 | L10: =K10+E10 -> 24363247
A11: 보증금 | F11: 13081010 | G11: 보증금 | I11: 28000 | J11: 4171.9406 | K11: 7653455
A12: Total | C12: =SUM(C4:C11) -> 719.1937 | D12: =SUM(D4:D11) -> 107.30071 | E12: =SUM(E4:E11) -> 134940 | F12: 52981010 | G12: Total | I12: =SUM(I4:I11) -> 223728.58 | J12: =SUM(J4:J11) -> 33361.088 | K12: =SUM(K4:K10) -> 37925462
C13: =C12+I12 -> 224447.77 | D13: =D12+J12 -> 33468.388 | E13: =E12+K12 -> 38060402
A14: 보증금 | B14: 13081010 | H14: =SUBTOTAL(9,H17:H74) -> 35786.57 | I14: =SUBTOTAL(9,I17:I75) -> 224447.77 | J14: =SUBTOTAL(9,J17:J75) -> 33468.389
A15: 날짜 | B15: 내역 | D15: 증빙번호 | E15: 대계정 | F15: 소계정 | G15: 입금 | I15: 출금 | K15: 잔액 | M15: 비고
G16: RMB | H16: USD | I16: RMB | J16: USD | K16: RMB | L16: USD
A17: 44742 | B17: 기존 잔고 | K17: 720.61599 | L17: 107.30071 | N17: 107.30071
A18: 44754 | B18: 입금 | D18: 1 | G18: 240007.24 | H18: 35786.57 | K18: =K17+G18-I18 -> 240727.86 | L18: =L17+H18-J18 -> 35893.871 | M18: 입금
A19: 44754 | B19: 송금수수료 | E19: 해외지사비 | J19: 26 | K19: =K18+G19-I19 -> 240727.86 | L19: =L18+H19-J19 -> 35867.871
A20: 44756 | B20: 사무실 운영세금(4,5,6월분 7월 납부)_6월 환율 | D20: 2 | E20: 해외지사비 | I20: =J20*'통장내역(환율표)'!$D$18 -> 719.1937 | J20: 107.30071 | K20: =K19+G20-I20 -> 240008.66 | L20: =L19+H20-J20 -> 35760.57 | M20: 사무실 운영세금(4,5,6월분 7월 납부)
A21: 44756 | B21: 사무실 운영세금(4,5,6월분 7월 납부)_7월 환율 | D21: 2 | E21: 해외지사비 | I21: =11384.02-I20 -> 10664.826 | J21: =I21/'통장내역(환율표)'!$D$33 -> 1589.0365 | K21: =K20+G21-I21 -> 229343.84 | L21: =L20+H21-J21 -> 34171.533 | N21: =35760.57-J21 -> 34171.533
A22: 44757 | B22: 주재원 대행 수수료 | D22: 3 | E22: 해외지사비 | I22: 300 | J22: =I22/'통장내역(환율표)'!$D$33 -> 44.699364 | K22: =K21+G22-I22 -> 229043.84 | L22: =L21+H22-J22 -> 34126.834 | M22: 신순연 | N22: =N21-J22+H22 -> 34126.834
A23: 44757 | B23: 주재원 5대보험 | D23: 3 | E23: 해외지사비 | I23: 7707.43 | J23: =I23/'통장내역(환율표)'!$D$33 -> 1148.3907 | K23: =K22+G23-I23 -> 221336.41 | L23: =L22+H23-J23 -> 32978.443 | M23: 신순연 | N23: =N22-J23+H23 -> 32978.443
A24: 44757 | B24: 주재원 개인소득세 | D24: 3 | E24: 해외지사비 | I24: 4778.34 | J24: =I24/'통장내역(환율표)'!$D$33 -> 711.96253 | K24: =K23+G24-I24 -> 216558.07 | L24: =L23+H24-J24 -> 32266.481 | M24: 신순연 | N24: =N23-J24+H24 -> 32266.481
A25: 44757 | B25: 주재원 수당 | D25: 3 | E25: 해외지사비 | I25: 13500 | J25: =I25/'통장내역(환율표)'!$D$33 -> 2011.4714 | K25: =K24+G25-I25 -> 203058.07 | L25: =L24+H25-J25 -> 30255.009 | M25: 신순연 | N25: =N24-J25+H25 -> 30255.009
A26: 44757 | B26: 주재원 주택 수당 | D26: 3 | E26: 해외지사비 | I26: 20000 | J26: =I26/'통장내역(환율표)'!$D$33 -> 2979.9576 | K26: =K25+G26-I26 -> 183058.07 | L26: =L25+H26-J26 -> 27275.052 | M26: 신순연 | N26: =N25-J26+H26 -> 27275.052
A27: 44757 | B27: 주재원 대행 수수료 | D27: 3 | E27: 해외지사비 | I27: 300 | J27: =I27/'통장내역(환율표)'!$D$33 -> 44.699364 | K27: =K26+G27-I27 -> 182758.07 | L27: =L26+H27-J27 -> 27230.353 | M27: 김명관 | N27: =N26-J27+H27 -> 27230.353
A28: 44757 | B28: 주재원 5대보험 | D28: 3 | E28: 해외지사비 | I28: 634.29 | J28: =I28/'통장내역(환율표)'!$D$33 -> 94.507865 | K28: =K27+G28-I28 -> 182123.78 | L28: =L27+H28-J28 -> 27135.845 | M28: 김명관 | N28: =N27-J28+H28 -> 27135.845
A29: 44757 | B29: 주재원 개인소득세 | D29: 3 | E29: 해외지사비 | I29: 4332.43 | J29: =I29/'통장내역(환율표)'!$D$33 -> 645.52289 | K29: =K28+G29-I29 -> 177791.35 | L29: =L28+H29-J29 -> 26490.322 | M29: 김명관 | N29: =N28-J29+H29 -> 26490.322
A30: 44757 | B30: 주재원 수당 | D30: 3 | E30: 해외지사비 | I30: 13500 | J30: =I30/'통장내역(환율표)'!$D$33 -> 2011.4714 | K30: =K29+G30-I30 -> 164291.35 | L30: =L29+H30-J30 -> 24478.85 | M30: 김명관 | N30: =N29-J30+H30 -> 24478.85
A31: 44757 | B31: 주재원 주택 수당 | D31: 3 | E31: 해외지사비 | I31: 14000 | J31: =I31/'통장내역(환율표)'!$D$33 -> 2085.9703 | K31: =K30+G31-I31 -> 150291.35 | L31: =L30+H31-J31 -> 22392.88 | M31: 김명관 | N31: =N30-J31+H31 -> 22392.88
A32: 44757 | B32: 주재원 대행 수수료 | D32: 3 | E32: 해외지사비 | I32: 300 | J32: =I32/'통장내역(환율표)'!$D$33 -> 44.699364 | K32: =K31+G32-I32 -> 149991.35 | L32: =L31+H32-J32 -> 22348.181 | M32: 현채인 | N32: =N31-J32+H32 -> 22348.181
A33: 44757 | B33: 주재원 5대보험 | D33: 3 | E33: 해외지사비 | I33: 501.68 | J33: =I33/'통장내역(환율표)'!$D$33 -> 74.749257 | K33: =K32+G33-I33 -> 149489.67 | L33: =L32+H33-J33 -> 22273.431 | M33: 현채인 | N33: =N32-J33+H33 -> 22273.431
... A35: 44757 | B35: 주재원 수당 | D35: 3 | E35: 해외지사비 | I35: 21220.91 | J35: =I35/'통장내역(환율표)'!$D$33 -> 3161.8706 | K35: =K34+G35-I35 -> 119724.32 | L35: =L34+H35-J35 -> 17838.457 | M35: 현채인 | N35: =N34-J35+H35 -> 17838.457
A36: 44757 | B36: 은행수수료 | D36: 3 | E36: 해외지사비 | I36: 12 | J36: =I36/'통장내역(환율표)'!$D$33 -> 1.7879746 | K36: =K35+G36-I36 -> 119712.32 | L36: =L35+H36-J36 -> 17836.669 | N36: =N35-J36+H36 -> 17836.669
A37: 44757 | B37: 주재원 주택 Deposit 2개월 분(김명관) | D37: 4 | E37: 보증금 | I37: 28000 | J37: =I37/'통장내역(환율표)'!$D$33 -> 4171.9406 | K37: =K36+G37-I37 -> 91712.316 | L37: =L36+H37-J37 -> 13664.729 | M37: 주재원 주택 Deposit 2개월 분(김명관) 영수증 Scan본상 계산 잘못 됨. (14000x2+7.2=28007.2) | N37: =N36-J37+H37 -> 13664.729
A38: 44757 | B38: 은행수수료 | D38: 4 | E38: 해외지사비 | I38: 7.2 | J38: =I38/'통장내역(환율표)'!$D$33 -> 1.0727847 | K38: =K37+G38-I38 -> 91705.116 | L38: =L37+H38-J38 -> 13663.656 | N38: =N37-J38+H38 -> 13663.656
A39: 44760 | B39: 사무실 에어컨 및 전기/물 비용 | D39: 5 | E39: 해외지사비 | I39: 548.35 | J39: =I39/'통장내역(환율표)'!$D$33 -> 81.702988 | K39: =K38+G39-I39 -> 91156.766 | L39: =L38+H39-J39 -> 13581.953 | M39: 사무실 에어컨 및 전기/물 비용 | N39: =N38-J39+H39 -> 13581.953
A40: 44760 | B40: 은행수수료 | D40: 5 | E40: 해외지사비 | I40: 3.6 | J40: =I40/'통장내역(환율표)'!$D$33 -> 0.53639237 | K40: =K39+G40-I40 -> 91153.166 | L40: =L39+H40-J40 -> 13581.417 | N40: =N39-J40+H40 -> 13581.417
A41: 44760 | B41: 김명관책임 건강검진 | D41: 6 | E41: 해외지사비 | I41: 717.1 | J41: =I41/'통장내역(환율표)'!$D$33 -> 106.84638 | K41: =K40+G41-I41 -> 90436.066 | L41: =L40+H41-J41 -> 13474.57 | N41: =N40-J41+H41 -> 13474.57
...

Sheet 내역_22.07 (수정)
A1: 7월 전도금 사용 내역 | K1: 100066029
A2: 6/10 송금 환율(1,257.6) | E2: 100041588 | G2: 7/10 송금 환율(1,299.3) | K2: 100041589 | L2: 1200000696
A3: 대계정 | B3: 소계정 | C3: 금액 (RMB) | D3: 금액 (USD) | E3: 금액 (KRW) | G3: 대계정 | H3: 소계정 | I3: 금액 (RMB) | J3: 금액 (USD) | K3: 금액 (KRW)
A4: 소모품비 | G4: 소모품비
A5: 업무추진비 | B5: 일반 | F5: 51131050 | G5: 업무추진비 | H5: 일반 | I5: 4707.69 | J5: 701.44 | K5: 911381 | L5: =K5+E5 -> 911381
A6: 여비교통비 | B6: 해외 | F6: 51061030 | G6: 여비교통비 | H6: 해외 | I6: 28305.6 | J6: 4217.4744 | K6: 5479759 | L6: =K6+E6 -> 5479759
A7: 지급임차료 | B7: 사무실관리 | F7: 51201020 | G7: 지급임차료 | H7: 사무실관리 | I7: 19440 | J7: 2896.5188 | K7: 3763448 | L7: =K7+E7 -> 3763448
A8: 지급임차료 | B8: 차량임차료 | F8: 51201030 | G8: 지급임차료 | H8: 차량임차료 | I8: 16500 | J8: 2458.465 | K8: 3194290 | L8: =K8+E8 -> 3194290
A9: 통신비 | B9: 기타 | F9: 51071700 | G9: 통신비 | H9: 기타 | I9: 1799 | J9: 268.04719 | K9: 348277 | L9: =K9+E9 -> 348277
A10: 해외지사비 | C10: 719.1937 | D10: 107.30071 | E10: 134940 | F10: 51321010 | G10: 해외지사비 | I10: 124976.29 | J10: 18647.202 | K10: 24228307 | L10: =K10+E10 -> 24363247
A11: 보증금 | F11: 13081010 | G11: 보증금 | I11: 28000 | J11: 4171.9406
A12: Total | C12: =SUM(C4:C11) -> 719.1937 | D12: =SUM(D4:D11) -> 107.30071 | E12: =SUM(E4:E11) -> 134940 | F12: 52981010 | G12: Total | I12: =SUM(I4:I11) -> 223728.58 | J12: =SUM(J4:J11) -> 33361.088 | K12: =SUM(K4:K10) -> 37925462
C13: =C12+I12 -> 224447.77 | D13: =D12+J12 -> 33468.388 | E13: =E12+K12 -> 38060402
A14: 보증금 | B14: 13081010 | H14: =SUBTOTAL(9,H17:H74) -> 35786.57 | I14: =SUBTOTAL(9,I17:I75) -> 224447.77 | J14: =SUBTOTAL(9,J17:J75) -> 33468.129
A15: 날짜 | B15: 내역 | D15: 증빙번호 | E15: 대계정 | F15: 소계정 | G15: 입금 | I15: 출금 | K15: 잔액 | M15: 비고
G16: RMB | H16: USD | I16: RMB | J16: USD | K16: RMB | L16: USD
A17: 44742 | B17: 기존 잔고 | K17: 720.61599 | L17: 107.30071 | N17: 107.30071
A18: 44754 | B18: 입금 | D18: 1 | G18: 240007.24 | H18: 35786.57 | K18: =K17+G18-I18 -> 240727.86 | L18: =L17+H18-J18 -> 35893.871 | M18: 입금
A19: 44754 | B19: 송금수수료 | E19: 해외지사비 | J19: 26 | K19: =K18+G19-I19 -> 240727.86 | L19: =L18+H19-J19 -> 35867.871
A20: 44756 | B20: 사무실 운영세금(4,5,6월분 7월 납부)_6월 환율 | D20: 2 | E20: 해외지사비 | I20: =J20*'통장내역(환율표)'!$D$25 -> 720.94226 | J20: 107.30071 | K20: =K19+G20-I20 -> 240006.91 | L20: =L19+H20-J20 -> 35760.57 | M20: 사무실 운영세금(4,5,6월분 7월 납부)
A21: 44756 | B21: 사무실 운영세금(4,5,6월분 7월 납부)_7월 환율 | D21: 2 | E21: 해외지사비 | I21: =11384.02-I20 -> 10663.078 | J21: =I21/'통장내역(환율표)'!$D$33 -> 1588.776 | K21: =K20+G21-I21 -> 229343.84 | L21: =L20+H21-J21 -> 34171.794 | N21: =35760.57-J21 -> 34171.794
A22: 44757 | B22: 주재원 대행 수수료 | D22: 3 | E22: 해외지사비 | I22: 300 | J22: =I22/'통장내역(환율표)'!$D$33 -> 44.699364 | K22: =K21+G22-I22 -> 229043.84 | L22: =L21+H22-J22 -> 34127.095 | M22: 신순연 | N22: =N21-J22+H22 -> 34127.095
A23: 44757 | B23: 주재원 5대보험 | D23: 3 | E23: 해외지사비 | I23: 7707.43 | J23: =I23/'통장내역(환율표)'!$D$33 -> 1148.3907 | K23: =K22+G23-I23 -> 221336.41 | L23: =L22+H23-J23 -> 32978.704 | M23: 신순연 | N23: =N22-J23+H23 -> 32978.704
A24: 44757 | B24: 주재원 개인소득세 | D24: 3 | E24: 해외지사비 | I24: 4778.34 | J24: =I24/'통장내역(환율표)'!$D$33 -> 711.96253 | K24: =K23+G24-I24 -> 216558.07 | L24: =L23+H24-J24 -> 32266.741 | M24: 신순연 | N24: =N23-J24+H24 -> 32266.741
A25: 44757 | B25: 주재원 수당 | D25: 3 | E25: 해외지사비 | I25: 13500 | J25: =I25/'통장내역(환율표)'!$D$33 -> 2011.4714 | K25: =K24+G25-I25 -> 203058.07 | L25: =L24+H25-J25 -> 30255.27 | M25: 신순연 | N25: =N24-J25+H25 -> 30255.27
A26: 44757 | B26: 주재원 주택 수당 | D26: 3 | E26: 해외지사비 | I26: 20000 | J26: =I26/'통장내역(환율표)'!$D$33 -> 2979.9576 | K26: =K25+G26-I26 -> 183058.07 | L26: =L25+H26-J26 -> 27275.312 | M26: 신순연 | N26: =N25-J26+H26 -> 27275.312
A27: 44757 | B27: 주재원 대행 수수료 | D27: 3 | E27: 해외지사비 | I27: 300 | J27: =I27/'통장내역(환율표)'!$D$33 -> 44.699364 | K27: =K26+G27-I27 -> 182758.07 | L27: =L26+H27-J27 -> 27230.613 | M27: 김명관 | N27: =N26-J27+H27 -> 27230.613
A28: 44757 | B28: 주재원 5대보험 | D28: 3 | E28: 해외지사비 | I28: 634.29 | J28: =I28/'통장내역(환율표)'!$D$33 -> 94.507865 | K28: =K27+G28-I28 -> 182123.78 | L28: =L27+H28-J28 -> 27136.105 | M28: 김명관 | N28: =N27-J28+H28 -> 27136.105
A29: 44757 | B29: 주재원 개인소득세 | D29: 3 | E29: 해외지사비 | I29: 4332.43 | J29: =I29/'통장내역(환율표)'!$D$33 -> 645.52289 | K29: =K28+G29-I29 -> 177791.35 | L29: =L28+H29-J29 -> 26490.582 | M29: 김명관 | N29: =N28-J29+H29 -> 26490.582
A30: 44757 | B30: 주재원 수당 | D30: 3 | E30: 해외지사비 | I30: 13500 | J30: =I30/'통장내역(환율표)'!$D$33 -> 2011.4714 | K30: =K29+G30-I30 -> 164291.35 | L30: =L29+H30-J30 -> 24479.111 | M30: 김명관 | N30: =N29-J30+H30 -> 24479.111
A31: 44757 | B31: 주재원 주택 수당 | D31: 3 | E31: 해외지사비 | I31: 14000 | J31: =I31/'통장내역(환율표)'!$D$33 -> 2085.9703 | K31: =K30+G31-I31 -> 150291.35 | L31: =L30+H31-J31 -> 22393.141 | M31: 김명관 | N31: =N30-J31+H31 -> 22393.141
A32: 44757 | B32: 주재원 대행 수수료 | D32: 3 | E32: 해외지사비 | I32: 300 | J32: =I32/'통장내역(환율표)'!$D$33 -> 44.699364 | K32: =K31+G32-I32 -> 149991.35 | L32: =L31+H32-J32 -> 22348.441 | M32: 현채인 | N32: =N31-J32+H32 -> 22348.441
A33: 44757 | B33: 주재원 5대보험 | D33: 3 | E33: 해외지사비 | I33: 501.68 | J33: =I33/'통장내역(환율표)'!$D$33 -> 74.749257 | K33: =K32+G33-I33 -> 149489.67 | L33: =L32+H33-J33 -> 22273.692 | M33: 현채인 | N33: =N32-J33+H33 -> 22273.692
... A35: 44757 | B35: 주재원 수당 | D35: 3 | E35: 해외지사비 | I35: 21220.91 | J35: =I35/'통장내역(환율표)'!$D$33 -> 3161.8706 | K35: =K34+G35-I35 -> 119724.32 | L35: =L34+H35-J35 -> 17838.718 | M35: 현채인 | N35: =N34-J35+H35 -> 17838.718
A36: 44757 | B36: 은행수수료 | D36: 3 | E36: 해외지사비 | I36: 12 | J36: =I36/'통장내역(환율표)'!$D$33 -> 1.7879746 | K36: =K35+G36-I36 -> 119712.32 | L36: =L35+H36-J36 -> 17836.93 | N36: =N35-J36+H36 -> 17836.93
A37: 44757 | B37: 주재원 주택 Deposit 2개월 분(김명관) | D37: 4 | E37: 보증금 | I37: 28000 | J37: =I37/'통장내역(환율표)'!$D$33 -> 4171.9406 | K37: =K36+G37-I37 -> 91712.316 | L37: =L36+H37-J37 -> 13664.989 | M37: 주재원 주택 Deposit 2개월 분(김명관) 영수증 Scan본상 계산 잘못 됨. (14000x2+7.2=28007.2) | N37: =N36-J37+H37 -> 13664.989
A38: 44757 | B38: 은행수수료 | D38: 4 | E38: 해외지사비 | I38: 7.2 | J38: =I38/'통장내역(환율표)'!$D$33 -> 1.0727847 | K38: =K37+G38-I38 -> 91705.116 | L38: =L37+H38-J38 -> 13663.917 | N38: =N37-J38+H38 -> 13663.917
A39: 44760 | B39: 사무실 에어컨 및 전기/물 비용 | D39: 5 | E39: 해외지사비 | I39: 548.35 | J39: =I39/'통장내역(환율표)'!$D$33 -> 81.702988 | K39: =K38+G39-I39 -> 91156.766 | L39: =L38+H39-J39 -> 13582.214 | M39: 사무실 에어컨 및 전기/물 비용 | N39: =N38-J39+H39 -> 13582.214
A40: 44760 | B40: 은행수수료 | D40: 5 | E40: 해외지사비 | I40: 3.6 | J40: =I40/'통장내역(환율표)'!$D$33 -> 0.53639237 | K40: =K39+G40-I40 -> 91153.166 | L40: =L39+H40-J40 -> 13581.677 | N40: =N39-J40+H40 -> 13581.677
A41: 44760 | B41: 김명관책임 건강검진 | D41: 6 | E41: 해외지사비 | I41: 717.1 | J41: =I41/'통장내역(환율표)'!$D$33 -> 106.84638 | K41: =K40+G41-I41 -> 90436.066 | L41: =L40+H41-J41 -> 13474.831 | N41: =N40-J41+H41 -> 13474.831
...

Sheet 내역_22.08
A1: 8월 전도금 사용 내역 | K1: 100066029
A2: 7/10 송금 환율(1,299.3) | E2: 100048802 | G2: 8/10 송금 환율(1305.1) | K2: 100048803 | L2: 1200000696
A3: 대계정 | B3: 소계정 | C3: 금액 (RMB) | D3: 금액 (USD) | E3: 금액 (KRW) | G3: 대계정 | H3: 소계정 | I3: 금액 (RMB) | J3: 금액 (USD) | K3: 금액 (KRW)
A4: 소모품비 | G4: 소모품비
A5: 업무추진비 | B5: 일반 | F5: 51131050 | G5: 업무추진비 | H5: 일반 | I5: 3453 | J5: 513.94055 | K5: 670743 | L5: =K5+E5 -> 670743
A6: 여비교통비 | B6: 해외 | F6: 51061030 | G6: 여비교통비 | H6: 해외 | I6: 12434.15 | J6: 1850.6846 | K6: 2415322 | L6: =K6+E6 -> 2415322
A7: 지급임차료 | B7: 사무실관리 | F7: 51201020 | G7: 지급임차료 | H7: 사무실관리 | I7: 19440 | J7: 2893.4273 | K7: 3776215 | L7: =K7+E7 -> 3776215
A8: 지급임차료 | B8: 차량임차료 | F8: 51201030 | G8: 지급임차료 | H8: 차량임차료 | I8: 16500 | J8: 2455.841 | K8: 3205117 | L8: =K8+E8 -> 3205117
A9: 통신비 | B9: 기타 | F9: 51071700 | G9: 통신비 | H9: 기타 | I9: 997.6 | J9: 148.48164 | K9: 193781 | L9: =K9+E9 -> 193781
A10: 해외지사비 | C10: 16280.375 | D10: 2425.7413 | E10: 3151764 | F10: 51321010 | G10: 해외지사비 | I10: 105948.8 | J10: 15795.297 | K10: 20614446 | L10: =K10+E10 -> 23766210
A11: 보증금 | F11: 13081010 | G11: 보증금
A12: Total | C12: =SUM(C4:C11) -> 16280.375 | D12: =SUM(D4:D11) -> 2425.7413 | E12: =SUM(E4:E11) -> 3151764 | F12: 52981010 | G12: Total | I12: =SUM(I4:I11) -> 158773.55 | J12: =SUM(J4:J11) -> 23657.672 | K12: =SUM(K4:K10) -> 30875624
C13: =C12+I12 -> 175053.92 | D13: =D12+J12 -> 26083.413 | E13: =E12+K12 -> 34027388 | K13: 16280.086 | L13: 2425.7418
A14: 보증금 | B14: 13081010 | H14: =SUBTOTAL(9,H17:H67) -> 23964.2 | I14: =SUBTOTAL(9,I17:I67) -> 175053.92 | J14: =SUBTOTAL(9,J17:J67) -> 26083.413
A15: 날짜 | B15: 내역 | D15: 증빙번호 | E15: 대계정 | F15: 소계정 | G15: 입금 | I15: 출금 | K15: 잔액 | M15: 비고
G16: RMB | H16: USD | I16: RMB | J16: USD | K16: RMB | L16: USD
A17: 44742 | B17: 기존 잔고 | E17: 잡이익 | K17: 16280.086 | L17: 2425.4813 | N17: 2425.4813
B18: 7월 환율 차이 | E18: 해외지사비 | H18: 0.26 | K18: =K17+G18-I18 -> 16280.086 | L18: =L17+H18-J18 -> 2425.7413 | N18: =N17-J18+H18 -> 2425.7413
A19: 44784 | B19: 입금 | D19: 1 | G19: 160831.26 | H19: 23963.94 | K19: =K18+G19-I19 -> 177111.35 | L19: =L18+H19-J19 -> 26389.681 | M19: 입금
A20: 44784 | B20: 송금수수료 | E20: 해외지사비 | J20: 26 | K20: =K19+G20-I20 -> 177111.35 | L20: =L19+H20-J20 -> 26363.681
A21: 44793 | B21: 주재원 대행 수수료 | D21: 2 | E21: 해외지사비 | I21: 300 | J21: =I21/'통장내역(환율표)'!$D$33 -> 44.699364 | K21: =K20+G21-I21 -> 176811.35 | L21: =L20+H21-J21 -> 26318.982 | M21: 신순연 | N21: =N18-J21+H21 -> 2381.0419
A22: 44793 | B22: 주재원 5대보험 | D22: 2 | E22: 해외지사비 | I22: 7707.43 | J22: =I22/'통장내역(환율표)'!$D$33 -> 1148.3907 | K22: =K21+G22-I22 -> 169103.92 | L22: =L21+H22-J22 -> 25170.591 | M22: 신순연 | N22: =N21-J22+H22 -> 1232.6512
A23: 44793 | B23: 주재원 개인소득세 | D23: 2 | E23: 해외지사비 | I23: 5104.58 | J23: =I23/'통장내역(환율표)'!$D$33 -> 760.5716 | K23: =K22+G23-I23 -> 163999.34 | L23: =L22+H23-J23 -> 24410.02 | M23: 신순연 | N23: =N22-J23+H23 -> 472.0796
A24: 44793 | B24: 주재원 수당_7월 | D24: 2 | E24: 해외지사비 | I24: =J24*'통장내역(환율표)'!$D$33 -> 3168.3646 | J24: 472.0796 | K24: =K23+G24-I24 -> 160830.97 | L24: =L23+H24-J24 -> 23937.94 | M24: 신순연 | N24: =N23-J24 -> 0
A25: 44793 | B25: 주재원 수당_8월 | D25: 2 | E25: 해외지사비 | I25: =13500-I24 -> 10331.635 | J25: =I25/'통장내역(환율표)'!$D$41 -> 1537.7488 | K25: =K24+G25-I25 -> 150499.34 | L25: =L24+H25-J25 -> 22400.191 | N25: =23937.94-J25 -> 22400.191
A26: 44793 | B26: 주재원 주택 수당 | D26: 2 | E26: 해외지사비 | I26: 20000 | J26: =I26/'통장내역(환율표)'!$D$41 -> 2976.777 | K26: =K25+G26-I26 -> 130499.34 | L26: =L25+H26-J26 -> 19423.414 | M26: 신순연 | N26: =N25-J26 -> 19423.414
A27: 44793 | B27: 주재원 대행 수수료 | D27: 2 | E27: 해외지사비 | I27: 300 | J27: =I27/'통장내역(환율표)'!$D$41 -> 44.651655 | K27: =K26+G27-I27 -> 130199.34 | L27: =L26+H27-J27 -> 19378.763 | M27: 김명관 | N27: =N26-J27 -> 19378.763
A28: 44793 | B28: 주재원 5대보험 | D28: 2 | E28: 해외지사비 | I28: 4332.43 | J28: =I28/'통장내역(환율표)'!$D$41 -> 644.8339 | K28: =K27+G28-I28 -> 125866.91 | L28: =L27+H28-J28 -> 18733.929 | M28: 김명관 | N28: =N27-J28 -> 18733.929
A29: 44793 | B29: 주재원 개인소득세 | D29: 2 | E29: 해외지사비 | I29: 2071.79 | J29: =I29/'통장내역(환율표)'!$D$41 -> 308.36284 | K29: =K28+G29-I29 -> 123795.12 | L29: =L28+H29-J29 -> 18425.566 | M29: 김명관 | N29: =N28-J29 -> 18425.566
A30: 44793 | B30: 주재원 수당 | D30: 2 | E30: 해외지사비 | I30: 13500 | J30: =I30/'통장내역(환율표)'!$D$41 -> 2009.3245 | K30: =K29+G30-I30 -> 110295.12 | L30: =L29+H30-J30 -> 16416.241 | M30: 김명관 | N30: =N29-J30 -> 16416.241
A31: 44793 | B31: 주재원 주택 수당 | D31: 2 | E31: 해외지사비 | I31: 14000 | J31: =I31/'통장내역(환율표)'!$D$41 -> 2083.7439 | K31: =K30+G31-I31 -> 96295.116 | L31: =L30+H31-J31 -> 14332.497 | M31: 김명관 | N31: =N30-J31 -> 14332.497
A32: 44793 | B32: 주재원 대행 수수료 | D32: 2 | E32: 해외지사비 | I32: 300 | J32: =I32/'통장내역(환율표)'!$D$41 -> 44.651655 | K32: =K31+G32-I32 -> 95995.116 | L32: =L31+H32-J32 -> 14287.846 | M32: 현채인 | N32: =N31-J32 -> 14287.846
A33: 44793 | B33: 주재원 5대보험 | D33: 2 | E33: 해외지사비 | I33: 8544.44 | J33: =I33/'통장내역(환율표)'!$D$41 -> 1271.7446 | K33: =K32+G33-I33 -> 87450.676 | L33: =L32+H33-J33 -> 13016.101 | M33: 현채인 | N33: =N32-J33 -> 13016.101
A34: 44793 | B34: 주재원 개인소득세 | D34: 2 | E34: 해외지사비 | I34: 501.68 | J34: =I34/'통장내역(환율표)'!$D$41 -> 74.669475 | K34: =K33+G34-I34 -> 86948.996 | L34: =L33+H34-J34 -> 12941.432 | M34: 현채인 | N34: =N33-J34 -> 12941.432
A35: 44793 | B35: 주재원 수당 | D35: 2 | E35: 해외지사비 | I35: 21220.91 | J35: =I35/'통장내역(환율표)'!$D$41 -> 3158.4959 | K35: =K34+G35-I35 -> 65728.086 | L35: =L34+H35-J35 -> 9782.9358 | M35: 현채인 | N35: =N34-J35 -> 9782.9358
A36: 44793 | B36: 은행수수료 | D36: 2 | E36: 해외지사비 | I36: 12 | J36: =I36/'통장내역(환율표)'!$D$41 -> 1.7860662 | K36: =K35+G36-I36 -> 65716.086 | L36: =L35+H36-J36 -> 9781.1497 | N36: =N35-J36 -> 9781.1497
A37: 44793 | B37: 사무실 임대료 | D37: 3 | E37: 지급임차료 | F37: 사무실관리 | I37: 19440 | J37: =I37/'통장내역(환율표)'!$D$41 -> 2893.4273 | K37: =K36+G37-I37 -> 46276.086 | L37: =L36+H37-J37 -> 6887.7224 | M37: 사무실 임대료 | N37: =N36-J37 -> 6887.7224
A38: 44793 | B38: 은행수수료 | D38: 3 | E38: 해외지사비 | I38: 7.2 | J38: =I38/'통장내역(환율표)'!$D$41 -> 1.0716397 | K38: =K37+G38-I38 -> 46268.886 | L38: =L37+H38-J38 -> 6886.6508 | N38: =N37-J38 -> 6886.6508
A39: 44793 | B39: 차량 Rent비 | D39: 4 | E39: 지급임차료 | F39: 차량임차료 | I39: 16500 | J39: =I39/'통장내역(환율표)'!$D$41 -> 2455.841 | K39: =K38+G39-I39 -> 29768.886 | L39: =L38+H39-J39 -> 4430.8097 | M39: 차량 Rent비 | N39: =N38-J39 -> 4430.8097
A40: 44793 | B40: 은행수수료 | D40: 4 | E40: 해외지사비 | I40: 7.2 | J40: =I40/'통장내역(환율표)'!$D$41 -> 1.0716397 | K40: =K39+G40-I40 -> 29761.686 | L40: =L39+H40-J40 -> 4429.7381 | N40: =N39-J40 -> 4429.7381
...

Sheet 내역_22.09
A1: 9월 전도금 사용 내역 | K1: 100066029
A2: 8/10 송금 환율(1305.1) | E2: 100055945 | G2: 9/10 송금 환율(1381.2) | K2: 100055946 | L2: 1200000696
A3: 대계정 | B3: 소계정 | C3: 금액 (RMB) | D3: 금액 (USD) | E3: 금액 (KRW) | G3: 대계정 | H3: 소계정 | I3: 금액 (RMB) | J3: 금액 (USD) | K3: 금액 (KRW)
A4: 소모품비 | G4: 소모품비
A5: 업무추진비 | B5: 일반 | F5: 51131050 | G5: 업무추진비 | H5: 일반 | I5: 8344 | J5: 1201.9334 | K5: 1660106 | L5: =K5+E5 -> 1660106
A6: 여비교통비 | B6: 해외 | F6: 51061030 | G6: 여비교통비 | H6: 해외 | I6: 4939.87 | J6: 711.57652 | K6: 982834 | L6: =K6+E6 -> 982834
A7: 지급임차료 | B7: 사무실관리 | C7: 2057.7146 | D7: 306.26787 | E7: 399713 | F7: 51201020 | G7: 지급임차료 | H7: 사무실관리 | I7: 17382.285 | J7: 2503.8769 | K7: 3458359 | L7: =K7+E7 -> 3858072
A8: 지급임차료 | B8: 차량임차료 | F8: 51201030 | G8: 지급임차료 | H8: 차량임차료 | I8: 10500 | J8: 1512.5 | K8: 2089065 | L8: =K8+E8 -> 2089065
A9: 통신비 | B9: 기타 | F9: 51071700 | G9: 통신비 | H9: 기타 | I9: 297.5 | J9: 42.854167 | K9: 59184 | L9: =K9+E9 -> 59184
A10: 해외지사비 | F10: 51321010 | G10: 해외지사비 | I10: 123243.54 | J10: 17778.939 | K10: 24556272 | L10: =K10+E10 -> 24556272
A11: 보증금 | F11: 13081010 | G11: 보증금
A12: Total | C12: =SUM(C4:C11) -> 2057.7146 | D12: =SUM(D4:D11) -> 306.26787 | E12: =SUM(E4:E11) -> 399713 | F12: 52981010 | G12: Total | I12: =SUM(I4:I11) -> 164707.2 | J12: =SUM(J4:J11) -> 23751.68 | K12: =SUM(K4:K10) -> 32805820
C13: =C12+I12 -> 166764.91 | D13: =D12+J12 -> 24057.948 | E13: =E12+K12 -> 33205533 | K13: 16280.086 | L13: 2425.7418
A14: 보증금 | B14: 13081010 | H14: =SUBTOTAL(9,H17:H62) -> 28271.532 | I14: =SUBTOTAL(9,I17:I62) -> 166764.91 | J14: =SUBTOTAL(9,J17:J62) -> 24057.948
A15: 날짜 | B15: 내역 | D15: 증빙번호 | E15: 대계정 | F15: 소계정 | G15: 입금 | I15: 출금 | K15: 잔액 | M15: 비고
G16: RMB | H16: USD | I16: RMB | J16: USD | K16: RMB | L16: USD
A17: 44804 | B17: 기존 잔고 | K17: 2057.426 | L17: 306.26787 | N17: 306.26787
A18: 44818 | B18: 입금 | D18: 1 | G18: 196035.17 | H18: 28264.4 | K18: =K17+G18-I18 -> 198092.6 | L18: =L17+H18-J18 -> 28570.668 | M18: 입금
A19: 44818 | B19: 송금수수료 | E19: 해외지사비 | J19: 26 | K19: =K18+G19-I19 -> 198092.6 | L19: =L18+H19-J19 -> 28544.668
A20: 44823 | B20: 사무실 임대료_8월 | D20: 3 | E20: 지급임차료 | F20: 사무실임차 | I20: =J20*'통장내역(환율표)'!$D$41 -> 2057.7146 | J20: 306.26787 | K20: =K19+G20-I20 -> 196034.88 | L20: =L19+H20-J20 -> 28238.4 | M20: 사무실 임대료 | N20: =N17-J20+H20 -> 0
A21: 44823 | B21: 사무실 임대료_9월 | D21: 3 | E21: 지급임차료 | F21: 사무실임차 | I21: =19440-I20 -> 17382.285 | J21: =I21/'통장내역(환율표)'!$D$46 -> 2503.8769 | K21: =K20+G21-I21 -> 178652.6 | L21: =L20+H21-J21 -> 25734.523 | N21: =28238.4-J21+H21 -> 25734.523
A22: 44823 | B22: 은행수수료 | D22: 3 | E22: 해외지사비 | I22: 7.2 | J22: =I22/'통장내역(환율표)'!$D$46 -> 1.0371429 | K22: =K21+G22-I22 -> 178645.4 | L22: =L21+H22-J22 -> 25733.486 | N22: =N21-J22+H22 -> 25733.486
A23: 44825 | B23: 예금이자 | E23: 잡이익 | G23: 49.51 | H23: =G23/'통장내역(환율표)'!$D$46 -> 7.1317977 | J23: =I23/'통장내역(환율표)'!$D$46 -> 0 | K23: =K22+G23-I23 -> 178694.91 | L23: =L22+H23-J23 -> 25740.618 | N23: =N22-J23+H23 -> 25740.618
A24: 44827 | B24: 주재원 대행 수수료 | D24: 2 | E24: 해외지사비 | I24: 300 | J24: =I24/'통장내역(환율표)'!$D$46 -> 43.214286 | K24: =K23+G24-I24 -> 178394.91 | L24: =L23+H24-J24 -> 25697.403 | M24: 신순연 | N24: =N23-J24+H24 -> 25697.403
A25: 44827 | B25: 주재원 5대보험 | D25: 2 | E25: 해외지사비 | I25: 7572.43 | J25: =I25/'통장내역(환율표)'!$D$46 -> 1090.7905 | K25: =K24+G25-I25 -> 170822.48 | L25: =L24+H25-J25 -> 24606.613 | N25: =N24-J25+H25 -> 24606.613
A26: 44827 | B26: 주재원 개인소득세 | D26: 2 | E26: 해외지사비 | I26: 5104.59 | J26: =I26/'통장내역(환율표)'!$D$46 -> 735.30405 | K26: =K25+G26-I26 -> 165717.89 | L26: =L25+H26-J26 -> 23871.309 | M26: 신순연 | N26: =N25-J26+H26 -> 23871.309
A27: 44827 | B27: 주재원 수당 | D27: 2 | E27: 해외지사비 | I27: 13500 | J27: =I27/'통장내역(환율표)'!$D$46 -> 1944.6429 | K27: =K26+G27-I27 -> 152217.89 | L27: =L26+H27-J27 -> 21926.666 | M27: 신순연 | N27: =N26-J27+H27 -> 21926.666
A28: 44827 | B28: 주재원 주택 수당 | D28: 2 | E28: 해외지사비 | I28: 20000 | J28: =I28/'통장내역(환율표)'!$D$46 -> 2880.9524 | K28: =K27+G28-I28 -> 132217.89 | L28: =L27+H28-J28 -> 19045.714 | M28: 신순연 | N28: =N27-J28+H28 -> 19045.714
A29: 44827 | B29: 주재원 대행 수수료 | D29: 2 | E29: 해외지사비 | I29: 300 | J29: =I29/'통장내역(환율표)'!$D$46 -> 43.214286 | K29: =K28+G29-I29 -> 131917.89 | L29: =L28+H29-J29 -> 19002.499 | M29: 김명관 | N29: =N28-J29+H29 -> 19002.499
A30: 44827 | B30: 주재원 5대보험 | D30: 2 | E30: 해외지사비 | I30: 4197.43 | J30: =I30/'통장내역(환율표)'!$D$46 -> 604.62981 | K30: =K29+G30-I30 -> 127720.46 | L30: =L29+H30-J30 -> 18397.869 | M30: 김명관 | N30: =N29-J30+H30 -> 18397.869
A31: 44827 | B31: 주재원 개인소득세 | D31: 2 | E31: 해외지사비 | I31: 2114.3 | J31: =I31/'통장내역(환율표)'!$D$46 -> 304.55989 | K31: =K30+G31-I31 -> 125606.16 | L31: =L30+H31-J31 -> 18093.31 | M31: 김명관 | N31: =N30-J31+H31 -> 18093.31
A32: 44827 | B32: 주재원 수당 | D32: 2 | E32: 해외지사비 | I32: 13500 | J32: =I32/'통장내역(환율표)'!$D$46 -> 1944.6429 | K32: =K31+G32-I32 -> 112106.16 | L32: =L31+H32-J32 -> 16148.667 | M32: 김명관 | N32: =N31-J32+H32 -> 16148.667
A33: 44827 | B33: 주재원 주택 수당 | D33: 2 | E33: 해외지사비 | I33: 14000 | J33: =I33/'통장내역(환율표)'!$D$46 -> 2016.6667 | K33: =K32+G33-I33 -> 98106.156 | L33: =L32+H33-J33 -> 14132 | M33: 김명관 | N33: =N32-J33+H33 -> 14132
A34: 44827 | B34: 주재원 대행 수수료 | D34: 2 | E34: 해외지사비 | I34: 300 | J34: =I34/'통장내역(환율표)'!$D$46 -> 43.214286 | K34: =K33+G34-I34 -> 97806.156 | L34: =L33+H34-J34 -> 14088.786 | M34: 현채인 | N34: =N33-J34+H34 -> 14088.786
A35: 44827 | B35: 주재원 5대보험 | D35: 2 | E35: 해외지사비 | I35: 8295.14 | J35: =I35/'통장내역(환율표)'!$D$46 -> 1194.8952 | K35: =K34+G35-I35 -> 89511.016 | L35: =L34+H35-J35 -> 12893.891 | M35: 현채인 | N35: =N34-J35+H35 -> 12893.891
A36: 44827 | B36: 주재원 개인소득세 | D36: 2 | E36: 해외지사비 | I36: 1493.42 | J36: =I36/'통장내역(환율표)'!$D$46 -> 215.1236 | K36: =K35+G36-I36 -> 88017.596 | L36: =L35+H36-J36 -> 12678.767 | M36: 현채인 | N36: =N35-J36+H36 -> 12678.767
A37: 44827 | B37: 주재원 수당 | D37: 2 | E37: 해외지사비 | I37: 20229.17 | J37: =I37/'통장내역(환율표)'!$D$46 -> 2913.9638 | K37: =K36+G37-I37 -> 67788.426 | L37: =L36+H37-J37 -> 9764.8031 | M37: 현채인 | N37: =N36-J37+H37 -> 9764.8031
A38: 44827 | B38: 은행수수료 | D38: 2 | E38: 해외지사비 | I38: 12 | J38: =I38/'통장내역(환율표)'!$D$46 -> 1.7285715 | K38: =K37+G38-I38 -> 67776.426 | L38: =L37+H38-J38 -> 9763.0745 | N38: =N37-J38+H38 -> 9763.0745
A39: 44827 | B39: 차량 Rent비 | D39: 4 | E39: 지급임차료 | F39: 차량 | I39: 10500 | J39: =I39/'통장내역(환율표)'!$D$46 -> 1512.5 | K39: =K38+G39-I39 -> 57276.426 | L39: =L38+H39-J39 -> 8250.5745 | M39: 차량 Rent비 | N39: =N38-J39+H39 -> 8250.5745
A40: 44827 | B40: 차량 기사비 | D40: 4 | E40: 해외지사비 | I40: 6000 | J40: =I40/'통장내역(환율표)'!$D$46 -> 864.28573 | K40: =K39+G40-I40 -> 51276.426 | L40: =L39+H40-J40 -> 7386.2888 | N40: =N39-J40+H40 -> 7386.2888
...

Sheet 내역_22.10
A1: 10월 전도금 사용 내역 | K1: 100066029
A2: 9/10 송금 환율(1381.2) | E2: 100068838 | G2: 10/10 송금 환율(1,410.3) | K2: 100062087 | L2: 1200000696
A3: 대계정 | B3: 소계정 | C3: 금액 (RMB) | D3: 금액 (USD) | E3: 금액 (KRW) | G3: 대계정 | H3: 소계정 | I3: 금액 (RMB) | J3: 금액 (USD) | K3: 금액 (KRW)
A4: 소모품비 | G4: 소모품비
A5: 업무추진비 | B5: 일반 | F5: 51131050 | G5: 업무추진비 | H5: 일반 | I5: 2088 | J5: 292.34114 | K5: 412287 | L5: =K5+E5 -> 412287
A6: 여비교통비 | B6: 해외 | F6: 51061030 | G6: 여비교통비 | H6: 해외 | I6: 16155.48 | J6: 2261.9308 | K6: 3190000 | L6: =K6+E6 -> 3190000
A7: 지급임차료 | B7: 사무실관리 | C7: 11215.001 | D7: 1615.4941 | E7: 2231315 | F7: 51201020 | G7: 지급임차료 | H7: 사무실관리 | I7: 8224.9995 | J7: 1151.5832 | K7: 1624073 | L7: =K7+E7 -> 3855388
A8: 지급임차료 | B8: 차량임차료 | F8: 51201030 | G8: 지급임차료 | H8: 차량임차료 | I8: 10500 | J8: 1470.1063 | K8: 2073296 | L8: =K8+E8 -> 2073296
A9: 통신비 | B9: 기타 | F9: 51071700 | G9: 통신비 | H9: 기타 | I9: 1129 | J9: 158.07143 | K9: 222926 | L9: =K9+E9 -> 222926
A10: 해외지사비 | C10: 23259.73 | D10: 3350.5088 | E10: 4627724 | F10: 51321010 | G10: 해외지사비 | I10: 135794.1 | J10: 19272.37 | K10: 27179823 | L10: =K10+E10 -> 31807547
A11: 보증금 | F11: 13081010 | G11: 보증금
A12: Total | C12: =SUM(C4:C11) -> 34474.731 | D12: =SUM(D4:D11) -> 4966.0029 | E12: =SUM(E4:E11) -> 6859039 | F12: 52981010 | G12: Total | I12: =SUM(I4:I11) -> 173891.58 | J12: =SUM(J4:J11) -> 24606.403 | K12: =SUM(K4:K10) -> 34702405
C13: =C12+I12 -> 208366.31 | D13: =D12+J12 -> 29572.406 | E13: =E12+K12 -> 41561444 | K13: 16280.086 | L13: 2425.7418
A14: 보증금 | B14: 13081010 | H14: =SUBTOTAL(9,H17:H69) -> 29965.843 | I14: =SUBTOTAL(9,I17:I87) -> 210036.34 | J14: =SUBTOTAL(9,J17:J85) -> 29572.406
A15: 날짜 | B15: 내역 | D15: 증빙번호 | E15: 대계정 | F15: 소계정 | G15: 입금 | I15: 출금 | K15: 잔액 | M15: 비고
G16: RMB | H16: USD | I16: RMB | J16: USD | K16: RMB | L16: USD
A17: 44804 | B17: 기존 잔고 | K17: 31377.2 | L17: 4519.852 | N17: 4519.85
A18: 44848 | B18: 입금 | D18: 1 | G18: 210653.98 | H18: 29519.69 | K18: =K17+G18-I18 -> 242031.18 | L18: =L17+H18-J18 -> 34039.542 | M18: 입금
A19: 44848 | B19: 송금수수료 | E19: 해외지사비 | J19: 26 | K19: =K18+G19-I19 -> 242031.18 | L19: =L18+H19-J19 -> 34013.542
A20: 44858 | B20: 9월 사무실 관리비 중복 입금 반환 입금 | D20: 2 | E20: 해외지사비 | G20: 3097.26 | H20: =G20/'통장내역(환율표)'!$D$46 -> 446.15294 | I20: 0 | J20: =I20/'통장내역(환율표)'!$D$46 -> 0 | K20: =K19+G20-I20 -> 245128.44 | L20: =L19+H20-J20 -> 34459.695 | N20: =N17-J20+H20 -> 4966.0029
A21: 44859 | B21: 사무실 운영세금(7, 8, 9월 분) | D21: 3 | E21: 해외지사비 | I21: 23259.73 | J21: =I21/'통장내역(환율표)'!$D$46 -> 3350.5088 | K21: =K20+G21-I21 -> 221868.71 | L21: =L20+H21-J21 -> 31109.186 | N21: =N20-J21+H21 -> 1615.4941
A22: 44859 | B22: 사무실 임대료_9월 환율 | D22: 4 | E22: 지급임차료 | F22: 사무실임차 | I22: =J22*'통장내역(환율표)'!$D$46 -> 11215.001 | J22: 1615.4941 | K22: =K21+G22-I22 -> 210653.71 | L22: =L21+H22-J22 -> 29493.692 | N22: =N21-J22+H22 -> 0
A23: 44859 | B23: 사무실 임대료_10월 환율 | D23: 4 | E23: 지급임차료 | F23: 사무실임차 | I23: =19440-I22 -> 8224.9995 | J23: =I23/'통장내역(환율표)'!$D$53 -> 1151.5832 | K23: =K22+G23-I23 -> 202428.71 | L23: =L22+H23-J23 -> 28342.109 | N23: =29493.69-J23 -> 28342.107
A24: 44859 | B24: 은행수수료 | D24: 4 | E24: 해외지사비 | I24: 7.2 | J24: =I24/'통장내역(환율표)'!$D$53 -> 1.0080729 | K24: =K23+G24-I24 -> 202421.51 | L24: =L23+H24-J24 -> 28341.101 | N24: =N23-J24+H24 -> 28341.099
A25: 44859 | B25: 차량 Rent비 | D25: 5 | E25: 지급임차료 | F25: 차량임차료 | I25: 10500 | J25: =I25/'통장내역(환율표)'!$D$53 -> 1470.1063 | K25: =K24+G25-I25 -> 191921.51 | L25: =L24+H25-J25 -> 26870.994 | N25: =N24-J25+H25 -> 26870.992
A26: 44859 | B26: 차량 기사비 | D26: 5 | E26: 해외지사비 | I26: 6000 | J26: =I26/'통장내역(환율표)'!$D$53 -> 840.06075 | K26: =K25+G26-I26 -> 185921.51 | L26: =L25+H26-J26 -> 26030.934 | N26: =N25-J26+H26 -> 26030.932
A27: 44859 | B27: 기사 야근비용 | D27: 5 | E27: 해외지사비 | I27: 300 | J27: =I27/'통장내역(환율표)'!$D$53 -> 42.003037 | K27: =K26+G27-I27 -> 185621.51 | L27: =L26+H27-J27 -> 25988.931 | N27: =N26-J27+H27 -> 25988.929
A28: 44859 | B28: 은행수수료 | D28: 5 | E28: 해외지사비 | I28: 7.2 | J28: =I28/'통장내역(환율표)'!$D$53 -> 1.0080729 | K28: =K27+G28-I28 -> 185614.31 | L28: =L27+H28-J28 -> 25987.923 | N28: =N27-J28+H28 -> 25987.921
A29: 44859 | B29: 세무대행비 | D29: 6 | E29: 해외지사비 | I29: 1000 | J29: =I29/'통장내역(환율표)'!$D$53 -> 140.01012 | K29: =K28+G29-I29 -> 184614.31 | L29: =L28+H29-J29 -> 25847.912 | N29: =N28-J29+H29 -> 25847.91
A30: 44859 | B30: 은행수수료 | D30: 6 | E30: 해외지사비 | I30: 3.6 | J30: =I30/'통장내역(환율표)'!$D$53 -> 0.50403645 | K30: =K29+G30-I30 -> 184610.71 | L30: =L29+H30-J30 -> 25847.408 | N30: =N29-J30+H30 -> 25847.406
A31: 44859 | B31: 사무실 에어컨 및 전기/물 비용 | D31: 7 | E31: 해외지사비 | I31: 2040.13 | J31: =I31/'통장내역(환율표)'!$D$53 -> 285.63886 | K31: =K30+G31-I31 -> 182570.58 | L31: =L30+H31-J31 -> 25561.77 | M31: 신순연 | N31: =N30-J31+H31 -> 25561.768
A32: 44859 | B32: 은행수수료 | D32: 7 | E32: 해외지사비 | I32: 3.6 | J32: =I32/'통장내역(환율표)'!$D$53 -> 0.50403645 | K32: =K31+G32-I32 -> 182566.98 | L32: =L31+H32-J32 -> 25561.266 | N32: =N31-J32+H32 -> 25561.264
A33: 44859 | B33: 주유비, 주차비, 톨비 | D33: 8 | E33: 여비교통비 | F33: 해외 | I33: 2205 | J33: =I33/'통장내역(환율표)'!$D$53 -> 308.72232 | K33: =K32+G33-I33 -> 180361.98 | L33: =L32+H33-J33 -> 25252.543 | M33: 주유비 1291, 주치바 900, 톨비 14 | N33: =N32-J33+H33 -> 25252.541
A34: 44859 | B34: 은행수수료 | D34: 8 | E34: 해외지사비 | I34: 3.6 | J34: =I34/'통장내역(환율표)'!$D$53 -> 0.50403645 | K34: =K33+G34-I34 -> 180358.38 | L34: =L33+H34-J34 -> 25252.039 | N34: =N33-J34+H34 -> 25252.037
A35: 44859 | B35: 주재원 대행 수수료 | D35: 9 | E35: 해외지사비 | I35: 300 | J35: =I35/'통장내역(환율표)'!$D$53 -> 42.003037 | K35: =K34+G35-I35 -> 180058.38 | L35: =L34+H35-J35 -> 25210.036 | M35: 신순연 | N35: =N34-J35+H35 -> 25210.034
A36: 44859 | B36: 주재원 5대보험 | D36: 9 | E36: 해외지사비 | I36: 7599.43 | J36: =I36/'통장내역(환율표)'!$D$53 -> 1063.9971 | K36: =K35+G36-I36 -> 172458.95 | L36: =L35+H36-J36 -> 24146.039 | M36: 신순연 | N36: =N35-J36+H36 -> 24146.037
A37: 44859 | B37: 주재원 개인소득세 | D37: 9 | E37: 해외지사비 | I37: 5104.58 | J37: =I37/'통장내역(환율표)'!$D$53 -> 714.69288 | K37: =K36+G37-I37 -> 167354.37 | L37: =L36+H37-J37 -> 23431.346 | M37: 신순연 | N37: =N36-J37+H37 -> 23431.344
A38: 44859 | B38: 주재원 수당 | D38: 9 | E38: 해외지사비 | I38: 13500 | J38: =I38/'통장내역(환율표)'!$D$53 -> 1890.1367 | K38: =K37+G38-I38 -> 153854.37 | L38: =L37+H38-J38 -> 21541.209 | M38: 신순연 | N38: =N37-J38+H38 -> 21541.207
A39: 44859 | B39: 주재원 주택 수당 | D39: 9 | E39: 해외지사비 | I39: 20000 | J39: =I39/'통장내역(환율표)'!$D$53 -> 2800.2025 | K39: =K38+G39-I39 -> 133854.37 | L39: =L38+H39-J39 -> 18741.007 | M39: 신순연 | N39: =N38-J39+H39 -> 18741.005
A40: 44859 | B40: 주재원 대행 수수료 | D40: 9 | E40: 해외지사비 | I40: 300 | J40: =I40/'통장내역(환율표)'!$D$53 -> 42.003037 | K40: =K39+G40-I40 -> 133554.37 | L40: =L39+H40-J40 -> 18699.004 | M40: 김명관 | N40: =N39-J40+H40 -> 18699.002
...

Sheet 내역_22.11
A1: 11월 전도금 사용 내역 | K1: 100066029
A2: 10/10 송금 환율(1,410.3) | E2: 100069659 | G2: 11/10 송금 환율(1368.3) | K2: 100069665 | L2: 1200000696
A3: 대계정 | B3: 소계정 | C3: 금액 (RMB) | D3: 금액 (USD) | E3: 금액 (KRW) | G3: 대계정 | H3: 소계정 | I3: 금액 (RMB) | J3: 금액 (USD) | K3: 금액 (KRW)
A4: 소모품비 | G4: 소모품비
A5: 업무추진비 | B5: 일반 | F5: 51131050 | G5: 업무추진비 | H5: 일반 | I5: 4902 | J5: 685.39111 | K5: 937819 | L5: =K5+E5 -> 937819
A6: 여비교통비 | B6: 해외 | F6: 51061030 | G6: 여비교통비 | H6: 해외 | I6: 3271.04 | J6: 457.35246 | K6: 625792 | L6: =K6+E6 -> 625792
A7: 지급임차료 | B7: 사무실관리 | F7: 51201020 | G7: 지급임차료 | H7: 사무실관리 | I7: 19440 | J7: 2718.0749 | K7: 3719135 | L7: =K7+E7 -> 3719135
A8: 지급임차료 | B8: 차량임차료 | F8: 51201030 | G8: 지급임차료 | H8: 차량임차료 | I8: 10500 | J8: 1468.096 | K8: 2008801 | L8: =K8+E8 -> 2008801
A9: 통신비 | B9: 기타 | F9: 51071700 | G9: 통신비 | H9: 기타 | I9: 695 | J9: 97.173975 | K9: 132958 | L9: =K9+E9 -> 132958
A10: 해외지사비 | C10: 35092.369 | D10: 4913.287 | E10: 6929213 | F10: 51321010 | G10: 해외지사비 | I10: 87962.151 | J10: 12324.751 | K10: 16863955 | L10: =K10+E10 -> 23793168
A11: 보증금 | F11: 13081010 | G11: 보증금
A12: Total | C12: =SUM(C4:C11) -> 35092.369 | D12: =SUM(D4:D11) -> 4913.287 | E12: =SUM(E4:E11) -> 6929213 | F12: 52981010 | G12: Total | I12: =SUM(I4:I11) -> 126770.19 | J12: =SUM(J4:J11) -> 17750.839 | K12: =SUM(K4:K10) -> 24288460
C13: =C12+I12 -> 161862.56 | D13: =D12+J12 -> 22664.126 | E13: =E12+K12 -> 31217673 | K13: 16280.086 | L13: 2425.7418
A14: 보증금 | B14: 13081010 | H14: =SUBTOTAL(9,H17:H64) -> 22744.4 | I14: =SUBTOTAL(9,I17:I79) -> 161862.56 | J14: =SUBTOTAL(9,J17:J77) -> 22664.12
A15: 날짜 | B15: 내역 | D15: 증빙번호 | E15: 대계정 | F15: 소계정 | G15: 입금 | I15: 출금 | K15: 잔액 | M15: 비고
G16: RMB | H16: USD | I16: RMB | J16: USD | K16: RMB | L16: USD
A17: 44865 | B17: 기존 잔고 | K17: 35092.099 | L17: 4913.289 | N17: 4913.287
A18: 44876 | B18: USD 입금 | G18: 162484.74 | H18: 22744.4 | K18: =K17+G18-I18 -> 197576.84 | L18: =L17+H18-J18 -> 27657.689
A19: 44876 | B19: 은행수수료 | D19: 1 | E19: 해외지사비 | J19: 26 | K19: =K18+G19-I19 -> 197576.84 | L19: =L18+H19-J19 -> 27631.689
A20: 44890 | B20: 주재원 대행 수수료 | D20: 2 | E20: 해외지사비 | I20: 300 | J20: =I20/'통장내역(환율표)'!$D$53 -> 42.003037 | K20: =K19+G20-I20 -> 197276.84 | L20: =L19+H20-J20 -> 27589.686 | M20: 신순연 | N20: =N17-J20+H20 -> 4871.2839
A21: 44890 | B21: 주재원 5대보험 | D21: 2 | E21: 해외지사비 | I21: 7599.43 | J21: =I21/'통장내역(환율표)'!$D$53 -> 1063.9971 | K21: =K20+G21-I21 -> 189677.41 | L21: =L20+H21-J21 -> 26525.689 | M21: 신순연 | N21: =N20-J21+H21 -> 3807.2868
