Workbook
Name Large_scale_classification: [1]Sheet3!$C$4:$C$10

Sheet 통장내역(환율표)
B2: 통장 일자 | C2: 지급 | F2: 송금액 | I2: 입금 | K2: 출금 | M2: 잔액
C3: 지급시 환율 | D3: 환산요율 | E3: 전표번호 | F3: USD | G3: 수수료 | H3: RMB | I3: USD | J3: RMB | K3: USD | L3: RMB | M3: USD | N3: RMB
B4: 45854 | F4: 74022.44 | N4: =H4-L4 -> 0
B5: 45854 | C5: 1373.8 | D5: =-H5/F5 -> 7.1674 | E5: 2000001679 | F5: -73987.44 | H5: 530297.58 | K5: 35 | L5: 73092 | N5: =H5-L5 -> 457205.58
B6: 45855 | L6: 2403.6 | N6: =N5-L6 -> 454801.98
B7: 45860 | L7: 28287.2 | N7: =N6-L7 -> 426514.78
B8: 45862 | L8: 345390.38 | N8: =N7-L8 -> 81124.4
B9: 45863 | L9: 80014.4 | N9: =N8-L9 -> 1110
N10: =N9 -> 1110
B11: 45881 | F11: 66958.93 | N11: =N10+H11-L11 -> 1110
B12: 45881 | C12: 1384.2 | D12: =-H12/F12 -> 7.1783 | E12: 2000001943 | F12: -66933.93 | H12: 480471.83 | K12: 25 | N12: =N11+H12-L12 -> 481581.83
B13: 45883 | L13: 1110.0568 | N13: =N12+H13-L13 -> 480471.77
B14: 45883 | L14: 26430.74 | N14: =N13+H14-L14 -> 454041.03
B15: 45887 | L15: 33.6 | N15: =N14+H15-L15 -> 454007.43
B16: 45888 | L16: 148030.18 | N16: =N15+H16-L16 -> 305977.25
B17: 45889 | L17: 292153.69 | N17: =N16+H17-L17 -> 13823.563
N18: =N17+H18-L18 -> 13823.563
B19: 45910 | L19: 243.6 | N19: =N18+H19-L19 -> 13579.963
B20: 45911 | F20: 58404.05 | N20: =N19+H20-L20 -> 13579.963
B21: 45911 | C21: 1386.6 | D21: =-H21/F21 -> 7.1105999 | E21: 2000002211 | F21: -58379.05 | H21: 415110.07 | K21: 25 | N21: =N20+H21-L21 -> 428690.03
B22: 45915 | L22: 13580.058 | N22: =N21+H22-L22 -> 415109.98
B23: 45915 | L23: 13975.74 | N23: =N22+H23-L23 -> 401134.24
B24: 45921 | J24: 32.36 | N24: =N23+H24-L24+J24 -> 401166.6
B25: 45923 | L25: 399903.2 | N25: =N24+H25-L25 -> 1263.3953
N26: =N25+H26-L26 -> 1263.3953
B27: 45943 | F27: 76124.43 | N27: =N26+H27-L27 -> 1263.3953
B28: 45943 | C28: 1401.9 | D28: =-H28/F28 -> 7.1165 | E28: 2000002505 | F28: -76099.43 | H28: 541561.59 | K28: 25 | N28: =N27+H28-L28 -> 542824.99
B29: 45945 | L29: 1263.4825 | N29: =N28+H29-L29 -> 541561.5
B30: 45945 | L30: 26248.32 | N30: =N29+H30-L30 -> 515313.18
B31: 45952 | L31: 57279.62 | N31: =N30+H31-L31 -> 458033.56
B32: 45953 | L32: 435679.23 | N32: =N31+H32-L32 -> 22354.333
N33: =N32+H33-L33 -> 22354.333
B34: 45974 | F34: 58100.87 | N34: =N33+H34-L34 -> 22354.333
B35: 45974 | C35: 1454 | D35: =-H35/F35 -> 7.0841 | E35: 2000002746 | F35: -58075.87 | H35: 411415.27 | K35: 25 | N35: =N34+H35-L35 -> 433769.6
B36: 45975 | L36: 22335.89 | N36: =N35+H36-L36 -> 411433.71
B37: 45975 | L37: 5111.91 | N37: =N36+H37-L37 -> 406321.8
B38: 45985 | L38: 377571.91 | N38: =N37+H38-L38 -> 28749.893
N39: =N38 -> 28749.893
B40: 46002 | F40: 60766.8 | N40: =N39+H40-L40 -> 28749.893
B41: 46002 | C41: 1470.4 | D41: =-H41/F41 -> 7.0497 | E41: 2000003021 | F41: -60741.8 | H41: 428211.47 | K41: 25 | N41: =N40+H41-L41 -> 456961.36
...

Sheet 내역_25.01
B2: ▶ 25년 1월 전도금 정산 내역 (심천지사)_4000061 (B2F590) | H2: 보증금 입금 내역_1,234.5 (#1900000828 / #1200000234 / #100013313)
B3: 24년 12월 송금_1,433.2(#) | F3: 1433.2 | H3: 25년 1월 송금_1458.2(#) | L3: 1458.2 | N3: 25년 1월 2차 송금_1,434.30 (#) | R3: 1434.3 | X3: 1327.2
B4: 대계정 | C4: 소계정 | D4: 금액 (CNY) | E4: 금액 (USD) | F4: 금액 (KRW) | H4: 대계정 | I4: 소계정 | J4: 금액 (CNY) | K4: 금액 (USD) | L4: 금액 (KRW) | N4: 대계정 | O4: 소계정 | P4: 금액 (CNY) | Q4: 금액 (USD) | R4: 금액 (KRW)
A5: 51131050 | B5: 업무추진비 | C5: 일반 | F5: =ROUND(E5*$F$3,0) -> 0 | H5: 업무추진비 | I5: 일반 | J5: 30124.08 | K5: 4115.82 | L5: =ROUND(K5*$L$3,0) -> 6001689 | M5: =L5+F5 -> 6001689 | N5: 업무추진비 | O5: 일반 | R5: =ROUND(Q5*$R$3,0) -> 0 | S5: =F5+L5+R5 -> 6001689
A6: 51061030 | B6: 여비교통비 | C6: 해외 | D6: 1600 | E6: 220.27 | F6: =ROUND(E6*$F$3,0) -> 315691 | H6: 여비교통비 | I6: 해외 | J6: 23408.08 | K6: 3198.22 | L6: =ROUND(K6*$L$3,0) -> 4663644 | M6: =L6+F6 -> 4979335 | N6: 여비교통비 | O6: 해외 | R6: =ROUND(Q6*$R$3,0) -> 0 | S6: =F6+L6+R6 -> 4979335
A7: 51201020 | B7: 지급임차료 | C7: 사무실임차료 | D7: 24455 | E7: 3366.74 | F7: =ROUND(E7*$F$3,0) -> 4825212 | H7: 지급임차료 | I7: 사무실임차료 | L7: =ROUND(K7*$L$3,0) -> 0 | M7: =L7+F7 -> 4825212 | N7: 지급임차료 | O7: 사무실임차료 | R7: =ROUND(Q7*$R$3,0) -> 0 | S7: =F7+L7+R7 -> 4825212
A8: 51201030 | B8: 지급임차료 | C8: 차량임차료 | D8: 8307.64 | E8: 1143.72 | F8: =ROUND(E8*$F$3,0) -> 1639180 | H8: 지급임차료 | I8: 차량임차료 | J8: 9192.36 | K8: 1255.94 | L8: =ROUND(K8*$L$3,0) -> 1831412 | M8: =L8+F8 -> 3470592 | N8: 지급임차료 | O8: 차량임차료 | R8: =ROUND(Q8*$R$3,0) -> 0 | S8: =F8+L8+R8 -> 3470592
A9: 51071700 | B9: 통신비 | C9: 기타 | F9: =ROUND(E9*$F$3,0) -> 0 | H9: 통신비 | I9: 기타 | J9: 1412.84 | K9: 193.03 | L9: =ROUND(K9*$L$3,0) -> 281476 | M9: =L9+F9 -> 281476 | N9: 통신비 | O9: 기타 | R9: =ROUND(Q9*$R$3,0) -> 0 | S9: =F9+L9+R9 -> 281476
A10: 51321010 | B10: 해외지사비 | D10: 43977.03 | E10: 6054.36 | F10: =ROUND(E10*$F$3,0) -> 8677109 | H10: 해외지사비 | J10: 331930.54 | K10: 45402.28 | L10: =ROUND(K10*$L$3,0) -> 66205605 | M10: =L10+F10 -> 74882714 | N10: 해외지사비 | R10: =ROUND(Q10*$R$3,0) -> 0 | S10: =F10+L10+R10 -> 74882714
A11: 51031020 | B11: 급여(incentive) | C11: 성과급여조정 | F11: =ROUND(E11*$F$3,0) -> 0 | G11: =G13/G12 -> 1433.2038 | H11: 급여(incentive) | I11: 포상금 | L11: =ROUND(K11*$L$3,0) -> 0 | M11: =L11+F11 -> 0 | N11: 급여(incentive) | O11: 포상금 | Q11: 36 | R11: =ROUND(Q11*$R$3,0) -> 51635 | S11: =F11+L11+R11 -> 51635
A12: 52981010 | B12: (-)잡이익(50) | C12: (-)잡이익 | F12: =ROUND(E12*$F$3,0) -> 0 | G12: =E13+Q13+AB13 -> 10821.09 | H12: (-)잡이익(50) | I12: (-)잡이익 | L12: =ROUND(K12*$L$3,0) -> 0 | M12: =L12+F12 -> 0 | N12: (-)잡이익(50) | O12: (-)잡이익 | R12: =ROUND(Q12*$R$3,0) -> 0 | S12: =F12+L12+R12 -> 0
B13: Total | D13: =SUM(D5:D11)-D12 -> 78339.67 | E13: =SUM(E5:E11)-E12 -> 10785.09 | F13: =SUM(F5:F11)-F12 -> 15457192 | G13: =F13+R13+AC13 -> 15508827 | H13: Total | J13: =SUM(J5:J11)-J12 -> 396067.9 | K13: =SUM(K5:K11)-K12 -> 54165.29 | L13: =SUM(L5:L11)-L12 -> 78983826 | M13: =L13+F13 -> 94441018 | N13: Total | P13: =SUM(P5:P11)-P12 -> 0 | Q13: =SUM(Q5:Q11)-Q12 -> 36 | R13: =SUM(R5:R11)-R12 -> 51635 | S13: =F13+L13+R13 -> 94492653 | X13: =F13+R13 -> 15508827
D14: =SUM(D7:D10) -> 76739.67 | E14: =SUM(E7:E10) -> 10564.82 | F14: =SUM(F7:F10) -> 15141501 | J14: =J13+D13+P13 -> 474407.57 | K14: =K13+E13+Q13 -> 64986.38 | L14: =L13+F13+R13 -> 94492653 | M14: =M16-E12 -> 64950.382 | P14: =P13+D13+J13 -> 474407.57 | Q14: =Q13+E13+K13 -> 64986.38 | R14: =R13+F13+L13 -> 94492653
K15: =K16-H85 -> 474407.57 | M15: =M16-J85 -> 64950.382
K16: =SUBTOTAL(9,K19:K103) -> 474407.57 | M16: =SUBTOTAL(9,M19:M103) -> 64950.382
B17: 날짜 | C17: 내역 | D17: 담당자 | E17: 증빙번호 | F17: 대계정 | G17: 소계정 | H17: 입금 | K17: 출금 | N17: 잔액 | R17: 항목
B18: 날짜 | C18: 내역 | D18: 담당자 | E18: 증빙번호 | F18: 대계정 | G18: 소계정 | H18: CNY | I18: 환산요율 | J18: USD | K18: CNY | L18: 환산요율 | M18: USD | N18: CNY | O18: USD | P18: 비고 | R18: 항목
B19: 45657 | N19: 78313.1 | O19: 10785.092 | S19: 10785.091
B20: 45667 | C20: 4분기 세금 비용 | E20: 1 | F20: 해외지사비 | K20: 42812.63 | L20: ='[2]통장내역(환율표)'!$D$238 -> 7.2637 | M20: =K20/L20 -> 5894.0526 | N20: =N19+H20-K20 -> 35500.47 | O20: =O19+J20-M20 -> 4891.0398 | P20: 12월 송금 | S20: =S19-M20 -> 4891.0387
B21: 45670 | C21: USD입금 and RMB 환전 | E21: 2 | H21: 473948.32 | J21: 64806 | N21: =N20+H21-K21 -> 509448.79 | O21: =O20+J21-M21 -> 69697.04
B22: 45670 | C22: 은행수수료 | E22: 2 | F22: 해외지사비 | M22: 51 | N22: =N21+H22-K22 -> 509448.79 | O22: =O21+J22-M22 -> 69646.04
B23: 45672 | C23: DB HITEK조회확인서 수수료 | E23: 3 | F23: 해외지사비 | K23: 140 | L23: ='[2]통장내역(환율표)'!$D$238 -> 7.2637 | M23: =K23/L23 -> 19.273924 | N23: =N22+H23-K23 -> 509308.79 | O23: =O22+J23-M23 -> 69626.766 | P23: 12월 송금 | S23: =S20-M23 -> 4871.7648
B24: 45672 | C24: 사무실 임대료/전기세 관련 | E24: 4 | F24: 지급임차료 | G24: 사무실 | K24: 24455 | L24: ='[2]통장내역(환율표)'!$D$238 -> 7.2637 | M24: =K24/L24 -> 3366.7415 | N24: =N23+H24-K24 -> 484853.79 | O24: =O23+J24-M24 -> 66260.024 | P24: 12월 송금 | S24: =S23-M24 -> 1505.0233
B25: 45672 | C25: 은행수수료 | E25: 5 | F25: 해외지사비 | K25: 7.2 | L25: ='[2]통장내역(환율표)'!$D$238 -> 7.2637 | M25: =K25/L25 -> 0.99123036 | N25: =N24+H25-K25 -> 484846.59 | O25: =O24+J25-M25 -> 66259.033 | P25: 12월 송금 | S25: =S24-M25 -> 1504.0321
B26: 45672 | C26: 사무실 주차비 | E26: 6 | F26: 여비교통비 | G26: 해외 | K26: 1600 | L26: ='[2]통장내역(환율표)'!$D$238 -> 7.2637 | M26: =K26/L26 -> 220.27341 | N26: =N25+H26-K26 -> 483246.59 | O26: =O25+J26-M26 -> 66038.76 | P26: 12월 송금 | S26: =S25-M26 -> 1283.7587
B27: 45672 | C27: 은행수수료 | E27: 7 | F27: 해외지사비 | K27: 3.6 | L27: ='[2]통장내역(환율표)'!$D$238 -> 7.2637 | M27: =K27/L27 -> 0.49561518 | N27: =N26+H27-K27 -> 483242.99 | O27: =O26+J27-M27 -> 66038.264 | P27: 12월 송금 | S27: =S26-M27 -> 1283.2631
B28: 45674 | C28: 세무대행비 | E28: 8 | F28: 해외지사비 | K28: 1010 | L28: ='[2]통장내역(환율표)'!$D$238 -> 7.2637 | M28: =K28/L28 -> 139.04759 | N28: =N27+H28-K28 -> 482232.99 | O28: =O27+J28-M28 -> 65899.217 | P28: 12월 송금 | S28: =S27-M28 -> 1144.2155
B29: 45674 | C29: 은행수수료 | E29: 9 | F29: 해외지사비 | K29: 3.6 | L29: ='[2]통장내역(환율표)'!$D$238 -> 7.2637 | M29: =K29/L29 -> 0.49561518 | N29: =N28+H29-K29 -> 482229.39 | O29: =O28+J29-M29 -> 65898.721 | P29: 12월 송금 | S29: =S28-M29 -> 1143.7198
B30: 45674 | C30: 차량 Rent비 | E30: 10 | F30: 지급임차료 | G30: 차량임차료 | K30: =L30*M30 -> 8307.6379 | L30: ='[2]통장내역(환율표)'!$D$238 -> 7.2637 | M30: 1143.7198 | N30: =N29+H30-K30 -> 473921.75 | O30: =O29+J30-M30 -> 64755.001 | P30: 12월 송금 | S30: =S29-M30 -> -3.4106051e-12
B31: 45674 | C31: 차량 Rent비 | E31: 10 | F31: 지급임차료 | G31: 차량임차료 | K31: =10500-K30 -> 2192.3621 | L31: ='[2]통장내역(환율표)'!$D$246 -> 7.3191 | M31: =K31/L31 -> 299.53985 | N31: =N30+H31-K31 -> 471729.39 | O31: =O30+J31-M31 -> 64455.461 | P31: 1월 송금 | S31: =64755-M31 -> 64455.46
B32: 45674 | C32: 차량 기사비 | E32: 10 | F32: 해외지사비 | K32: 6000 | L32: ='[2]통장내역(환율표)'!$D$246 -> 7.3191 | M32: =K32/L32 -> 819.77292 | N32: =N31+H32-K32 -> 465729.39 | O32: =O31+J32-M32 -> 63635.688 | P32: 1월 송금 | S32: =S31-M32 -> 63635.687
B33: 45674 | C33: 기사 야근비용 | E33: 10 | F33: 해외지사비 | K33: 610 | L33: ='[2]통장내역(환율표)'!$D$246 -> 7.3191 | M33: =K33/L33 -> 83.343581 | N33: =N32+H33-K33 -> 465119.39 | O33: =O32+J33-M33 -> 63552.345 | P33: 1월 송금 | S33: =S32-M33 -> 63552.344
B34: 45674 | C34: 차량 Rent비 | E34: 10 | F34: 지급임차료 | G34: 차량임차료 | K34: 7000 | L34: ='[2]통장내역(환율표)'!$D$246 -> 7.3191 | M34: =K34/L34 -> 956.40174 | N34: =N33+H34-K34 -> 458119.39 | O34: =O33+J34-M34 -> 62595.943 | P34: 1월 송금 | S34: =S33-M34 -> 62595.942
B35: 45674 | C35: 차량 기사비 | E35: 10 | F35: 해외지사비 | K35: 6000 | L35: ='[2]통장내역(환율표)'!$D$246 -> 7.3191 | M35: =K35/L35 -> 819.77292 | N35: =N34+H35-K35 -> 452119.39 | O35: =O34+J35-M35 -> 61776.17 | P35: 1월 송금 | S35: =S34-M35 -> 61776.169
B36: 45674 | C36: 기사 야근비용 | E36: 10 | F36: 해외지사비 | K36: 510 | L36: ='[2]통장내역(환율표)'!$D$246 -> 7.3191 | M36: =K36/L36 -> 69.680699 | N36: =N35+H36-K36 -> 451609.39 | O36: =O35+J36-M36 -> 61706.489 | P36: 1월 송금 | S36: =S35-M36 -> 61706.488
B37: 45674 | C37: 은행수수료 | E37: 11 | F37: 해외지사비 | K37: 7.2 | L37: ='[2]통장내역(환율표)'!$D$246 -> 7.3191 | M37: =K37/L37 -> 0.98372751 | N37: =N36+H37-K37 -> 451602.19 | O37: =O36+J37-M37 -> 61705.506 | P37: 1월 송금 | S37: =S36-M37 -> 61705.505
B38: 45674 | C38: 사무실 WIFI+통신비 | E38: 12 | F38: 통신비 | G38: 기타 | K38: 417.84 | L38: ='[2]통장내역(환율표)'!$D$246 -> 7.3191 | M38: =K38/L38 -> 57.088986 | N38: =N37+H38-K38 -> 451184.35 | O38: =O37+J38-M38 -> 61648.417 | P38: 1월 송금 | R38: 신순연 | S38: =S37-M38 -> 61648.416
B39: 45674 | C39: 은행수수료 | E39: 13 | F39: 해외지사비 | K39: 3.6 | L39: ='[2]통장내역(환율표)'!$D$246 -> 7.3191 | M39: =K39/L39 -> 0.49186375 | N39: =N38+H39-K39 -> 451180.75 | O39: =O38+J39-M39 -> 61647.925 | P39: 1월 송금 | R39: 신순연 | S39: =S38-M39 -> 61647.924
B40: 45674 | C40: 출장비 | E40: 14 | F40: 여비교통비 | G40: 해외 | K40: 2579.69 | L40: ='[2]통장내역(환율표)'!$D$246 -> 7.3191 | M40: =K40/L40 -> 352.46 | N40: =N39+H40-K40 -> 448601.06 | O40: =O39+J40-M40 -> 61295.465 | P40: 1월 송금 | R40: Pan Shi Qiang | S40: =S39-M40 -> 61295.464
B41: 45674 | C41: 시내교통비 | E41: 15 | F41: 여비교통비 | G41: 해외 | K41: 178.26 | L41: ='[2]통장내역(환율표)'!$D$246 -> 7.3191 | M41: =K41/L41 -> 24.355454 | N41: =N40+H41-K41 -> 448422.8 | O41: =O40+J41-M41 -> 61271.109 | P41: 1월 송금 | R41: Pan Shi Qiang | S41: =S40-M41 -> 61271.108
...

Sheet 내역_25.02
B2: ▶ 25년 2월 전도금 정산 내역 (심천지사)_4000061 (B2F590) | H2: 보증금 입금 내역_1,234.5 (#1900000828 / #1200000234 / #100013313)
B3: 25년 1월 송금_1458.2(#) | F3: 1458.2 | H3: 25년 1월 2차 송금_1,434.30 (#) | L3: 1434.3 | N3: 25년 2월 송금_1447.40 (#) | R3: 1447.4 | X3: 1327.2
B4: 대계정 | C4: 소계정 | D4: 금액 (CNY) | E4: 금액 (USD) | F4: 금액 (KRW) | H4: 대계정 | I4: 소계정 | J4: 금액 (CNY) | K4: 금액 (USD) | L4: 금액 (KRW) | N4: 대계정 | O4: 소계정 | P4: 금액 (CNY) | Q4: 금액 (USD) | R4: 금액 (KRW)
A5: 51131050 | B5: 업무추진비 | C5: 일반 | D5: 13162.8 | E5: 1798.42 | F5: =ROUND(E5*$F$3,0) -> 2622456 | H5: 업무추진비 | I5: 일반 | J5: 3415.36 | K5: 472.51 | L5: =ROUND(K5*$L$3,0) -> 677721 | M5: =L5+F5 -> 3300177 | N5: 업무추진비 | O5: 일반 | R5: =ROUND(Q5*$R$3,0) -> 0 | S5: =F5+L5+R5 -> 3300177
A6: 51061030 | B6: 여비교통비 | C6: 해외 | D6: 7210.07 | E6: 985.1 | F6: =ROUND(E6*$F$3,0) -> 1436473 | H6: 여비교통비 | I6: 해외 | J6: 7124.78 | K6: 985.71 | L6: =ROUND(K6*$L$3,0) -> 1413804 | M6: =L6+F6 -> 2850277 | N6: 여비교통비 | O6: 해외 | R6: =ROUND(Q6*$R$3,0) -> 0 | S6: =F6+L6+R6 -> 2850277
A7: 51201020 | B7: 지급임차료 | C7: 사무실임차료 | D7: 24224 | E7: 3309.7 | F7: =ROUND(E7*$F$3,0) -> 4826205 | H7: 지급임차료 | I7: 사무실임차료 | L7: =ROUND(K7*$L$3,0) -> 0 | M7: =L7+F7 -> 4826205 | N7: 지급임차료 | O7: 사무실임차료 | R7: =ROUND(Q7*$R$3,0) -> 0 | S7: =F7+L7+R7 -> 4826205
A8: 51201030 | B8: 지급임차료 | C8: 차량임차료 | D8: 17500 | E8: 2391 | F8: =ROUND(E8*$F$3,0) -> 3486556 | H8: 지급임차료 | I8: 차량임차료 | L8: =ROUND(K8*$L$3,0) -> 0 | M8: =L8+F8 -> 3486556 | N8: 지급임차료 | O8: 차량임차료 | R8: =ROUND(Q8*$R$3,0) -> 0 | S8: =F8+L8+R8 -> 3486556
A9: 51071700 | B9: 통신비 | C9: 기타 | D9: 1155.8 | E9: 157.92 | F9: =ROUND(E9*$F$3,0) -> 230279 | H9: 통신비 | I9: 기타 | J9: 93.06 | K9: 12.87 | L9: =ROUND(K9*$L$3,0) -> 18459 | M9: =L9+F9 -> 248738 | N9: 통신비 | O9: 기타 | R9: =ROUND(Q9*$R$3,0) -> 0 | S9: =F9+L9+R9 -> 248738
A10: 51321010 | B10: 해외지사비 | D10: 14627.75 | E10: 1998.57 | F10: =ROUND(E10*$F$3,0) -> 2914315 | H10: 해외지사비 | J10: 45500.22 | K10: 6294.91 | L10: =ROUND(K10*$L$3,0) -> 9028789 | M10: =L10+F10 -> 11943104 | N10: 해외지사비 | P10: 167290.76 | Q10: 22984.82 | R10: =ROUND(Q10*$R$3,0) -> 33268228 | S10: =F10+L10+R10 -> 45211332
A11: 51031020 | B11: 급여(incentive) | C11: 성과급여조정 | F11: =ROUND(E11*$F$3,0) -> 0 | G11: =G13/G12 -> 1450.1752 | H11: 급여(incentive) | I11: 포상금 | L11: =ROUND(K11*$L$3,0) -> 0 | M11: =L11+F11 -> 0 | N11: 급여(incentive) | O11: 포상금 | P11: 56779 | Q11: 7783.81 | R11: =ROUND(Q11*$R$3,0) -> 11266287 | S11: =F11+L11+R11 -> 11266287
A12: 52981010 | B12: (-)잡이익(50) | C12: (-)잡이익 | F12: =ROUND(E12*$F$3,0) -> 0 | G12: =E13+Q13+AB13 -> 41409.34 | H12: (-)잡이익(50) | I12: (-)잡이익 | L12: =ROUND(K12*$L$3,0) -> 0 | M12: =L12+F12 -> 0 | N12: (-)잡이익(50) | O12: (-)잡이익 | R12: =ROUND(Q12*$R$3,0) -> 0 | S12: =F12+L12+R12 -> 0
B13: Total | D13: =SUM(D5:D11)-D12 -> 77880.42 | E13: =SUM(E5:E11)-E12 -> 10640.71 | F13: =SUM(F5:F11)-F12 -> 15516284 | G13: =F13+R13+AC13 -> 60050799 | H13: Total | J13: =SUM(J5:J11)-J12 -> 56133.42 | K13: =SUM(K5:K11)-K12 -> 7766 | L13: =SUM(L5:L11)-L12 -> 11138773 | M13: =L13+F13 -> 26655057 | N13: Total | P13: =SUM(P5:P11)-P12 -> 224069.76 | Q13: =SUM(Q5:Q11)-Q12 -> 30768.63 | R13: =SUM(R5:R11)-R12 -> 44534515 | S13: =F13+L13+R13 -> 71189572 | X13: =F13+R13 -> 60050799
D14: =SUM(D7:D10) -> 57507.55 | E14: =SUM(E7:E10) -> 7857.19 | F14: =SUM(F7:F10) -> 11457355 | J14: =J13+D13+P13 -> 358083.6 | K14: =K13+E13+Q13 -> 49175.34 | L14: =L13+F13+R13 -> 71189572 | M14: =M16-E12 -> #REF! | P14: =P13+D13+J13 -> 358083.6 | Q14: =Q13+E13+K13 -> 49175.34 | R14: =R13+F13+L13 -> 71189572
K15: =K16-H95 -> #REF! | M15: =M16-J95 -> #REF!
K16: =SUBTOTAL(9,K19:K97) -> #REF! | M16: =SUBTOTAL(9,M19:M97) -> #REF!
B17: 날짜 | C17: 내역 | D17: 담당자 | E17: 증빙번호 | F17: 대계정 | G17: 소계정 | H17: 입금 | K17: 출금 | N17: 잔액 | R17: 항목
B18: 날짜 | C18: 내역 | D18: 담당자 | E18: 증빙번호 | F18: 대계정 | G18: 소계정 | H18: CNY | I18: 환산요율 | J18: USD | K18: CNY | L18: 환산요율 | M18: USD | N18: CNY | O18: USD | P18: 비고 | R18: 항목
B19: 45688 | N19: 133987.27 | O19: 18406.711 | S19: 10640.71
B20: 45699 | C20: USD입금 and RMB 환전 | E20: 1 | H20: 324926.21 | J20: 44595 | N20: =N19+H20-K20 -> 458913.48 | O20: =O19+J20-M20 -> 63001.711 | S20: =S19-M20 -> 10640.71
C21: 은행수수료 | F21: 해외지사비 | M21: 51 | N21: =N20+H21-K21 -> 458913.48 | O21: =O20+J21-M21 -> 62950.711 | P21: 2월 송금
B22: 45702 | C22: 사무실 임대료/전기세 관련 | E22: 2 | F22: 지급임차료 | G22: 사무실임차료 | K22: 24224 | L22: =#REF! -> #REF! | M22: =K22/L22 -> #REF! | N22: =N21+H22-K22 -> 434689.48 | O22: =O21+J22-M22 -> #REF! | P22: 1월 송금 | S22: =S20-M22 -> #REF!
B23: 45702 | C23: 은행수수료 | E23: 3 | F23: 해외지사비 | K23: 7.2 | L23: =#REF! -> #REF! | M23: =K23/L23 -> #REF! | N23: =N22+H23-K23 -> 434682.28 | O23: =O22+J23-M23 -> #REF! | P23: 1월 송금 | S23: =S22-M23 -> #REF!
B24: 45702 | C24: 사무실 주차비 | E24: 4 | F24: 여비교통비 | G24: 해외 | K24: 1600 | L24: =#REF! -> #REF! | M24: =K24/L24 -> #REF! | N24: =N23+H24-K24 -> 433082.28 | O24: =O23+J24-M24 -> #REF! | P24: 1월 송금 | S24: =S23-M24 -> #REF!
B25: 45702 | C25: 은행수수료 | E25: 5 | F25: 해외지사비 | K25: 3.6 | L25: =#REF! -> #REF! | M25: =K25/L25 -> #REF! | N25: =N24+H25-K25 -> 433078.68 | O25: =O24+J25-M25 -> #REF! | P25: 1월 송금 | S25: =S24-M25 -> #REF!
B26: 45708 | C26: 세무대행비 | E26: 6 | F26: 해외지사비 | K26: 1010 | L26: =#REF! -> #REF! | M26: =K26/L26 -> #REF! | N26: =N25+H26-K26 -> 432068.68 | O26: =O25+J26-M26 -> #REF! | P26: 1월 송금 | S26: =S25-M26 -> #REF!
B27: 45708 | C27: 은행수수료 | E27: 7 | F27: 해외지사비 | K27: 3.6 | L27: =#REF! -> #REF! | M27: =K27/L27 -> #REF! | N27: =N26+H27-K27 -> 432065.08 | O27: =O26+J27-M27 -> #REF! | P27: 1월 송금 | S27: =S26-M27 -> #REF!
B28: 45708 | C28: 차량 Rent비 | E28: 8 | F28: 지급임차료 | G28: 차량임차료 | K28: 10500 | L28: =#REF! -> #REF! | M28: =K28/L28 -> #REF! | N28: =N27+H28-K28 -> 421565.08 | O28: =O27+J28-M28 -> #REF! | P28: 1월 송금 | S28: =S27-M28 -> #REF!
B29: 45708 | C29: 차량 기사비 | E29: 8 | F29: 해외지사비 | K29: 6000 | L29: =#REF! -> #REF! | M29: =K29/L29 -> #REF! | N29: =N28+H29-K29 -> 415565.08 | O29: =O28+J29-M29 -> #REF! | P29: 1월 송금 | S29: =S28-M29 -> #REF!
B30: 45708 | C30: 기사 야근비용 | E30: 8 | F30: 해외지사비 | K30: 680 | L30: =#REF! -> #REF! | M30: =K30/L30 -> #REF! | N30: =N29+H30-K30 -> 414885.08 | O30: =O29+J30-M30 -> #REF! | P30: 1월 송금 | S30: =S29-M30 -> #REF!
B31: 45708 | C31: 차량 Rent비 | E31: 8 | F31: 지급임차료 | G31: 차량임차료 | K31: 7000 | L31: =#REF! -> #REF! | M31: =K31/L31 -> #REF! | N31: =N30+H31-K31 -> 407885.08 | O31: =O30+J31-M31 -> #REF! | P31: 1월 송금 | S31: =S30-M31 -> #REF!
B32: 45708 | C32: 차량 기사비 | E32: 8 | F32: 해외지사비 | K32: 6000 | L32: =#REF! -> #REF! | M32: =K32/L32 -> #REF! | N32: =N31+H32-K32 -> 401885.08 | O32: =O31+J32-M32 -> #REF! | P32: 1월 송금 | S32: =S31-M32 -> #REF!
B33: 45708 | C33: 기사 야근비용 | E33: 8 | F33: 해외지사비 | K33: 230 | L33: =#REF! -> #REF! | M33: =K33/L33 -> #REF! | N33: =N32+H33-K33 -> 401655.08 | O33: =O32+J33-M33 -> #REF! | P33: 1월 송금 | S33: =S32-M33 -> #REF!
B34: 45708 | C34: 은행수수료 | E34: 9 | F34: 해외지사비 | K34: 7.2 | L34: =#REF! -> #REF! | M34: =K34/L34 -> #REF! | N34: =N33+H34-K34 -> 401647.88 | O34: =O33+J34-M34 -> #REF! | P34: 1월 송금 | S34: =S33-M34 -> #REF!
B35: 45708 | C35: 신순연_사무실 wfi, 통신비 | E35: 10 | F35: 통신비 | G35: 기타 | K35: 397.8 | L35: =#REF! -> #REF! | M35: =K35/L35 -> #REF! | N35: =N34+H35-K35 -> 401250.08 | O35: =O34+J35-M35 -> #REF! | P35: 1월 송금 | S35: =S34-M35 -> #REF!
B36: 45708 | C36: 은행수수료 | E36: 11 | F36: 해외지사비 | K36: 3.6 | L36: =#REF! -> #REF! | M36: =K36/L36 -> #REF! | N36: =N35+H36-K36 -> 401246.48 | O36: =O35+J36-M36 -> #REF! | P36: 1월 송금 | S36: =S35-M36 -> #REF!
B37: 45708 | C37: Pan Shi Qiang_출장비 | E37: 12 | F37: 여비교통비 | G37: 해외 | K37: 1231.33 | L37: =#REF! -> #REF! | M37: =K37/L37 -> #REF! | N37: =N36+H37-K37 -> 400015.15 | O37: =O36+J37-M37 -> #REF! | P37: 1월 송금 | S37: =S36-M37 -> #REF!
B38: 45708 | C38: Pan Shi Qiang_통신비 | E38: 13 | F38: 통신비 | G38: 기타 | K38: 108.9 | L38: =#REF! -> #REF! | M38: =K38/L38 -> #REF! | N38: =N37+H38-K38 -> 399906.25 | O38: =O37+J38-M38 -> #REF! | P38: 1월 송금 | S38: =S37-M38 -> #REF!
B39: 45708 | C39: 은행수수료 | E39: 14 | F39: 해외지사비 | K39: 3.6 | L39: =#REF! -> #REF! | M39: =K39/L39 -> #REF! | N39: =N38+H39-K39 -> 399902.65 | O39: =O38+J39-M39 -> #REF! | P39: 1월 송금 | S39: =S38-M39 -> #REF!
B40: 45708 | C40: Zhang Liang_시내교통비 | E40: 15 | F40: 여비교통비 | G40: 해외 | K40: 503.6 | L40: =#REF! -> #REF! | M40: =K40/L40 -> #REF! | N40: =N39+H40-K40 -> 399399.05 | O40: =O39+J40-M40 -> #REF! | P40: 1월 송금 | S40: =S39-M40 -> #REF!
B41: 45708 | C41: Zhang Liang_출장비 | E41: 16 | F41: 여비교통비 | G41: 해외 | K41: 617.75 | L41: =#REF! -> #REF! | M41: =K41/L41 -> #REF! | N41: =N40+H41-K41 -> 398781.3 | O41: =O40+J41-M41 -> #REF! | P41: 1월 송금 | S41: =S40-M41 -> #REF!
...

Sheet 내역_25.03
B2: ▶ 25년 3월 전도금 정산 내역 (심천지사)_4000061 (B2F590) | H2: 보증금 입금 내역_1,234.5 (#1900000828 / #1200000234 / #100013313)
B3: 25년 2월 송금_1447.40 (#) | F3: 1447.4 | H3: 25년 3월 송금_1,446.30 (#) | L3: 1446.3 | X3: 1327.2
B4: 대계정 | C4: 소계정 | D4: 금액 (CNY) | E4: 금액 (USD) | F4: 금액 (KRW) | H4: 대계정 | I4: 소계정 | J4: 금액 (CNY) | K4: 금액 (USD) | L4: 금액 (KRW)
A5: 51131050 | B5: 업무추진비 | C5: 일반 | D5: 14845.68 | E5: 2035.1825 | F5: =ROUND(E5*$F$3,0) -> 2945723 | H5: 업무추진비 | I5: 일반 | L5: =ROUND(K5*$L$3,0) -> 0 | M5: =L5+F5 -> 2945723 | S5: =F5+L5+R5 -> 2945723
A6: 51061030 | B6: 여비교통비 | C6: 해외 | D6: 18459.27 | E6: 2530.5737 | F6: =ROUND(E6*$F$3,0) -> 3662752 | H6: 여비교통비 | I6: 해외 | J6: 18692.93 | K6: 2589.84 | L6: =ROUND(K6*$L$3,0) -> 3745686 | M6: =L6+F6 -> 7408438 | S6: =F6+L6+R6 -> 7408438
A7: 51201020 | B7: 지급임차료 | C7: 사무실임차료 | D7: 25272 | E7: 3464.53 | F7: =ROUND(E7*$F$3,0) -> 5014561 | H7: 지급임차료 | I7: 사무실임차료 | L7: =ROUND(K7*$L$3,0) -> 0 | M7: =L7+F7 -> 5014561 | S7: =F7+L7+R7 -> 5014561
A8: 51201030 | B8: 지급임차료 | C8: 차량임차료 | D8: 17500 | E8: 2399.07 | F8: =ROUND(E8*$F$3,0) -> 3472414 | H8: 지급임차료 | I8: 차량임차료 | L8: =ROUND(K8*$L$3,0) -> 0 | M8: =L8+F8 -> 3472414 | S8: =F8+L8+R8 -> 3472414
A9: 51071700 | B9: 통신비 | C9: 기타 | D9: 1453.59 | E9: 199.27205 | F9: =ROUND(E9*$F$3,0) -> 288426 | H9: 통신비 | I9: 기타 | J9: 169 | K9: 23.41 | L9: =ROUND(K9*$L$3,0) -> 33858 | M9: =L9+F9 -> 322284 | S9: =F9+L9+R9 -> 322284
A10: 51321010 | B10: 해외지사비 | D10: 23429.319 | E10: 3211.9156 | F10: =ROUND(E10*$F$3,0) -> 4648927 | H10: 해외지사비 | J10: 274853 | K10: 38130.88 | L10: =ROUND(K10*$L$3,0) -> 55148692 | M10: =L10+F10 -> 59797619 | S10: =F10+L10+R10 -> 59797619
A11: 51031020 | B11: 급여(incentive) | C11: 성과급여조정 | G11: =G13/G12 -> 1447.4 | H11: 급여(incentive) | I11: 포상금 | L11: =ROUND(K11*$L$3,0) -> 0 | M11: =L11+F11 -> 0 | S11: =F11+L11+R11 -> 0
A12: 52981010 | B12: (-)잡이익(50) | C12: (-)잡이익 | D12: 103.37 | E12: 14.17 | F12: =ROUND(E12*$F$3,0) -> 20510 | G12: =E13+Q13+AB13 -> 13826.374 | H12: (-)잡이익(50) | I12: (-)잡이익 | L12: =ROUND(K12*$L$3,0) -> 0 | M12: =L12+F12 -> 20510 | S12: =F12+L12+R12 -> 20510
B13: Total | D13: =SUM(D5:D11)-D12 -> 100856.49 | E13: =SUM(E5:E11)-E12 -> 13826.374 | F13: =SUM(F5:F11)-F12 -> 20012293 | G13: =F13+R13+AC13 -> 20012293 | H13: Total | J13: =SUM(J5:J11)-J12 -> 293714.93 | K13: =SUM(K5:K11)-K12 -> 40744.13 | L13: =SUM(L5:L11)-L12 -> 58928236 | M13: =L13+F13 -> 78940529 | S13: =F13+L13+R13 -> 78940529 | X13: =F13+R13 -> 20012293
J14: =J13+D13+P13 -> 394571.42 | K14: =K13+E13+Q13 -> 54570.504 | L14: =L13+F13+R13 -> 78940529 | M14: =M16-E12 -> #REF!
J15: =J16-G96 -> 0 | K15: =K16-H96 -> #REF! | L15: =L16-I96 -> 0 | M15: =M16-J96 -> #REF!
K16: =SUBTOTAL(9,K19:K105) -> #REF! | M16: =SUBTOTAL(9,M19:M105) -> #REF!
B17: 날짜 | C17: 내역 | D17: 담당자 | E17: 증빙번호 | F17: 대계정 | G17: 소계정 | H17: 입금 | K17: 출금 | N17: 잔액 | R17: 항목
B18: 날짜 | C18: 내역 | D18: 담당자 | E18: 증빙번호 | F18: 대계정 | G18: 소계정 | H18: CNY | I18: 환산요율 | J18: USD | K18: CNY | L18: 환산요율 | M18: USD | N18: CNY | O18: USD | P18: 비고 | R18: 항목
B19: 45716 | N19: 100829.88 | O19: 13826.37 | S19: 13826.369
B20: 45727 | C20: USD입금 and RMB 환전 | E20: 1 | H20: 346107.95 | J20: 48003 | N20: =N19+H20-K20 -> 446937.83 | O20: =O19+J20-M20 -> 61829.37 | P20: 2월 송금
B21: 45727 | C21: 은행수수료 | F21: 해외지사비 | M21: 51 | N21: =N20+H21-K21 -> 446937.83 | O21: =O20+J21-M21 -> 61778.37 | P21: 2월 송금
B22: 45733 | C22: 사무실 임대료/전기세 관련 | E22: 2 | F22: 지급임차료 | G22: 사무실 | K22: 25272 | L22: =#REF! -> #REF! | M22: =K22/L22 -> #REF! | N22: =N21+H22-K22 -> 421665.83 | O22: =O21+J22-M22 -> #REF! | P22: 2월 송금 | S22: =S19-M22+J22 -> #REF!
B23: 45733 | C23: 은행수수료 | E23: 3 | F23: 해외지사비 | K23: 7.2 | L23: =#REF! -> #REF! | M23: =K23/L23 -> #REF! | N23: =N22+H23-K23 -> 421658.63 | O23: =O22+J23-M23 -> #REF! | P23: 2월 송금 | S23: =S22-M23+J23 -> #REF!
B24: 45733 | C24: 사무실 주차비 | E24: 4 | F24: 여비교통비 | G24: 해외 | K24: 1600 | L24: =#REF! -> #REF! | M24: =K24/L24 -> #REF! | N24: =N23+H24-K24 -> 420058.63 | O24: =O23+J24-M24 -> #REF! | P24: 2월 송금 | S24: =S23-M24+J24 -> #REF!
B25: 45733 | C25: 은행수수료 | E25: 5 | F25: 해외지사비 | K25: 3.6 | L25: =#REF! -> #REF! | M25: =K25/L25 -> #REF! | N25: =N24+H25-K25 -> 420055.03 | O25: =O24+J25-M25 -> #REF! | P25: 2월 송금 | S25: =S24-M25+J25 -> #REF!
B26: 45737 | C26: 이자 | E26: 6 | F26: 잡이익 | H26: 103.37 | I26: =#REF! -> #REF! | J26: 14.17 | L26: =#REF! -> #REF! | M26: =K26/L26 -> #REF! | N26: =N25+H26-K26 -> 420158.4 | O26: =O25+J26-M26 -> #REF! | P26: 2월 송금 | S26: =S25-M26+J26 -> #REF!
B27: 45737 | C27: 세무대행비 | E27: 7 | F27: 해외지사비 | K27: 1010 | L27: =#REF! -> #REF! | M27: =K27/L27 -> #REF! | N27: =N26+H27-K27 -> 419148.4 | O27: =O26+J27-M27 -> #REF! | P27: 2월 송금 | S27: =S26-M27+J27 -> #REF!
B28: 45737 | C28: 은행수수료 | E28: 8 | F28: 해외지사비 | K28: 3.6 | L28: =#REF! -> #REF! | M28: =K28/L28 -> #REF! | N28: =N27+H28-K28 -> 419144.8 | O28: =O27+J28-M28 -> #REF! | P28: 2월 송금 | S28: =S27-M28+J28 -> #REF!
B29: 45737 | C29: 차량 Rent비 | E29: 9 | F29: 지급임차료 | G29: 차량임차료 | K29: 10500 | L29: =#REF! -> #REF! | M29: =K29/L29 -> #REF! | N29: =N28+H29-K29 -> 408644.8 | O29: =O28+J29-M29 -> #REF! | P29: 2월 송금 | S29: =S28-M29+J29 -> #REF!
B30: 45737 | C30: 차량 기사비 | E30: 9 | F30: 해외지사비 | K30: 6000 | L30: =#REF! -> #REF! | M30: =K30/L30 -> #REF! | N30: =N29+H30-K30 -> 402644.8 | O30: =O29+J30-M30 -> #REF! | P30: 2월 송금 | S30: =S29-M30+J30 -> #REF!
B31: 45737 | C31: 기사 야근비용 | E31: 9 | F31: 해외지사비 | K31: 760 | L31: =#REF! -> #REF! | M31: =K31/L31 -> #REF! | N31: =N30+H31-K31 -> 401884.8 | O31: =O30+J31-M31 -> #REF! | P31: 2월 송금 | S31: =S30-M31+J31 -> #REF!
B32: 45737 | C32: 차량 Rent비 | E32: 9 | F32: 지급임차료 | G32: 차량임차료 | K32: 7000 | L32: =#REF! -> #REF! | M32: =K32/L32 -> #REF! | N32: =N31+H32-K32 -> 394884.8 | O32: =O31+J32-M32 -> #REF! | P32: 2월 송금 | S32: =S31-M32+J32 -> #REF!
B33: 45737 | C33: 차량 기사비 | E33: 9 | F33: 해외지사비 | K33: 6000 | L33: =#REF! -> #REF! | M33: =K33/L33 -> #REF! | N33: =N32+H33-K33 -> 388884.8 | O33: =O32+J33-M33 -> #REF! | P33: 2월 송금 | S33: =S32-M33+J33 -> #REF!
B34: 45737 | C34: 기사 야근비용 | E34: 9 | F34: 해외지사비 | K34: 900 | L34: =#REF! -> #REF! | M34: =K34/L34 -> #REF! | N34: =N33+H34-K34 -> 387984.8 | O34: =O33+J34-M34 -> #REF! | P34: 2월 송금 | S34: =S33-M34+J34 -> #REF!
B35: 45737 | C35: 은행수수료 | E35: 10 | F35: 해외지사비 | K35: 7.2 | L35: =#REF! -> #REF! | M35: =K35/L35 -> #REF! | N35: =N34+H35-K35 -> 387977.6 | O35: =O34+J35-M35 -> #REF! | P35: 2월 송금 | S35: =S34-M35+J35 -> #REF!
B36: 45737 | C36: 신순연_사무실 wfi, 통신비 | E36: 11 | F36: 통신비 | G36: 기타 | K36: 419 | L36: =#REF! -> #REF! | M36: 57.44 | N36: =N35+H36-K36 -> 387558.6 | O36: =O35+J36-M36 -> #REF! | P36: 2월 송금 | R36: 신순연 | S36: =S35-M36+J36 -> #REF!
B37: 45737 | C37: 은행수수료 | E37: 12 | F37: 해외지사비 | K37: 3.6 | L37: =#REF! -> #REF! | M37: =K37/L37 -> #REF! | N37: =N36+H37-K37 -> 387555 | O37: =O36+J37-M37 -> #REF! | P37: 2월 송금 | R37: 신순연 | S37: =S36-M37+J37 -> #REF!
B38: 45737 | C38: 시내교통비 | E38: 13 | F38: 여비교통비 | G38: 해외 | K38: 428.18 | L38: =#REF! -> #REF! | M38: =K38/L38 -> #REF! | N38: =N37+H38-K38 -> 387126.82 | O38: =O37+J38-M38 -> #REF! | P38: 2월 송금 | R38: Pan Shi Qiang | S38: =S37-M38+J38 -> #REF!
B39: 45737 | C39: 출장비 | E39: 14 | F39: 여비교통비 | G39: 해외 | K39: 2164.32 | L39: =#REF! -> #REF! | M39: =K39/L39 -> #REF! | N39: =N38+H39-K39 -> 384962.5 | O39: =O38+J39-M39 -> #REF! | P39: 2월 송금 | R39: Pan Shi Qiang | S39: =S38-M39+J39 -> #REF!
B40: 45737 | C40: 택배비 | E40: 15 | F40: 해외지사비 | K40: 142.4 | L40: =#REF! -> #REF! | M40: =K40/L40 -> #REF! | N40: =N39+H40-K40 -> 384820.1 | O40: =O39+J40-M40 -> #REF! | P40: 2월 송금 | R40: Pan Shi Qiang | S40: =S39-M40+J40 -> #REF!
B41: 45737 | C41: 통신비 | E41: 16 | F41: 통신비 | G41: 기타 | K41: 118.8 | L41: =#REF! -> #REF! | M41: =K41/L41 -> #REF! | N41: =N40+H41-K41 -> 384701.3 | O41: =O40+J41-M41 -> #REF! | P41: 2월 송금 | R41: Pan Shi Qiang | S41: =S40-M41+J41 -> #REF!
...

Sheet 내역_25.04
B2: ▶ 25년 4월 전도금 정산 내역 (심천지사)_4000061 (B2F590) | H2: 보증금 입금 내역_1,234.5 (#1900000828 / #1200000234 / #100013313)
B3: 25년 3월 송금_1,446.30 (#) | F3: 1446.3 | H3: 25년 4월 송금_1,482.90 (#) | L3: 1482.9 | X3: 1327.2
B4: 대계정 | C4: 소계정 | D4: 금액 (CNY) | E4: 금액 (USD) | F4: 금액 (KRW) | H4: 대계정 | I4: 소계정 | J4: 금액 (CNY) | K4: 금액 (USD) | L4: 금액 (KRW)
A5: 51131050 | B5: 업무추진비 | C5: 일반 | F5: =ROUND(E5*$F$3,0) -> 0 | H5: 업무추진비 | I5: 일반 | J5: 19195.4 | K5: 2619.03 | L5: =ROUND(K5*$L$3,0) -> 3883760 | M5: =L5+F5 -> 3883760 | S5: =F5+L5+R5 -> 3883760
A6: 51061030 | B6: 여비교통비 | C6: 해외 | F6: =ROUND(E6*$F$3,0) -> 0 | H6: 여비교통비 | I6: 해외 | J6: 30648.81 | K6: 4181.74 | L6: =ROUND(K6*$L$3,0) -> 6201102 | M6: =L6+F6 -> 6201102 | S6: =F6+L6+R6 -> 6201102
A7: 51201020 | B7: 지급임차료 | C7: 사무실임차료 | D7: 142.17 | E7: 19.7 | F7: =ROUND(E7*$F$3,0) -> 28492 | H7: 지급임차료 | I7: 사무실임차료 | J7: 24914.83 | K7: 3399.39 | L7: =ROUND(K7*$L$3,0) -> 5040955 | M7: =L7+F7 -> 5069447 | S7: =F7+L7+R7 -> 5069447
A8: 51201030 | B8: 지급임차료 | C8: 차량임차료 | F8: =ROUND(E8*$F$3,0) -> 0 | H8: 지급임차료 | I8: 차량임차료 | J8: 17500 | K8: 2387.71 | L8: =ROUND(K8*$L$3,0) -> 3540735 | M8: =L8+F8 -> 3540735 | S8: =F8+L8+R8 -> 3540735
A9: 51071700 | B9: 통신비 | C9: 기타 | F9: =ROUND(E9*$F$3,0) -> 0 | H9: 통신비 | I9: 기타 | J9: 1469.1 | K9: 200.44 | L9: =ROUND(K9*$L$3,0) -> 297232 | M9: =L9+F9 -> 297232 | S9: =F9+L9+R9 -> 297232
A10: 51321010 | B10: 해외지사비 | D10: 52250.88 | E10: 7239.17 | F10: =ROUND(E10*$F$3,0) -> 10470012 | H10: 해외지사비 | J10: 265516.81 | K10: 36252.26 | L10: =ROUND(K10*$L$3,0) -> 53758476 | M10: =L10+F10 -> 64228488 | S10: =F10+L10+R10 -> 64228488
A11: 51031020 | B11: 급여(incentive) | C11: 성과급여조정 | G11: =G13/G12 -> 1446.3 | H11: 급여(incentive) | I11: 포상금 | L11: =ROUND(K11*$L$3,0) -> 0 | M11: =L11+F11 -> 0 | S11: =F11+L11+R11 -> 0
A12: 52981010 | B12: (-)잡이익(50) | C12: (-)잡이익 | F12: =ROUND(E12*$F$3,0) -> 0 | G12: =E13+Q13+AB13 -> 7258.87 | H12: (-)잡이익(50) | I12: (-)잡이익 | L12: =ROUND(K12*$L$3,0) -> 0 | M12: =L12+F12 -> 0 | S12: =F12+L12+R12 -> 0
B13: Total | D13: =SUM(D5:D11)-D12 -> 52393.05 | E13: =SUM(E5:E11)-E12 -> 7258.87 | F13: =SUM(F5:F11)-F12 -> 10498504 | G13: =F13+R13+AC13 -> 10498504 | H13: Total | J13: =SUM(J5:J11)-J12 -> 359244.95 | K13: =SUM(K5:K11)-K12 -> 49040.57 | L13: =SUM(L5:L11)-L12 -> 72722260 | M13: =L13+F13 -> 83220764 | S13: =F13+L13+R13 -> 83220764 | X13: =F13+R13 -> 10498504
J14: =J13+D13+P13 -> 411638 | K14: =K13+E13+Q13 -> 56299.44 | L14: =L13+F13+R13 -> 83220764 | M14: =M16-E12 -> #REF!
J15: =J16-#REF! -> #REF! | K15: =K16-#REF! -> #REF! | L15: =L16-#REF! -> #REF! | M15: =M16-#REF! -> #REF!
K16: =SUBTOTAL(9,K19:K105) -> 123285 | M16: =SUBTOTAL(9,M19:M105) -> #REF!
B17: 날짜 | C17: 내역 | D17: 담당자 | E17: 증빙번호 | F17: 대계정 | G17: 소계정 | H17: 입금 | K17: 출금 | N17: 잔액 | R17: 항목
B18: 날짜 | C18: 내역 | D18: 담당자 | E18: 증빙번호 | F18: 대계정 | G18: 소계정 | H18: CNY | I18: 환산요율 | J18: USD | K18: CNY | L18: 환산요율 | M18: USD | N18: CNY | O18: USD | P18: 비고 | R18: 항목
B19: 45747 | N19: 52366.41 | O19: 7258.868 | S19: 7258.8664
B20: 45757 | C20: 1분기 기업 소득세 | E20: 1 | F20: 해외지사비 | K20: 52250.88 | L20: =#REF! -> #REF! | M20: =K20/L20 -> #REF! | N20: =N19+H20-K20 -> 115.53 | O20: =O19+J20-M20 -> #REF! | P20: 3월 송금 | S20: =S19-M20+J20 -> #REF!
B21: 45757 | C21: USD입금 and RMB 환전 | E21: 2 | H21: 404322.65 | J21: 55191 | N21: =N20+H21-K21 -> 404438.18 | O21: =O20+J21-M21 -> #REF!
B22: 45757 | C22: 은행수수료 | F22: 해외지사비 | M22: 25 | N22: =N21+H22-K22 -> 404438.18 | O22: =O21+J22-M22 -> #REF! | P22: 4월 송금
B23: 45762 | C23: 사무실 임대료/전기세 관련 | E23: 3 | F23: 지급임차료 | G23: 사무실임차료 | K23: =L23*M23 -> #REF! | L23: =#REF! -> #REF! | M23: 19.696706 | N23: =N22+H23-K23 -> #REF! | O23: =O22+J23-M23 -> #REF! | P23: 3월 송금
B24: 45762 | C24: 사무실 임대료/전기세 관련 | E24: 3 | F24: 지급임차료 | G24: 사무실임차료 | K24: =25057-K23 -> #REF! | L24: =#REF! -> #REF! | M24: =K24/L24 -> #REF! | N24: =N23+H24-K24 -> #REF! | O24: =O23+J24-M24 -> #REF! | P24: 4월 송금 | S24: =55166-M24 -> #REF!
B25: 45762 | C25: 은행수수료 | E25: 4 | F25: 해외지사비 | K25: 7.2 | L25: =#REF! -> #REF! | M25: =K25/L25 -> #REF! | N25: =N24+H25-K25 -> #REF! | O25: =O24+J25-M25 -> #REF! | P25: 4월 송금 | S25: =S24-M25+J25 -> #REF!
B26: 45762 | C26: 사무실 주차비 | E26: 5 | F26: 여비교통비 | G26: 해외 | K26: 1600 | L26: =#REF! -> #REF! | M26: =K26/L26 -> #REF! | N26: =N25+H26-K26 -> #REF! | O26: =O25+J26-M26 -> #REF! | P26: 4월 송금 | S26: =S25-M26+J26 -> #REF!
B27: 45762 | C27: 은행수수료 | E27: 6 | F27: 해외지사비 | K27: 3.6 | L27: =#REF! -> #REF! | M27: =K27/L27 -> #REF! | N27: =N26+H27-K27 -> #REF! | O27: =O26+J27-M27 -> #REF! | P27: 4월 송금 | S27: =S26-M27+J27 -> #REF!
B28: 45768 | C28: 세무대행비 | E28: 7 | F28: 해외지사비 | K28: 1010 | L28: =#REF! -> #REF! | M28: =K28/L28 -> #REF! | N28: =N27+H28-K28 -> #REF! | O28: =O27+J28-M28 -> #REF! | P28: 4월 송금 | S28: =S27-M28+J28 -> #REF!
B29: 45768 | C29: 은행수수료 | E29: 8 | F29: 해외지사비 | K29: 3.6 | L29: =#REF! -> #REF! | M29: =K29/L29 -> #REF! | N29: =N28+H29-K29 -> #REF! | O29: =O28+J29-M29 -> #REF! | P29: 4월 송금 | S29: =S28-M29+J29 -> #REF!
B30: 45768 | C30: 차량 Rent비 | E30: 9 | F30: 지급임차료 | G30: 차량임차료 | K30: 10500 | L30: =#REF! -> #REF! | M30: =K30/L30 -> #REF! | N30: =N29+H30-K30 -> #REF! | O30: =O29+J30-M30 -> #REF! | P30: 4월 송금 | S30: =S29-M30+J30 -> #REF!
B31: 45768 | C31: 차량 기사비 | E31: 9 | F31: 해외지사비 | K31: 6000 | L31: =#REF! -> #REF! | M31: =K31/L31 -> #REF! | N31: =N30+H31-K31 -> #REF! | O31: =O30+J31-M31 -> #REF! | P31: 4월 송금 | S31: =S30-M31+J31 -> #REF!
B32: 45768 | C32: 기사 야근비용 | E32: 9 | F32: 해외지사비 | K32: 470 | L32: =#REF! -> #REF! | M32: =K32/L32 -> #REF! | N32: =N31+H32-K32 -> #REF! | O32: =O31+J32-M32 -> #REF! | P32: 4월 송금 | S32: =S31-M32+J32 -> #REF!
B33: 45768 | C33: 차량 Rent비 | E33: 9 | F33: 지급임차료 | G33: 차량임차료 | K33: 7000 | L33: =#REF! -> #REF! | M33: =K33/L33 -> #REF! | N33: =N32+H33-K33 -> #REF! | O33: =O32+J33-M33 -> #REF! | P33: 4월 송금 | S33: =S32-M33+J33 -> #REF!
B34: 45768 | C34: 차량 기사비 | E34: 9 | F34: 해외지사비 | K34: 6000 | L34: =#REF! -> #REF! | M34: =K34/L34 -> #REF! | N34: =N33+H34-K34 -> #REF! | O34: =O33+J34-M34 -> #REF! | P34: 4월 송금 | S34: =S33-M34+J34 -> #REF!
B35: 45768 | C35: 기사 야근비용 | E35: 9 | F35: 해외지사비 | K35: 400 | L35: =#REF! -> #REF! | M35: =K35/L35 -> #REF! | N35: =N34+H35-K35 -> #REF! | O35: =O34+J35-M35 -> #REF! | P35: 4월 송금 | S35: =S34-M35+J35 -> #REF!
B36: 45768 | C36: 은행수수료 | E36: 10 | F36: 해외지사비 | K36: 7.2 | L36: =#REF! -> #REF! | M36: =K36/L36 -> #REF! | N36: =N35+H36-K36 -> #REF! | O36: =O35+J36-M36 -> #REF! | P36: 4월 송금 | S36: =S35-M36+J36 -> #REF!
B37: 45768 | C37: 신순연_사무실 wfi, 통신비 | E37: 11 | F37: 통신비 | G37: 기타 | K37: 418 | L37: =#REF! -> #REF! | M37: =K37/L37 -> #REF! | N37: =N36+H37-K37 -> #REF! | O37: =O36+J37-M37 -> #REF! | P37: 4월 송금 | R37: 신순연 | S37: =S36-M37+J37 -> #REF!
B38: 45768 | C38: 은행수수료 | E38: 12 | F38: 해외지사비 | K38: 3.6 | L38: =#REF! -> #REF! | M38: =K38/L38 -> #REF! | N38: =N37+H38-K38 -> #REF! | O38: =O37+J38-M38 -> #REF! | P38: 4월 송금 | R38: 신순연 | S38: =S37-M38+J38 -> #REF!
B39: 45768 | C39: Pan Shi Qiang_시내교통비 | E39: 13 | F39: 여비교통비 | G39: 해외 | K39: 128.41 | L39: =#REF! -> #REF! | M39: =K39/L39 -> #REF! | N39: =N38+H39-K39 -> #REF! | O39: =O38+J39-M39 -> #REF! | P39: 4월 송금 | R39: Pan Shi Qiang | S39: =S38-M39+J39 -> #REF!
B40: 45768 | C40: Pan Shi Qiang_출장비 | E40: 14 | F40: 여비교통비 | G40: 해외 | K40: 4365.36 | L40: =#REF! -> #REF! | M40: =K40/L40 -> #REF! | N40: =N39+H40-K40 -> #REF! | O40: =O39+J40-M40 -> #REF! | P40: 4월 송금 | R40: Pan Shi Qiang | S40: =S39-M40+J40 -> #REF!
B41: 45768 | C41: Pan Shi Qiang_통신비 | E41: 15 | F41: 통신비 | G41: 기타 | K41: 153.6 | L41: =#REF! -> #REF! | M41: =K41/L41 -> #REF! | N41: =N40+H41-K41 -> #REF! | O41: =O40+J41-M41 -> #REF! | P41: 4월 송금 | R41: Pan Shi Qiang | S41: =S40-M41+J41 -> #REF!
...

Sheet 내역_25.05
B2: ▶ 25년 5월 전도금 정산 내역 (심천지사)_4000061 (B2F590) | H2: 보증금 입금 내역_1,234.5 (#1900000828 / #1200000234 / #100013313)
B3: 25년 4월 송금_1,482.90 (#) | F3: 1482.9 | H3: 25년 5월 송금_1405.60 (#) | L3: 1405.6 | X3: 1327.2
B4: 대계정 | C4: 소계정 | D4: 금액 (CNY) | E4: 금액 (USD) | F4: 금액 (KRW) | H4: 대계정 | I4: 소계정 | J4: 금액 (CNY) | K4: 금액 (USD) | L4: 금액 (KRW)
A5: 51131050 | B5: 업무추진비 | C5: 일반 | D5: 3161.4 | E5: 431.34 | F5: =ROUND(E5*$F$3,0) -> 639634 | H5: 업무추진비 | I5: 일반 | J5: 14265.08 | K5: 1986.7 | L5: =ROUND(K5*$L$3,0) -> 2792506 | M5: =L5+F5 -> 3432140 | S5: =F5+L5+R5 -> 3432140
A6: 51061030 | B6: 여비교통비 | C6: 해외 | D6: 11847.427 | E6: 1616.47 | F6: =ROUND(E6*$F$3,0) -> 2397063 | H6: 여비교통비 | I6: 해외 | J6: 19528.07 | K6: 2719.68 | L6: =ROUND(K6*$L$3,0) -> 3822782 | M6: =L6+F6 -> 6219845 | S6: =F6+L6+R6 -> 6219845
A7: 51201020 | B7: 지급임차료 | C7: 사무실임차료 | D7: 25096 | E7: 3424.11 | F7: =ROUND(E7*$F$3,0) -> 5077613 | H7: 지급임차료 | I7: 사무실임차료 | L7: =ROUND(K7*$L$3,0) -> 0 | M7: =L7+F7 -> 5077613 | S7: =F7+L7+R7 -> 5077613
A8: 51201030 | B8: 지급임차료 | C8: 차량임차료 | F8: =ROUND(E8*$F$3,0) -> 0 | H8: 지급임차료 | I8: 차량임차료 | J8: 20596 | K8: 2868.4 | L8: =ROUND(K8*$L$3,0) -> 4031823 | M8: =L8+F8 -> 4031823 | S8: =F8+L8+R8 -> 4031823
A9: 51071700 | B9: 통신비 | C9: 기타 | D9: 2034.12 | E9: 277.54 | F9: =ROUND(E9*$F$3,0) -> 411564 | H9: 통신비 | I9: 기타 | J9: 300 | K9: 41.78 | L9: =ROUND(K9*$L$3,0) -> 58726 | M9: =L9+F9 -> 470290 | S9: =F9+L9+R9 -> 470290
A10: 51321010 | B10: 해외지사비 | D10: 2938.75 | E10: 400.97 | F10: =ROUND(E10*$F$3,0) -> 594598 | H10: 해외지사비 | J10: 247302.52 | K10: 34492.81 | L10: =ROUND(K10*$L$3,0) -> 48483094 | M10: =L10+F10 -> 49077692 | S10: =F10+L10+R10 -> 49077692
A11: 51031020 | B11: 급여(incentive) | C11: 성과급여조정 | G11: =G13/G12 -> 1482.8999 | H11: 급여(incentive) | I11: 포상금 | L11: =ROUND(K11*$L$3,0) -> 0 | M11: =L11+F11 -> 0 | S11: =F11+L11+R11 -> 0
A12: 52981010 | B12: (-)잡이익(50) | C12: (-)잡이익 | F12: =ROUND(E12*$F$3,0) -> 0 | G12: =E13+Q13+AB13 -> 6150.43 | H12: (-)잡이익(50) | I12: (-)잡이익 | L12: =ROUND(K12*$L$3,0) -> 0 | M12: =L12+F12 -> 0 | S12: =F12+L12+R12 -> 0
B13: Total | D13: =SUM(D5:D11)-D12 -> 45077.697 | E13: =SUM(E5:E11)-E12 -> 6150.43 | F13: =SUM(F5:F11)-F12 -> 9120472 | G13: =F13+R13+AC13 -> 9120472 | H13: Total | J13: =SUM(J5:J11)-J12 -> 301991.67 | K13: =SUM(K5:K11)-K12 -> 42109.37 | L13: =SUM(L5:L11)-L12 -> 59188931 | M13: =L13+F13 -> 68309403 | S13: =F13+L13+R13 -> 68309403 | X13: =F13+R13 -> 9120472
J14: =J13+D13+P13 -> 347069.37 | K14: =K13+E13+Q13 -> 48259.8 | L14: =L13+F13+R13 -> 68309403 | M14: =M16-E12 -> #REF!
J15: =J16-#REF! -> #REF! | K15: =K16-#REF! -> #REF! | L15: =L16-#REF! -> #REF! | M15: =M16-#REF! -> #REF!
K16: =SUBTOTAL(9,K19:K111) -> #REF! | M16: =SUBTOTAL(9,M19:M111) -> #REF!
B17: 날짜 | C17: 내역 | D17: 담당자 | E17: 증빙번호 | F17: 대계정 | G17: 소계정 | H17: 입금 | K17: 출금 | N17: 잔액 | R17: 항목
B18: 날짜 | C18: 내역 | D18: 담당자 | E18: 증빙번호 | F18: 대계정 | G18: 소계정 | H18: CNY | I18: 환산요율 | J18: USD | K18: CNY | L18: 환산요율 | M18: USD | N18: CNY | O18: USD | P18: 비고 | R18: 항목
B19: 45777 | N19: 45051.06 | O19: 6150.4268 | S19: 6150.4252
B20: 45790 | C20: USD입금 and RMB 환전 | E20: 1 | H20: 343685.06 | J20: 47916 | N20: =N19+H20-K20 -> 388736.12 | O20: =O19+J20-M20 -> 54066.427
B21: 45790 | C21: 은행수수료 | F21: 해외지사비 | M21: 51 | N21: =N20+H21-K21 -> 388736.12 | O21: =O20+J21-M21 -> 54015.427
B22: 45792 | C22: 사무실 임대료/전기세 관련 | E22: 2 | F22: 지급임차료 | G22: 사무실임차료 | K22: 25096 | L22: =#REF! -> #REF! | M22: =K22/L22 -> #REF! | N22: =N21+H22-K22 -> 363640.12 | O22: =O21+J22-M22 -> #REF! | P22: 4월 송금 | S22: =S19-M22+J22 -> #REF!
B23: 45792 | C23: 은행수수료 | E23: 3 | F23: 해외지사비 | K23: 7.2 | L23: =#REF! -> #REF! | M23: =K23/L23 -> #REF! | N23: =N22+H23-K23 -> 363632.92 | O23: =O22+J23-M23 -> #REF! | P23: 4월 송금 | S23: =S22-M23+J23 -> #REF!
B24: 45792 | C24: 사무실 주차비 | E24: 4 | F24: 여비교통비 | G24: 해외 | K24: 1600 | L24: =#REF! -> #REF! | M24: =K24/L24 -> #REF! | N24: =N23+H24-K24 -> 362032.92 | O24: =O23+J24-M24 -> #REF! | P24: 4월 송금 | S24: =S23-M24+J24 -> #REF!
B25: 45792 | C25: 은행수수료 | E25: 5 | F25: 해외지사비 | K25: 3.6 | L25: =#REF! -> #REF! | M25: =K25/L25 -> #REF! | N25: =N24+H25-K25 -> 362029.32 | O25: =O24+J25-M25 -> #REF! | P25: 4월 송금 | S25: =S24-M25+J25 -> #REF!
B26: 45796 | C26: 세무대행비 | E26: 6 | F26: 해외지사비 | K26: 1010 | L26: =#REF! -> #REF! | M26: =K26/L26 -> #REF! | N26: =N25+H26-K26 -> 361019.32 | O26: =O25+J26-M26 -> #REF! | P26: 4월 송금 | S26: =S25-M26+J26 -> #REF!
B27: 45796 | C27: 은행수수료 | E27: 7 | F27: 해외지사비 | K27: 3.6 | L27: =#REF! -> #REF! | M27: =K27/L27 -> #REF! | N27: =N26+H27-K27 -> 361015.72 | O27: =O26+J27-M27 -> #REF! | P27: 4월 송금 | S27: =S26-M27+J27 -> #REF!
B28: 45796 | C28: 사무실 WIFI+통신비 | D28: 신순연 | E28: 8 | F28: 통신비 | G28: 기타 | K28: 1018.2 | L28: =#REF! -> #REF! | M28: =K28/L28 -> #REF! | N28: =N27+H28-K28 -> 359997.52 | O28: =O27+J28-M28 -> #REF! | P28: 4월 송금 | S28: =S27-M28+J28 -> #REF!
B29: 45796 | C29: 사무실 운영비 | D29: 신순연 | E29: 9 | F29: 해외지사비 | K29: 676 | L29: =#REF! -> #REF! | M29: =K29/L29 -> #REF! | N29: =N28+H29-K29 -> 359321.52 | O29: =O28+J29-M29 -> #REF! | P29: 4월 송금 | S29: =S28-M29+J29 -> #REF!
B30: 45796 | C30: 수수료 | D30: 신순연 | E30: 10 | F30: 해외지사비 | K30: 3.6 | L30: =#REF! -> #REF! | M30: =K30/L30 -> #REF! | N30: =N29+H30-K30 -> 359317.92 | O30: =O29+J30-M30 -> #REF! | P30: 4월 송금 | S30: =S29-M30+J30 -> #REF!
B31: 45796 | C31: 시내 교통비 | D31: Pan Shi Qiang | E31: 11 | F31: 여비교통비 | G31: 해외 | K31: 419.4 | L31: =#REF! -> #REF! | M31: =K31/L31 -> #REF! | N31: =N30+H31-K31 -> 358898.52 | O31: =O30+J31-M31 -> #REF! | P31: 4월 송금 | S31: =S30-M31+J31 -> #REF!
B32: 45796 | C32: 출장비 | D32: Pan Shi Qiang | E32: 12 | F32: 여비교통비 | G32: 해외 | K32: 628 | L32: =#REF! -> #REF! | M32: =K32/L32 -> #REF! | N32: =N31+H32-K32 -> 358270.52 | O32: =O31+J32-M32 -> #REF! | P32: 4월 송금 | S32: =S31-M32+J32 -> #REF!
B33: 45796 | C33: 통신비 | D33: Pan Shi Qiang | E33: 13 | F33: 통신비 | G33: 기타 | K33: 123.8 | L33: =#REF! -> #REF! | M33: =K33/L33 -> #REF! | N33: =N32+H33-K33 -> 358146.72 | O33: =O32+J33-M33 -> #REF! | P33: 4월 송금 | S33: =S32-M33+J33 -> #REF!
B34: 45796 | C34: 추진비 | D34: Pan Shi Qiang | E34: 14 | F34: 업무추진비 | G34: 일반 | K34: 318.4 | L34: =#REF! -> #REF! | M34: =K34/L34 -> #REF! | N34: =N33+H34-K34 -> 357828.32 | O34: =O33+J34-M34 -> #REF! | P34: 4월 송금 | S34: =S33-M34+J34 -> #REF!
B35: 45796 | C35: 수수료 | D35: Pan Shi Qiang | E35: 15 | F35: 해외지사비 | K35: 3.6 | L35: =#REF! -> #REF! | M35: =K35/L35 -> #REF! | N35: =N34+H35-K35 -> 357824.72 | O35: =O34+J35-M35 -> #REF! | P35: 4월 송금 | S35: =S34-M35+J35 -> #REF!
B36: 45796 | C36: 시내 교통비 | D36: Zhang Liang | E36: 16 | F36: 여비교통비 | G36: 해외 | K36: 536.62 | L36: =#REF! -> #REF! | M36: =K36/L36 -> #REF! | N36: =N35+H36-K36 -> 357288.1 | O36: =O35+J36-M36 -> #REF! | P36: 4월 송금 | S36: =S35-M36+J36 -> #REF!
B37: 45796 | C37: 출장비 | D37: Zhang Liang | E37: 17 | F37: 여비교통비 | G37: 해외 | K37: 5617.81 | L37: =#REF! -> #REF! | M37: =K37/L37 -> #REF! | N37: =N36+H37-K37 -> 351670.29 | O37: =O36+J37-M37 -> #REF! | P37: 4월 송금 | S37: =S36-M37+J37 -> #REF!
B38: 45796 | C38: 통신비 | D38: Zhang Liang | E38: 18 | F38: 통신비 | G38: 기타 | K38: 400 | L38: =#REF! -> #REF! | M38: =K38/L38 -> #REF! | N38: =N37+H38-K38 -> 351270.29 | O38: =O37+J38-M38 -> #REF! | P38: 4월 송금 | S38: =S37-M38+J38 -> #REF!
B39: 45796 | C39: 업무추진비 | D39: Zhang Liang | E39: 19 | F39: 업무추진비 | G39: 일반 | K39: 361 | L39: =#REF! -> #REF! | M39: =K39/L39 -> #REF! | N39: =N38+H39-K39 -> 350909.29 | O39: =O38+J39-M39 -> #REF! | P39: 4월 송금 | S39: =S38-M39+J39 -> #REF!
B40: 45796 | C40: 택배비 | D40: Zhang Liang | E40: 20 | F40: 해외지사비 | K40: 276.6 | L40: =#REF! -> #REF! | M40: =K40/L40 -> #REF! | N40: =N39+H40-K40 -> 350632.69 | O40: =O39+J40-M40 -> #REF! | P40: 4월 송금 | S40: =S39-M40+J40 -> #REF!
B41: 45796 | C41: 사무용픔 | D41: Zhang Liang | E41: 21 | F41: 해외지사비 | K41: 517 | L41: =#REF! -> #REF! | M41: =K41/L41 -> #REF! | N41: =N40+H41-K41 -> 350115.69 | O41: =O40+J41-M41 -> #REF! | P41: 4월 송금 | S41: =S40-M41+J41 -> #REF!
...

Sheet 2026-05
B2: ▶ 00년 00월 전도금 정산 내역 (심천지사)_4000061 (B2F590) | H2: 보증금 입금 내역_1,234.5 (#1900000828 / #1200000234 / #100013313)
B3: 00년 00월 송금_1405.60 (#) | F3: 1405.6 | H3: 00년 00월 송금_1358.90 (#) | L3: 1358.9
B4: 대계정 | C4: 소계정 | D4: 금액 (CNY) | E4: 금액 (USD) | F4: 금액 (KRW) | H4: 대계정 | I4: 소계정 | J4: 금액 (CNY) | K4: 금액 (USD) | L4: 금액 (KRW)
A5: 51131050 | B5: 업무추진비 | C5: 일반 | F5: =ROUND(E5*$F$3,0) -> 0 | H5: 업무추진비 | I5: 일반 | L5: =ROUND(K5*$L$3,0) -> 0 | S5: =F5+L5+R5 -> 0
A6: 51061030 | B6: 여비교통비 | C6: 해외 | F6: =ROUND(E6*$F$3,0) -> 0 | H6: 여비교통비 | I6: 해외 | L6: =ROUND(K6*$L$3,0) -> 0 | S6: =F6+L6+R6 -> 0
A7: 51201020 | B7: 지급임차료 | C7: 사무실임차료 | F7: =ROUND(E7*$F$3,0) -> 0 | H7: 지급임차료 | I7: 사무실임차료 | L7: =ROUND(K7*$L$3,0) -> 0 | S7: =F7+L7+R7 -> 0
A8: 51201030 | B8: 지급임차료 | C8: 차량임차료 | F8: =ROUND(E8*$F$3,0) -> 0 | H8: 지급임차료 | I8: 차량임차료 | L8: =ROUND(K8*$L$3,0) -> 0 | S8: =F8+L8+R8 -> 0
A9: 51071700 | B9: 통신비 | C9: 기타 | F9: =ROUND(E9*$F$3,0) -> 0 | H9: 통신비 | I9: 기타 | L9: =ROUND(K9*$L$3,0) -> 0
A10: 51321010 | B10: 해외지사비 | F10: =ROUND(E10*$F$3,0) -> 0 | H10: 해외지사비 | L10: =ROUND(K10*$L$3,0) -> 0
B11: 세금과공과 | C11: 기타 | F11: =ROUND(E11*$F$3,0) -> 0 | H11: 세금과공과 | I11: 기타 | L11: =ROUND(K11*$L$3,0) -> 0
A12: 51031020 | B12: 급여(incentive) | C12: 성과급여조정 | G12: =G14/G13 -> #REF! | H12: 급여(incentive) | I12: 포상금 | L12: =ROUND(K12*$L$3,0) -> 0
A13: 52981010 | B13: (-)잡이익(50) | C13: (-)잡이익 | F13: =ROUND(E13*$F$3,0) -> 0 | G13: =E14+R14+U14 -> 0 | H13: (-)잡이익(50) | I13: (-)잡이익 | L13: =ROUND(K13*$L$3,0) -> 0
B14: Total | D14: =SUM(D5:D12)-D13 -> 0 | E14: =SUM(E5:E12)-E13 -> 0 | F14: =SUM(F5:F12)-F13 -> 0 | G14: =F14+#REF!+V14 -> #REF! | H14: Total | J14: =SUM(J5:J12)-J13 -> 0 | K14: =SUM(K5:K12)-K13 -> 0 | L14: =SUM(L5:L12)-L13 -> 0
J15: =J14-J13 -> 0 | K15: =K14-K13 -> 0 | L15: =L14-L13 -> 0
I18: =SUBTOTAL(9,J21:J96) -> 438992.36 | K18: =SUBTOTAL(9,L21:L96) -> 64496.45 | L18: =SUBTOTAL(9,M21:M96) -> 671764.9 | M18: =SUBTOTAL(9,O21:O109) -> 100805.4 | N18: =SUBTOTAL(9,O21:O96) -> 99568.997
B19: 날짜 | E19: 내역 | F19: 담당자 | G19: 증빙번호 | H19: 대계정 | I19: 소계정 | J19: 입금 | M19: 출금 | P19: 잔액 | R19: 비고 | S19: 시스템 판독
B20: 출금일자 | C20: 증빙일자 | D20: 증빙번호(FULL) | E20: 내역 | F20: 담당자 | G20: 증빙번호 | H20: 대계정 | I20: 소계정 | J20: CNY | K20: 환산요율 | L20: USD | M20: CNY | N20: 환산요율 | O20: USD | P20: CNY | Q20: USD | R20: 비고 | S20: 시스템 판독
B21: 2026-04-30 | P21: 0 | Q21: 0
B22: 2026-05-06 | C22: 2026-05-06 | E22: USD입금/RMB환전 CNY 36153.32 | F22: 심천지사 | G22: 1 | H22: X | I22: 전도금 입금 | J22: 36153.32 | K22: 6.93 | L22: 5226.93 | P22: =P21+J22-M22 -> 36153.32 | Q22: =Q21+L22-O22 -> 5226.93 | S22: ✅ 입금 확인 (USD: 5226.93 / 환산요율: 6.93 / 수수료 USD: 10) 파표 외 영수증
B23: 2026-05-06 | C23: 2026-05-06 | E23: USD입금/RMB환전 수수료 USD 10 | F23: 심천지사 | G23: 1 | H23: 해외지사비 | I23: 전도금 입금 | M23: =O23*N23 -> 0 | O23: 10 | P23: =P22+J23-M23 -> 36153.32 | Q23: =Q22+L23-O23 -> 5216.93 | S23: ✅ 입금 확인 (USD: 5226.93 / 환산요율: 6.93 / 수수료 USD: 10) 파표 외 영수증
B24: 2026-05-18 | C24: 2026-05-18 | E24: USD입금/RMB환전 CNY 402839.04 | F24: 심천지사 | G24: 2 | H24: X | I24: 전도금 입금 | J24: 402839.04 | K24: 6.7996 | L24: 59269.52 | P24: =P23+J24-M24 -> 438992.36 | Q24: =Q23+L24-O24 -> 64486.45 | S24: ✅ 입금 확인 (USD: 59269.52 / 환산요율: 6.7996 / 수수료 USD: 25) 파표 외 영수증
B25: 2026-05-18 | C25: 2026-05-18 | E25: USD입금/RMB환전 수수료 USD 25 | F25: 심천지사 | G25: 2 | H25: 해외지사비 | I25: 전도금 입금 | M25: =O25*N25 -> 0 | O25: 25 | P25: =P24+J25-M25 -> 438992.36 | Q25: =Q24+L25-O25 -> 64461.45 | S25: ✅ 입금 확인 (USD: 59269.52 / 환산요율: 6.7996 / 수수료 USD: 25) 파표 외 영수증
B26: 2026-05-12 | C26: 2026-05-03 | D26: 26952000001805357341 | E26: 차량 Rent비 | F26: 심천지사 | G26: 3 | H26: 해외지사비 | M26: 3.6 | N26: ='통장내역(환율표)'!D94 -> 6.7491 | O26: =M26/N26 -> 0.53340446 | P26: =P25+J26-M26 -> 438988.76 | Q26: =Q25+L26-O26 -> 64460.917 | S26: ✅ 금액 일치
B27: 2026-05-12 | C27: 2026-05-03 | D27: 26952000001805650846 | E27: 차량 기사비 | F27: 심천지사 | G27: 4 | H27: 업무추진비 | I27: 일반 | M27: 258 | N27: ='통장내역(환율표)'!D94 -> 6.7491 | O27: =M27/N27 -> 38.227319 | P27: =P26+J27-M27 -> 438730.76 | Q27: =Q26+L27-O27 -> 64422.689 | S27: [⚠️ 금액 불일치 (이체 5,680.95 / 영수증 26,072.78)] 파표 회사코드 불일치/누락
B28: 2026-05-12 | C28: 2026-05-03 | D28: 26952000001805651776 | E28: 기사 야근비용 | F28: 심천지사 | G28: 5 | H28: 업무추진비 | M28: 873 | N28: ='통장내역(환율표)'!D94 -> 6.7491 | O28: =M28/N28 -> 129.35058 | P28: =P27+J28-M28 -> 437857.76 | Q28: =Q27+L28-O28 -> 64293.339 | S28: 파표 회사코드 불일치/누락
B29: 2026-05-12 | C29: 2026-05-03 | D29: 26952000001805065096 | E29: 차량 Rent비 | F29: 심천지사 | G29: 6 | H29: 업무추진비 | M29: 792.08 | N29: ='통장내역(환율표)'!D94 -> 6.7491 | O29: =M29/N29 -> 117.36083 | P29: =P28+J29-M29 -> 437065.68 | Q29: =Q28+L29-O29 -> 64175.978
B30: 2026-05-12 | C30: 2026-05-03 | D30: 26952000001805951821 | E30: 차량 기사비 | F30: 심천지사 | G30: 7 | H30: 업무추진비 | M30: 402 | N30: ='통장내역(환율표)'!D94 -> 6.7491 | O30: =M30/N30 -> 59.563497 | P30: =P29+J30-M30 -> 436663.68 | Q30: =Q29+L30-O30 -> 64116.414
B31: 2026-05-12 | C31: 2026-05-03 | D31: 26952000001805218291 | E31: 기사 야근비용 | F31: 심천지사 | G31: 8 | H31: 업무추진비 | M31: 297 | N31: ='통장내역(환율표)'!D94 -> 6.7491 | O31: =M31/N31 -> 44.005868 | P31: =P30+J31-M31 -> 436366.68 | Q31: =Q30+L31-O31 -> 64072.408 | S31: [⚠️ 금액 불일치 (이체 1,019.60 / 영수증 9,058.00)]
B32: 2026-05-12 | C32: 2026-05-06 | D32: 26952000001838818096 | E32: 세무 대행비 | F32: 심천지사 | G32: 9 | H32: 해외지사비 | M32: 676 | N32: ='통장내역(환율표)'!D94 -> 6.7491 | O32: =M32/N32 -> 100.1615 | P32: =P31+J32-M32 -> 435690.68 | Q32: =Q31+L32-O32 -> 63972.247
B33: 2026-05-12 | C33: 2026-05-06 | D33: 26952000001839468886 | E33: 세무 대행비 | F33: 심천지사 | G33: 10 | H33: 여비교통비 | I33: 해외 | M33: 51.1 | N33: ='통장내역(환율표)'!D94 -> 6.7491 | O33: =M33/N33 -> 7.5713799 | P33: =P32+J33-M33 -> 435639.58 | Q33: =Q32+L33-O33 -> 63964.676
B34: 2026-05-12 | C34: 2026-05-21 | D34: 26952000002085925876 | E34: 3월 사무실 전기세 | F34: 심천지사 | G34: 11 | H34: 여비교통비 | I34: 해외 | M34: 87.9 | N34: ='통장내역(환율표)'!D94 -> 6.7491 | O34: =M34/N34 -> 13.023959 | P34: =P33+J34-M34 -> 435551.68 | Q34: =Q33+L34-O34 -> 63951.652
B35: 2026-05-12 | C35: 2026-05-21 | D35: 26952000002085292786 | E35: 3월 사무실 전기세 | F35: 심천지사 | G35: 12 | H35: 여비교통비 | I35: 해외 | M35: 37.9 | N35: ='통장내역(환율표)'!D94 -> 6.7491 | O35: =M35/N35 -> 5.6155636 | P35: =P34+J35-M35 -> 435513.78 | Q35: =Q34+L35-O35 -> 63946.036
B36: 2026-05-12 | C36: 2026-05-21 | E36: 교통비 | F36: 심천지사 | G36: 13 | H36: 여비교통비 | I36: 해외 | M36: 52.7 | N36: ='통장내역(환율표)'!D94 -> 6.7491 | O36: =M36/N36 -> 7.8084486 | P36: =P35+J36-M36 -> 435461.08 | Q36: =Q35+L36-O36 -> 63938.228 | S36: [⚠️ 금액 불일치 (이체 8,707.90 / 영수증 9,353.40)] 파표 외 영수증
B37: 2026-05-12 | C37: 2026-05-21 | D37: 26952000002080236721 | E37: 차량 Rent비 | F37: 심천지사 | G37: 14 | H37: 통신비 | I37: 기타 | M37: 417 | N37: ='통장내역(환율표)'!D94 -> 6.7491 | O37: =M37/N37 -> 61.786016 | P37: =P36+J37-M37 -> 435044.08 | Q37: =Q36+L37-O37 -> 63876.442
B38: 2026-05-12 | C38: 2026-05-21 | D38: 26952000002080364596 | E38: 차량 기사비 | F38: 심천지사 | G38: 15 | H38: 통신비 | I38: 기타 | M38: 499 | N38: ='통장내역(환율표)'!D94 -> 6.7491 | O38: =M38/N38 -> 73.935784 | P38: =P37+J38-M38 -> 434545.08 | Q38: =Q37+L38-O38 -> 63802.506
B39: 2026-05-12 | C39: 2026-05-21 | D39: 26952000002079537391 | E39: 기사 야근비용 | F39: 심천지사 | G39: 16 | H39: 업무추진비 | I39: 일반 | M39: 693 | N39: ='통장내역(환율표)'!D94 -> 6.7491 | O39: =M39/N39 -> 102.68036 | P39: =P38+J39-M39 -> 433852.08 | Q39: =Q38+L39-O39 -> 63699.825
B40: 2026-05-12 | C40: 2026-05-12 | E40: 은행수수료 | F40: 심천지사 | G40: 17 | H40: 해외지사비 | M40: 3.6 | N40: ='통장내역(환율표)'!D94 -> 6.7491 | O40: =M40/N40 -> 0.53340446 | P40: =P39+J40-M40 -> 433848.48 | Q40: =Q39+L40-O40 -> 63699.292 | S40: [⚠️ 금액 불일치 (이체 16,850.00 / 영수증 5,140.28)]
B41: 2026-05-19 | C41: 2026-05-19 | E41: 은행수수료 | F41: 심천지사 | G41: 18 | H41: 해외지사비 | M41: 7.2 | N41: ='통장내역(환율표)'!D94 -> 6.7491 | O41: =M41/N41 -> 1.0668089 | P41: =P40+J41-M41 -> 433841.28 | Q41: =Q40+L41-O41 -> 63698.225 | S41: [⚠️ 금액 불일치 (이체 89.25 / 영수증 0.00)]
B42: 2026-05-23 | C42: 2026-05-23 | E42: 은행수수료 | F42: 심천지사 | G42: 19 | H42: 해외지사비 | M42: 3.6 | N42: ='통장내역(환율표)'!D94 -> 6.7491 | O42: =M42/N42 -> 0.53340446 | P42: =P41+J42-M42 -> 433837.68 | Q42: =Q41+L42-O42 -> 63697.692 | S42: [⚠️ 금액 불일치 (이체 17.00 / 영수증 0.00)]
B43: 2026-05-23 | C43: 2026-05-23 | E43: 은행수수료 | F43: 심천지사 | G43: 20 | H43: 해외지사비 | M43: 7.2 | N43: ='통장내역(환율표)'!D94 -> 6.7491 | O43: =M43/N43 -> 1.0668089 | P43: =P42+J43-M43 -> 433830.48 | Q43: =Q42+L43-O43 -> 63696.625 | S43: [⚠️ 금액 불일치 (이체 13.00 / 영수증 0.00)]
...

Sheet 통장지급내역

Sheet 당월 업무추진비
B2: ▶ 업무추진비 사용 내역
B4: NO | C4: 정산일자 | D4: 사용일자 | E4: 사용자 | F4: 사용처 | G4: 사용금액 | I4: 사용목적(상세 기재) | J4: 고객명 | K4: 참석자
G5: RMB | H5: KRW | K5: 고객 | L5: DBGC
B6: =ROW()-5 -> 1 | D6: 46133 | E6: xiongfeng | F6: 大师兄餐饮 | G6: 135 | I6: Have coffee with SDPC | J6: SDPC | K6: 魏慧 | L6: xiongfeng/金总
B7: =ROW()-5 -> 2 | D7: 46134 | E7: xiongfeng | F7: 星巴克 | G7: 68 | I7: Coffee with CSOT | J7: CSOT | K7: 裴娟实 | L7: xiongfeng
B8: =ROW()-5 -> 3 | D8: 46149 | E8: xiongfeng | F8: 星莹美食店 | G8: 370 | I8: Lunch with CSOT | J8: CSOT | K8: 裴娟实/彩霞 | L8: xiongfeng
B9: =ROW()-5 -> 4 | D9: 46151 | E9: xiongfeng | F9: 萍乡土菜 | G9: 233 | I9: Lunch with FITI | J9: SDPC | K9: 牛佳兴 | L9: xiongfeng
B10: =ROW()-5 -> 5 | D10: 46118 | E10: 신순연 | F10: 晶东 | G10: 258 | I10: 고객 업무 추진 및 CRM 유지 | J10: CSOT | K10: Li Xiang Yu | L10: -
B11: =ROW()-5 -> 6 | D11: 46119 | E11: 신순연 | F11: 郭老二 | G11: 873 | I11: 고객 업무 추진 및 CRM 유지 | J11: TianMa | K11: Mason전문가, Eddie전문가 | L11: 고재홍 상무, 최상신 전문위원, 김기일 프로, 박상현 프로, 황대욱 프로, 변승찬 프로, 권유석 지사장, 김명관 프로, 신순연 프로
B12: =ROW()-5 -> 7 | D12: 46120 | E12: 신순연 | F12: 韩庭 | G12: 402 | I12: 고객 업무 추진 및 CRM 유지 | J12: TianMa | K12: Mason전문가, Eddie전문가 | L12: 고재홍 상무, 최상신 전문위원, 김기일 프로, 박상현 프로, 황대욱 프로, 변승찬 프로, 신순연 프로
B13: =ROW()-5 -> 8 | D13: 46120 | E13: 신순연 | F13: 鱼头泡饭 | G13: 800 | I13: 고객 업무 추진 및 CRM 유지 | J13: CSOT | K13: Pan Xiao Dong과장 | L13: 고재홍 상무, 최상신 전문위원, 김기일 프로, 박상현 프로, 황대욱 프로, 변승찬 프로, 신순연 프로
B14: =ROW()-5 -> 9 | D14: 46128 | E14: 신순연 | F14: 京华楼 | G14: 297 | I14: 고객 업무 추진 및 CRM 유지 | J14: CSOT | K14: Nate전문가 | L14: 권유석 지사장, 이상태 프로, 박미령 프로, Xiong Feng프로, 신순연 프로
B15: =ROW()-5 -> 10 | D15: 46150 | E15: 신순연 | F15: 河坝 | G15: 693 | I15: 고객 업무 추진 및 CRM 유지 | J15: CSOT | K15: Liu Kai Yu, Jiang Song Lin(대리점) | L15: Zhang Liang, Lin Wei Jian, 신순연
B16: =ROW()-5 -> 11 | D16: 3월26일 | E16: 권유석 | F16: 스.벅 | G16: 60 | I16: 음료 | J16: CSOT | K16: 조달구매 | L16: 권유석/정겨운
B17: =ROW()-5 -> 12 | D17: 3월26일 | E17: 권유석 | F17: 소풍 | G17: 281 | I17: 석식 | J17: CSOT | K17: 조달구매 | L17: 권유석/정겨운
B18: =ROW()-5 -> 13 | D18: 3월31일 | E18: 권유석 | F18: 홍콩반점 | G18: 315 | I18: 석식 | J18: SDC | K18: 구매(신우철 부장) | L18: 권유석/정겨운
B19: =ROW()-5 -> 14 | D19: 4월2일 | E19: 권유석 | F19: 세븐일레븐 | G19: 100.7 | I19: 음료 | J19: CSOT | K19: 영업/KA | L19: 권유석/신순연
B20: =ROW()-5 -> 15 | D20: 4월3일 | E20: 권유석 | F20: 홍콩반점 | G20: 255 | I20: 석식 | J20: BOE | K20: 김문청 사장 | L20: 권유석
B21: =ROW()-5 -> 16 | D21: 4월17일 | E21: 권유석 | F21: 홍콩반점 | G21: 307.8 | I21: 석식 | J21: BOE | K21: 김청길 사장(MTK 대리점) | L21: 권유석
B22: =ROW()-5 -> 17 | D22: 4월21일 | E22: 권유석 | F22: 전통 찻집 | G22: 260 | I22: 음료 | J22: ESWIN | K22: 구매 책임자/담당자 | L22: 권유석/정겨운
B23: =ROW()-5 -> 18 | D23: 4월21일 | E23: 권유석 | F23: 订餐卡 | G23: 674 | I23: 중식 | J23: ESWIN | K23: 구매 책임자/담당자 | L23: 권유석/정겨운
B24: =ROW()-5 -> 19 | D24: 4월21일 | E24: 권유석 | F24: 스타벅스 | G24: 103 | I24: 음료 | J24: ESWIN | K24: 구매 책임자/담당자 | L24: 권유석/정겨운
B25: =ROW()-5 -> 20 | D25: 46132 | E25: PIAO MEILING | F25: 同盛餐饮 | G25: 246 | I25: CSOT 업무 추진 | J25: CSOT | K25: Liu Wei, Yu Han | L25: 박미령
B26: =ROW()-5 -> 21 | D26: 46149 | E26: PIAO MEILING | F26: 爱人餐饮 | G26: 140 | I26: CSOT 업무 추진 | J26: CSOT | K26: Fan Xiankun, Yu Han | L26: 박미령
B27: =ROW()-5 -> 22 | D27: 46109 | E27: zhangliang | F27: SDPC便利店 | G27: 36.04 | I27: SDPC업무 추진 | J27: SDPC | K27: 孙志强 | L27: zhangliang
B28: =ROW()-5 -> 23 | D28: 46156 | E28: zhangliang | F28: 印尼餐厅 | G28: 1016.12 | I28: HKC업무 추진 | J28: HKC | K28: DK Park、Eddie等 | L28: zhangliang、shenshunyan
B29: =ROW()-5 -> 24 | D29: 46134 | E29: zhangliang | F29: H1水果店 | G29: 58 | I29: HKC업무 추진 | J29: HKC | K29: 费如涵、陈杰 | L29: zhangliang
B30: =ROW()-5 -> 25
B31: =ROW()-5 -> 26
B32: =ROW()-5 -> 27
B33: =ROW()-5 -> 28
B34: =ROW()-5 -> 29
B35: =ROW()-5 -> 30
B36: =ROW()-5 -> 31
B37: =ROW()-5 -> 32
B38: =ROW()-5 -> 33
B39: =ROW()-5 -> 34
B40: =ROW()-5 -> 35
B41: =ROW()-5 -> 36
... B46: =ROW()-5 -> 41
...

Sheet 기사 야근 일지
C3: Liu Ming Liang | J3: chen guo liang | Q3: chen feng jun
C4: 일자 | D4: 내용 | E4: 인원 | F4: 시간 | G4: 비용 | H4: 비고 | J4: 일자 | K4: 내용 | L4: 인원 | M4: 시간 | N4: 비용 | O4: 비고 | Q4: 일자 | R4: 내용 | S4: 인원 | T4: 시간 | U4: 비용 | V4: 비고
C5: 46134 | E5: 심천지사 | G5: =F5*20 -> 0 | L5: 심천지사 | N5: =M5*20 -> 0 | S5: 심천지사 | U5: =T5*20 -> 0
E6: 심천지사 | G6: =F6*20 -> 0 | L6: 심천지사 | N6: =M6*20 -> 0 | S6: 심천지사 | U6: =T6*20 -> 0
E7: 심천지사 | G7: =F7*20 -> 0 | L7: 심천지사 | N7: =M7*20 -> 0 | S7: 심천지사 | U7: =T7*20 -> 0
E8: 심천지사 | G8: =F8*20 -> 0 | L8: 심천지사 | N8: =M8*20 -> 0 | S8: 심천지사 | U8: =T8*20 -> 0
E9: 심천지사 | G9: =F9*20 -> 0 | L9: 심천지사 | N9: =M9*20 -> 0 | S9: 심천지사 | U9: =T9*20 -> 0
E10: 심천지사 | G10: =F10*20 -> 0 | L10: 심천지사 | N10: =M10*20 -> 0 | S10: 심천지사 | U10: =T10*20 -> 0
E11: 심천지사 | G11: =F11*20 -> 0 | L11: 심천지사 | N11: =M11*20 -> 0 | S11: 심천지사 | U11: =T11*20 -> 0
E12: 심천지사 | G12: =F12*20 -> 0 | L12: 심천지사 | N12: =M12*20 -> 0 | S12: 심천지사 | U12: =T12*20 -> 0
E13: 심천지사 | G13: =F13*20 -> 0 | L13: 심천지사 | N13: =M13*20 -> 0 | S13: 심천지사 | U13: =T13*20 -> 0
E14: 심천지사 | G14: =F14*20 -> 0 | L14: 심천지사 | N14: =M14*20 -> 0 | S14: 심천지사 | U14: =T14*20 -> 0
E15: 심천지사 | G15: =F15*20 -> 0 | L15: 심천지사 | N15: =M15*20 -> 0 | S15: 심천지사 | U15: =T15*20 -> 0
E16: 심천지사 | G16: =F16*20 -> 0 | L16: 심천지사 | N16: =M16*20 -> 0 | S16: 심천지사 | U16: =T16*20 -> 0
E17: 심천지사 | G17: =F17*20 -> 0 | L17: 심천지사 | N17: =M17*20 -> 0 | S17: 심천지사 | U17: =T17*20 -> 0
... E23: 심천지사 | G23: =F23*20 -> 0 | L23: 심천지사 | N23: =M23*20 -> 0 | S23: 심천지사 | U23: =T23*20 -> 0
G24: =SUM(G5:G23) -> 0 | N24: =SUM(N5:N23) -> 0 | U24: =SUM(U5:U23) -> 0
