Workbook
Name Large_scale_classification: [1]Sheet3!$C$4:$C$10

Sheet 통장내역(환율표)
B2: 통장 일자 | C2: 지급 | F2: 송금액 | I2: 입금 | K2: 출금 | M2: 잔액
C3: 지급시 환율 | D3: 환산요율 | E3: 전표번호 | F3: USD | G3: 수수료 | H3: RMB | I3: USD | J3: RMB | K3: USD | L3: RMB | M3: USD | N3: RMB
B4: 45854 | F4: 74022.44 | N4: =H4-L4
B5: 45854 | C5: 1373.8 | D5: =-H5/F5 | E5: 2000001679 | F5: -73987.44 | H5: 530297.58 | K5: 35 | L5: 73092 | N5: =H5-L5
B6: 45855 | L6: 2403.6 | N6: =N5-L6
B7: 45860 | L7: 28287.2 | N7: =N6-L7
B8: 45862 | L8: 345390.38 | N8: =N7-L8
B9: 45863 | L9: 80014.4 | N9: =N8-L9
N10: =N9
B11: 45881 | F11: 66958.93 | N11: =N10+H11-L11
B12: 45881 | C12: 1384.2 | D12: =-H12/F12 | E12: 2000001943 | F12: -66933.93 | H12: 480471.83 | K12: 25 | N12: =N11+H12-L12
B13: 45883 | L13: 1110.0568 | N13: =N12+H13-L13
B14: 45883 | L14: 26430.74 | N14: =N13+H14-L14
B15: 45887 | L15: 33.6 | N15: =N14+H15-L15
B16: 45888 | L16: 148030.18 | N16: =N15+H16-L16
B17: 45889 | L17: 292153.69 | N17: =N16+H17-L17
N18: =N17+H18-L18
B19: 45910 | L19: 243.6 | N19: =N18+H19-L19
B20: 45911 | F20: 58404.05 | N20: =N19+H20-L20
B21: 45911 | C21: 1386.6 | D21: =-H21/F21 | E21: 2000002211 | F21: -58379.05 | H21: 415110.07 | K21: 25 | N21: =N20+H21-L21
B22: 45915 | L22: 13580.058 | N22: =N21+H22-L22
B23: 45915 | L23: 13975.74 | N23: =N22+H23-L23
B24: 45921 | J24: 32.36 | N24: =N23+H24-L24+J24
B25: 45923 | L25: 399903.2 | N25: =N24+H25-L25
N26: =N25+H26-L26
B27: 45943 | F27: 76124.43 | N27: =N26+H27-L27
B28: 45943 | C28: 1401.9 | D28: =-H28/F28 | E28: 2000002505 | F28: -76099.43 | H28: 541561.59 | K28: 25 | N28: =N27+H28-L28
B29: 45945 | L29: 1263.4825 | N29: =N28+H29-L29
B30: 45945 | L30: 26248.32 | N30: =N29+H30-L30
B31: 45952 | L31: 57279.62 | N31: =N30+H31-L31
B32: 45953 | L32: 435679.23 | N32: =N31+H32-L32
N33: =N32+H33-L33
B34: 45974 | F34: 58100.87 | N34: =N33+H34-L34
B35: 45974 | C35: 1454 | D35: =-H35/F35 | E35: 2000002746 | F35: -58075.87 | H35: 411415.27 | K35: 25 | N35: =N34+H35-L35
B36: 45975 | L36: 22335.89 | N36: =N35+H36-L36
B37: 45975 | L37: 5111.91 | N37: =N36+H37-L37
B38: 45985 | L38: 377571.91 | N38: =N37+H38-L38
N39: =N38
B40: 46002 | F40: 60766.8 | N40: =N39+H40-L40
B41: 46002 | C41: 1470.4 | D41: =-H41/F41 | E41: 2000003021 | F41: -60741.8 | H41: 428211.47 | K41: 25 | N41: =N40+H41-L41
...

Sheet 내역_25.01
B2: ▶ 25년 1월 전도금 정산 내역 (심천지사)_4000061 (B2F590) | H2: 보증금 입금 내역_1,234.5 (#1900000828 / #1200000234 / #100013313)
B3: 24년 12월 송금_1,433.2(#) | F3: 1433.2 | H3: 25년 1월 송금_1458.2(#) | L3: 1458.2 | N3: 25년 1월 2차 송금_1,434.30 (#) | R3: 1434.3 | X3: 1327.2
B4: 대계정 | C4: 소계정 | D4: 금액 (CNY) | E4: 금액 (USD) | F4: 금액 (KRW) | H4: 대계정 | I4: 소계정 | J4: 금액 (CNY) | K4: 금액 (USD) | L4: 금액 (KRW) | N4: 대계정 | O4: 소계정 | P4: 금액 (CNY) | Q4: 금액 (USD) | R4: 금액 (KRW)
A5: 51131050 | B5: 업무추진비 | C5: 일반 | F5: =ROUND(E5*$F$3,0) | H5: 업무추진비 | I5: 일반 | J5: 30124.08 | K5: 4115.82 | L5: =ROUND(K5*$L$3,0) | M5: =L5+F5 | N5: 업무추진비 | O5: 일반 | R5: =ROUND(Q5*$R$3,0) | S5: =F5+L5+R5
A6: 51061030 | B6: 여비교통비 | C6: 해외 | D6: 1600 | E6: 220.27 | F6: =ROUND(E6*$F$3,0) | H6: 여비교통비 | I6: 해외 | J6: 23408.08 | K6: 3198.22 | L6: =ROUND(K6*$L$3,0) | M6: =L6+F6 | N6: 여비교통비 | O6: 해외 | R6: =ROUND(Q6*$R$3,0) | S6: =F6+L6+R6
A7: 51201020 | B7: 지급임차료 | C7: 사무실임차료 | D7: 24455 | E7: 3366.74 | F7: =ROUND(E7*$F$3,0) | H7: 지급임차료 | I7: 사무실임차료 | L7: =ROUND(K7*$L$3,0) | M7: =L7+F7 | N7: 지급임차료 | O7: 사무실임차료 | R7: =ROUND(Q7*$R$3,0) | S7: =F7+L7+R7
A8: 51201030 | B8: 지급임차료 | C8: 차량임차료 | D8: 8307.64 | E8: 1143.72 | F8: =ROUND(E8*$F$3,0) | H8: 지급임차료 | I8: 차량임차료 | J8: 9192.36 | K8: 1255.94 | L8: =ROUND(K8*$L$3,0) | M8: =L8+F8 | N8: 지급임차료 | O8: 차량임차료 | R8: =ROUND(Q8*$R$3,0) | S8: =F8+L8+R8
A9: 51071700 | B9: 통신비 | C9: 기타 | F9: =ROUND(E9*$F$3,0) | H9: 통신비 | I9: 기타 | J9: 1412.84 | K9: 193.03 | L9: =ROUND(K9*$L$3,0) | M9: =L9+F9 | N9: 통신비 | O9: 기타 | R9: =ROUND(Q9*$R$3,0) | S9: =F9+L9+R9
A10: 51321010 | B10: 해외지사비 | D10: 43977.03 | E10: 6054.36 | F10: =ROUND(E10*$F$3,0) | H10: 해외지사비 | J10: 331930.54 | K10: 45402.28 | L10: =ROUND(K10*$L$3,0) | M10: =L10+F10 | N10: 해외지사비 | R10: =ROUND(Q10*$R$3,0) | S10: =F10+L10+R10
A11: 51031020 | B11: 급여(incentive) | C11: 성과급여조정 | F11: =ROUND(E11*$F$3,0) | G11: =G13/G12 | H11: 급여(incentive) | I11: 포상금 | L11: =ROUND(K11*$L$3,0) | M11: =L11+F11 | N11: 급여(incentive) | O11: 포상금 | Q11: 36 | R11: =ROUND(Q11*$R$3,0) | S11: =F11+L11+R11
A12: 52981010 | B12: (-)잡이익(50) | C12: (-)잡이익 | F12: =ROUND(E12*$F$3,0) | G12: =E13+Q13+AB13 | H12: (-)잡이익(50) | I12: (-)잡이익 | L12: =ROUND(K12*$L$3,0) | M12: =L12+F12 | N12: (-)잡이익(50) | O12: (-)잡이익 | R12: =ROUND(Q12*$R$3,0) | S12: =F12+L12+R12
B13: Total | D13: =SUM(D5:D11)-D12 | E13: =SUM(E5:E11)-E12 | F13: =SUM(F5:F11)-F12 | G13: =F13+R13+AC13 | H13: Total | J13: =SUM(J5:J11)-J12 | K13: =SUM(K5:K11)-K12 | L13: =SUM(L5:L11)-L12 | M13: =L13+F13 | N13: Total | P13: =SUM(P5:P11)-P12 | Q13: =SUM(Q5:Q11)-Q12 | R13: =SUM(R5:R11)-R12 | S13: =F13+L13+R13 | X13: =F13+R13
D14: =SUM(D7:D10) | E14: =SUM(E7:E10) | F14: =SUM(F7:F10) | J14: =J13+D13+P13 | K14: =K13+E13+Q13 | L14: =L13+F13+R13 | M14: =M16-E12 | P14: =P13+D13+J13 | Q14: =Q13+E13+K13 | R14: =R13+F13+L13
K15: =K16-H85 | M15: =M16-J85
K16: =SUBTOTAL(9,K19:K103) | M16: =SUBTOTAL(9,M19:M103)
B17: 날짜 | C17: 내역 | D17: 담당자 | E17: 증빙번호 | F17: 대계정 | G17: 소계정 | H17: 입금 | K17: 출금 | N17: 잔액 | R17: 항목
B18: 날짜 | C18: 내역 | D18: 담당자 | E18: 증빙번호 | F18: 대계정 | G18: 소계정 | H18: CNY | I18: 환산요율 | J18: USD | K18: CNY | L18: 환산요율 | M18: USD | N18: CNY | O18: USD | P18: 비고 | R18: 항목
B19: 45657 | N19: 78313.1 | O19: 10785.092 | S19: 10785.091
B20: 45667 | C20: 4분기 세금 비용 | E20: 1 | F20: 해외지사비 | K20: 42812.63 | L20: ='[2]통장내역(환율표)'!$D$238 | M20: =K20/L20 | N20: =N19+H20-K20 | O20: =O19+J20-M20 | P20: 12월 송금 | S20: =S19-M20
B21: 45670 | C21: USD입금 and RMB 환전 | E21: 2 | H21: 473948.32 | J21: 64806 | N21: =N20+H21-K21 | O21: =O20+J21-M21
B22: 45670 | C22: 은행수수료 | E22: 2 | F22: 해외지사비 | M22: 51 | N22: =N21+H22-K22 | O22: =O21+J22-M22
B23: 45672 | C23: DB HITEK조회확인서 수수료 | E23: 3 | F23: 해외지사비 | K23: 140 | L23: ='[2]통장내역(환율표)'!$D$238 | M23: =K23/L23 | N23: =N22+H23-K23 | O23: =O22+J23-M23 | P23: 12월 송금 | S23: =S20-M23
B24: 45672 | C24: 사무실 임대료/전기세 관련 | E24: 4 | F24: 지급임차료 | G24: 사무실 | K24: 24455 | L24: ='[2]통장내역(환율표)'!$D$238 | M24: =K24/L24 | N24: =N23+H24-K24 | O24: =O23+J24-M24 | P24: 12월 송금 | S24: =S23-M24
B25: 45672 | C25: 은행수수료 | E25: 5 | F25: 해외지사비 | K25: 7.2 | L25: ='[2]통장내역(환율표)'!$D$238 | M25: =K25/L25 | N25: =N24+H25-K25 | O25: =O24+J25-M25 | P25: 12월 송금 | S25: =S24-M25
B26: 45672 | C26: 사무실 주차비 | E26: 6 | F26: 여비교통비 | G26: 해외 | K26: 1600 | L26: ='[2]통장내역(환율표)'!$D$238 | M26: =K26/L26 | N26: =N25+H26-K26 | O26: =O25+J26-M26 | P26: 12월 송금 | S26: =S25-M26
B27: 45672 | C27: 은행수수료 | E27: 7 | F27: 해외지사비 | K27: 3.6 | L27: ='[2]통장내역(환율표)'!$D$238 | M27: =K27/L27 | N27: =N26+H27-K27 | O27: =O26+J27-M27 | P27: 12월 송금 | S27: =S26-M27
B28: 45674 | C28: 세무대행비 | E28: 8 | F28: 해외지사비 | K28: 1010 | L28: ='[2]통장내역(환율표)'!$D$238 | M28: =K28/L28 | N28: =N27+H28-K28 | O28: =O27+J28-M28 | P28: 12월 송금 | S28: =S27-M28
B29: 45674 | C29: 은행수수료 | E29: 9 | F29: 해외지사비 | K29: 3.6 | L29: ='[2]통장내역(환율표)'!$D$238 | M29: =K29/L29 | N29: =N28+H29-K29 | O29: =O28+J29-M29 | P29: 12월 송금 | S29: =S28-M29
B30: 45674 | C30: 차량 Rent비 | E30: 10 | F30: 지급임차료 | G30: 차량임차료 | K30: =L30*M30 | L30: ='[2]통장내역(환율표)'!$D$238 | M30: 1143.7198 | N30: =N29+H30-K30 | O30: =O29+J30-M30 | P30: 12월 송금 | S30: =S29-M30
B31: 45674 | C31: 차량 Rent비 | E31: 10 | F31: 지급임차료 | G31: 차량임차료 | K31: =10500-K30 | L31: ='[2]통장내역(환율표)'!$D$246 | M31: =K31/L31 | N31: =N30+H31-K31 | O31: =O30+J31-M31 | P31: 1월 송금 | S31: =64755-M31
B32: 45674 | C32: 차량 기사비 | E32: 10 | F32: 해외지사비 | K32: 6000 | L32: ='[2]통장내역(환율표)'!$D$246 | M32: =K32/L32 | N32: =N31+H32-K32 | O32: =O31+J32-M32 | P32: 1월 송금 | S32: =S31-M32
B33: 45674 | C33: 기사 야근비용 | E33: 10 | F33: 해외지사비 | K33: 610 | L33: ='[2]통장내역(환율표)'!$D$246 | M33: =K33/L33 | N33: =N32+H33-K33 | O33: =O32+J33-M33 | P33: 1월 송금 | S33: =S32-M33
B34: 45674 | C34: 차량 Rent비 | E34: 10 | F34: 지급임차료 | G34: 차량임차료 | K34: 7000 | L34: ='[2]통장내역(환율표)'!$D$246 | M34: =K34/L34 | N34: =N33+H34-K34 | O34: =O33+J34-M34 | P34: 1월 송금 | S34: =S33-M34
B35: 45674 | C35: 차량 기사비 | E35: 10 | F35: 해외지사비 | K35: 6000 | L35: ='[2]통장내역(환율표)'!$D$246 | M35: =K35/L35 | N35: =N34+H35-K35 | O35: =O34+J35-M35 | P35: 1월 송금 | S35: =S34-M35
B36: 45674 | C36: 기사 야근비용 | E36: 10 | F36: 해외지사비 | K36: 510 | L36: ='[2]통장내역(환율표)'!$D$246 | M36: =K36/L36 | N36: =N35+H36-K36 | O36: =O35+J36-M36 | P36: 1월 송금 | S36: =S35-M36
B37: 45674 | C37: 은행수수료 | E37: 11 | F37: 해외지사비 | K37: 7.2 | L37: ='[2]통장내역(환율표)'!$D$246 | M37: =K37/L37 | N37: =N36+H37-K37 | O37: =O36+J37-M37 | P37: 1월 송금 | S37: =S36-M37
B38: 45674 | C38: 사무실 WIFI+통신비 | E38: 12 | F38: 통신비 | G38: 기타 | K38: 417.84 | L38: ='[2]통장내역(환율표)'!$D$246 | M38: =K38/L38 | N38: =N37+H38-K38 | O38: =O37+J38-M38 | P38: 1월 송금 | R38: 신순연 | S38: =S37-M38
B39: 45674 | C39: 은행수수료 | E39: 13 | F39: 해외지사비 | K39: 3.6 | L39: ='[2]통장내역(환율표)'!$D$246 | M39: =K39/L39 | N39: =N38+H39-K39 | O39: =O38+J39-M39 | P39: 1월 송금 | R39: 신순연 | S39: =S38-M39
B40: 45674 | C40: 출장비 | E40: 14 | F40: 여비교통비 | G40: 해외 | K40: 2579.69 | L40: ='[2]통장내역(환율표)'!$D$246 | M40: =K40/L40 | N40: =N39+H40-K40 | O40: =O39+J40-M40 | P40: 1월 송금 | R40: Pan Shi Qiang | S40: =S39-M40
B41: 45674 | C41: 시내교통비 | E41: 15 | F41: 여비교통비 | G41: 해외 | K41: 178.26 | L41: ='[2]통장내역(환율표)'!$D$246 | M41: =K41/L41 | N41: =N40+H41-K41 | O41: =O40+J41-M41 | P41: 1월 송금 | R41: Pan Shi Qiang | S41: =S40-M41
...

Sheet 내역_25.02
B2: ▶ 25년 2월 전도금 정산 내역 (심천지사)_4000061 (B2F590) | H2: 보증금 입금 내역_1,234.5 (#1900000828 / #1200000234 / #100013313)
B3: 25년 1월 송금_1458.2(#) | F3: 1458.2 | H3: 25년 1월 2차 송금_1,434.30 (#) | L3: 1434.3 | N3: 25년 2월 송금_1447.40 (#) | R3: 1447.4 | X3: 1327.2
B4: 대계정 | C4: 소계정 | D4: 금액 (CNY) | E4: 금액 (USD) | F4: 금액 (KRW) | H4: 대계정 | I4: 소계정 | J4: 금액 (CNY) | K4: 금액 (USD) | L4: 금액 (KRW) | N4: 대계정 | O4: 소계정 | P4: 금액 (CNY) | Q4: 금액 (USD) | R4: 금액 (KRW)
A5: 51131050 | B5: 업무추진비 | C5: 일반 | D5: 13162.8 | E5: 1798.42 | F5: =ROUND(E5*$F$3,0) | H5: 업무추진비 | I5: 일반 | J5: 3415.36 | K5: 472.51 | L5: =ROUND(K5*$L$3,0) | M5: =L5+F5 | N5: 업무추진비 | O5: 일반 | R5: =ROUND(Q5*$R$3,0) | S5: =F5+L5+R5
A6: 51061030 | B6: 여비교통비 | C6: 해외 | D6: 7210.07 | E6: 985.1 | F6: =ROUND(E6*$F$3,0) | H6: 여비교통비 | I6: 해외 | J6: 7124.78 | K6: 985.71 | L6: =ROUND(K6*$L$3,0) | M6: =L6+F6 | N6: 여비교통비 | O6: 해외 | R6: =ROUND(Q6*$R$3,0) | S6: =F6+L6+R6
A7: 51201020 | B7: 지급임차료 | C7: 사무실임차료 | D7: 24224 | E7: 3309.7 | F7: =ROUND(E7*$F$3,0) | H7: 지급임차료 | I7: 사무실임차료 | L7: =ROUND(K7*$L$3,0) | M7: =L7+F7 | N7: 지급임차료 | O7: 사무실임차료 | R7: =ROUND(Q7*$R$3,0) | S7: =F7+L7+R7
A8: 51201030 | B8: 지급임차료 | C8: 차량임차료 | D8: 17500 | E8: 2391 | F8: =ROUND(E8*$F$3,0) | H8: 지급임차료 | I8: 차량임차료 | L8: =ROUND(K8*$L$3,0) | M8: =L8+F8 | N8: 지급임차료 | O8: 차량임차료 | R8: =ROUND(Q8*$R$3,0) | S8: =F8+L8+R8
A9: 51071700 | B9: 통신비 | C9: 기타 | D9: 1155.8 | E9: 157.92 | F9: =ROUND(E9*$F$3,0) | H9: 통신비 | I9: 기타 | J9: 93.06 | K9: 12.87 | L9: =ROUND(K9*$L$3,0) | M9: =L9+F9 | N9: 통신비 | O9: 기타 | R9: =ROUND(Q9*$R$3,0) | S9: =F9+L9+R9
A10: 51321010 | B10: 해외지사비 | D10: 14627.75 | E10: 1998.57 | F10: =ROUND(E10*$F$3,0) | H10: 해외지사비 | J10: 45500.22 | K10: 6294.91 | L10: =ROUND(K10*$L$3,0) | M10: =L10+F10 | N10: 해외지사비 | P10: 167290.76 | Q10: 22984.82 | R10: =ROUND(Q10*$R$3,0) | S10: =F10+L10+R10
A11: 51031020 | B11: 급여(incentive) | C11: 성과급여조정 | F11: =ROUND(E11*$F$3,0) | G11: =G13/G12 | H11: 급여(incentive) | I11: 포상금 | L11: =ROUND(K11*$L$3,0) | M11: =L11+F11 | N11: 급여(incentive) | O11: 포상금 | P11: 56779 | Q11: 7783.81 | R11: =ROUND(Q11*$R$3,0) | S11: =F11+L11+R11
A12: 52981010 | B12: (-)잡이익(50) | C12: (-)잡이익 | F12: =ROUND(E12*$F$3,0) | G12: =E13+Q13+AB13 | H12: (-)잡이익(50) | I12: (-)잡이익 | L12: =ROUND(K12*$L$3,0) | M12: =L12+F12 | N12: (-)잡이익(50) | O12: (-)잡이익 | R12: =ROUND(Q12*$R$3,0) | S12: =F12+L12+R12
B13: Total | D13: =SUM(D5:D11)-D12 | E13: =SUM(E5:E11)-E12 | F13: =SUM(F5:F11)-F12 | G13: =F13+R13+AC13 | H13: Total | J13: =SUM(J5:J11)-J12 | K13: =SUM(K5:K11)-K12 | L13: =SUM(L5:L11)-L12 | M13: =L13+F13 | N13: Total | P13: =SUM(P5:P11)-P12 | Q13: =SUM(Q5:Q11)-Q12 | R13: =SUM(R5:R11)-R12 | S13: =F13+L13+R13 | X13: =F13+R13
D14: =SUM(D7:D10) | E14: =SUM(E7:E10) | F14: =SUM(F7:F10) | J14: =J13+D13+P13 | K14: =K13+E13+Q13 | L14: =L13+F13+R13 | M14: =M16-E12 | P14: =P13+D13+J13 | Q14: =Q13+E13+K13 | R14: =R13+F13+L13
K15: =K16-H95 | M15: =M16-J95
K16: =SUBTOTAL(9,K19:K97) | M16: =SUBTOTAL(9,M19:M97)
B17: 날짜 | C17: 내역 | D17: 담당자 | E17: 증빙번호 | F17: 대계정 | G17: 소계정 | H17: 입금 | K17: 출금 | N17: 잔액 | R17: 항목
B18: 날짜 | C18: 내역 | D18: 담당자 | E18: 증빙번호 | F18: 대계정 | G18: 소계정 | H18: CNY | I18: 환산요율 | J18: USD | K18: CNY | L18: 환산요율 | M18: USD | N18: CNY | O18: USD | P18: 비고 | R18: 항목
B19: 45688 | N19: 133987.27 | O19: 18406.711 | S19: 10640.71
B20: 45699 | C20: USD입금 and RMB 환전 | E20: 1 | H20: 324926.21 | J20: 44595 | N20: =N19+H20-K20 | O20: =O19+J20-M20 | S20: =S19-M20
C21: 은행수수료 | F21: 해외지사비 | M21: 51 | N21: =N20+H21-K21 | O21: =O20+J21-M21 | P21: 2월 송금
B22: 45702 | C22: 사무실 임대료/전기세 관련 | E22: 2 | F22: 지급임차료 | G22: 사무실임차료 | K22: 24224 | L22: =#REF! | M22: =K22/L22 | N22: =N21+H22-K22 | O22: =O21+J22-M22 | P22: 1월 송금 | S22: =S20-M22
B23: 45702 | C23: 은행수수료 | E23: 3 | F23: 해외지사비 | K23: 7.2 | L23: =#REF! | M23: =K23/L23 | N23: =N22+H23-K23 | O23: =O22+J23-M23 | P23: 1월 송금 | S23: =S22-M23
B24: 45702 | C24: 사무실 주차비 | E24: 4 | F24: 여비교통비 | G24: 해외 | K24: 1600 | L24: =#REF! | M24: =K24/L24 | N24: =N23+H24-K24 | O24: =O23+J24-M24 | P24: 1월 송금 | S24: =S23-M24
B25: 45702 | C25: 은행수수료 | E25: 5 | F25: 해외지사비 | K25: 3.6 | L25: =#REF! | M25: =K25/L25 | N25: =N24+H25-K25 | O25: =O24+J25-M25 | P25: 1월 송금 | S25: =S24-M25
B26: 45708 | C26: 세무대행비 | E26: 6 | F26: 해외지사비 | K26: 1010 | L26: =#REF! | M26: =K26/L26 | N26: =N25+H26-K26 | O26: =O25+J26-M26 | P26: 1월 송금 | S26: =S25-M26
B27: 45708 | C27: 은행수수료 | E27: 7 | F27: 해외지사비 | K27: 3.6 | L27: =#REF! | M27: =K27/L27 | N27: =N26+H27-K27 | O27: =O26+J27-M27 | P27: 1월 송금 | S27: =S26-M27
B28: 45708 | C28: 차량 Rent비 | E28: 8 | F28: 지급임차료 | G28: 차량임차료 | K28: 10500 | L28: =#REF! | M28: =K28/L28 | N28: =N27+H28-K28 | O28: =O27+J28-M28 | P28: 1월 송금 | S28: =S27-M28
B29: 45708 | C29: 차량 기사비 | E29: 8 | F29: 해외지사비 | K29: 6000 | L29: =#REF! | M29: =K29/L29 | N29: =N28+H29-K29 | O29: =O28+J29-M29 | P29: 1월 송금 | S29: =S28-M29
B30: 45708 | C30: 기사 야근비용 | E30: 8 | F30: 해외지사비 | K30: 680 | L30: =#REF! | M30: =K30/L30 | N30: =N29+H30-K30 | O30: =O29+J30-M30 | P30: 1월 송금 | S30: =S29-M30
B31: 45708 | C31: 차량 Rent비 | E31: 8 | F31: 지급임차료 | G31: 차량임차료 | K31: 7000 | L31: =#REF! | M31: =K31/L31 | N31: =N30+H31-K31 | O31: =O30+J31-M31 | P31: 1월 송금 | S31: =S30-M31
B32: 45708 | C32: 차량 기사비 | E32: 8 | F32: 해외지사비 | K32: 6000 | L32: =#REF! | M32: =K32/L32 | N32: =N31+H32-K32 | O32: =O31+J32-M32 | P32: 1월 송금 | S32: =S31-M32
B33: 45708 | C33: 기사 야근비용 | E33: 8 | F33: 해외지사비 | K33: 230 | L33: =#REF! | M33: =K33/L33 | N33: =N32+H33-K33 | O33: =O32+J33-M33 | P33: 1월 송금 | S33: =S32-M33
B34: 45708 | C34: 은행수수료 | E34: 9 | F34: 해외지사비 | K34: 7.2 | L34: =#REF! | M34: =K34/L34 | N34: =N33+H34-K34 | O34: =O33+J34-M34 | P34: 1월 송금 | S34: =S33-M34
B35: 45708 | C35: 신순연_사무실 wfi, 통신비 | E35: 10 | F35: 통신비 | G35: 기타 | K35: 397.8 | L35: =#REF! | M35: =K35/L35 | N35: =N34+H35-K35 | O35: =O34+J35-M35 | P35: 1월 송금 | S35: =S34-M35
B36: 45708 | C36: 은행수수료 | E36: 11 | F36: 해외지사비 | K36: 3.6 | L36: =#REF! | M36: =K36/L36 | N36: =N35+H36-K36 | O36: =O35+J36-M36 | P36: 1월 송금 | S36: =S35-M36
B37: 45708 | C37: Pan Shi Qiang_출장비 | E37: 12 | F37: 여비교통비 | G37: 해외 | K37: 1231.33 | L37: =#REF! | M37: =K37/L37 | N37: =N36+H37-K37 | O37: =O36+J37-M37 | P37: 1월 송금 | S37: =S36-M37
B38: 45708 | C38: Pan Shi Qiang_통신비 | E38: 13 | F38: 통신비 | G38: 기타 | K38: 108.9 | L38: =#REF! | M38: =K38/L38 | N38: =N37+H38-K38 | O38: =O37+J38-M38 | P38: 1월 송금 | S38: =S37-M38
B39: 45708 | C39: 은행수수료 | E39: 14 | F39: 해외지사비 | K39: 3.6 | L39: =#REF! | M39: =K39/L39 | N39: =N38+H39-K39 | O39: =O38+J39-M39 | P39: 1월 송금 | S39: =S38-M39
B40: 45708 | C40: Zhang Liang_시내교통비 | E40: 15 | F40: 여비교통비 | G40: 해외 | K40: 503.6 | L40: =#REF! | M40: =K40/L40 | N40: =N39+H40-K40 | O40: =O39+J40-M40 | P40: 1월 송금 | S40: =S39-M40
B41: 45708 | C41: Zhang Liang_출장비 | E41: 16 | F41: 여비교통비 | G41: 해외 | K41: 617.75 | L41: =#REF! | M41: =K41/L41 | N41: =N40+H41-K41 | O41: =O40+J41-M41 | P41: 1월 송금 | S41: =S40-M41
...

Sheet 내역_25.03
B2: ▶ 25년 3월 전도금 정산 내역 (심천지사)_4000061 (B2F590) | H2: 보증금 입금 내역_1,234.5 (#1900000828 / #1200000234 / #100013313)
B3: 25년 2월 송금_1447.40 (#) | F3: 1447.4 | H3: 25년 3월 송금_1,446.30 (#) | L3: 1446.3 | X3: 1327.2
B4: 대계정 | C4: 소계정 | D4: 금액 (CNY) | E4: 금액 (USD) | F4: 금액 (KRW) | H4: 대계정 | I4: 소계정 | J4: 금액 (CNY) | K4: 금액 (USD) | L4: 금액 (KRW)
A5: 51131050 | B5: 업무추진비 | C5: 일반 | D5: 14845.68 | E5: 2035.1825 | F5: =ROUND(E5*$F$3,0) | H5: 업무추진비 | I5: 일반 | L5: =ROUND(K5*$L$3,0) | M5: =L5+F5 | S5: =F5+L5+R5
A6: 51061030 | B6: 여비교통비 | C6: 해외 | D6: 18459.27 | E6: 2530.5737 | F6: =ROUND(E6*$F$3,0) | H6: 여비교통비 | I6: 해외 | J6: 18692.93 | K6: 2589.84 | L6: =ROUND(K6*$L$3,0) | M6: =L6+F6 | S6: =F6+L6+R6
A7: 51201020 | B7: 지급임차료 | C7: 사무실임차료 | D7: 25272 | E7: 3464.53 | F7: =ROUND(E7*$F$3,0) | H7: 지급임차료 | I7: 사무실임차료 | L7: =ROUND(K7*$L$3,0) | M7: =L7+F7 | S7: =F7+L7+R7
A8: 51201030 | B8: 지급임차료 | C8: 차량임차료 | D8: 17500 | E8: 2399.07 | F8: =ROUND(E8*$F$3,0) | H8: 지급임차료 | I8: 차량임차료 | L8: =ROUND(K8*$L$3,0) | M8: =L8+F8 | S8: =F8+L8+R8
A9: 51071700 | B9: 통신비 | C9: 기타 | D9: 1453.59 | E9: 199.27205 | F9: =ROUND(E9*$F$3,0) | H9: 통신비 | I9: 기타 | J9: 169 | K9: 23.41 | L9: =ROUND(K9*$L$3,0) | M9: =L9+F9 | S9: =F9+L9+R9
A10: 51321010 | B10: 해외지사비 | D10: 23429.319 | E10: 3211.9156 | F10: =ROUND(E10*$F$3,0) | H10: 해외지사비 | J10: 274853 | K10: 38130.88 | L10: =ROUND(K10*$L$3,0) | M10: =L10+F10 | S10: =F10+L10+R10
A11: 51031020 | B11: 급여(incentive) | C11: 성과급여조정 | G11: =G13/G12 | H11: 급여(incentive) | I11: 포상금 | L11: =ROUND(K11*$L$3,0) | M11: =L11+F11 | S11: =F11+L11+R11
A12: 52981010 | B12: (-)잡이익(50) | C12: (-)잡이익 | D12: 103.37 | E12: 14.17 | F12: =ROUND(E12*$F$3,0) | G12: =E13+Q13+AB13 | H12: (-)잡이익(50) | I12: (-)잡이익 | L12: =ROUND(K12*$L$3,0) | M12: =L12+F12 | S12: =F12+L12+R12
B13: Total | D13: =SUM(D5:D11)-D12 | E13: =SUM(E5:E11)-E12 | F13: =SUM(F5:F11)-F12 | G13: =F13+R13+AC13 | H13: Total | J13: =SUM(J5:J11)-J12 | K13: =SUM(K5:K11)-K12 | L13: =SUM(L5:L11)-L12 | M13: =L13+F13 | S13: =F13+L13+R13 | X13: =F13+R13
J14: =J13+D13+P13 | K14: =K13+E13+Q13 | L14: =L13+F13+R13 | M14: =M16-E12
J15: =J16-G96 | K15: =K16-H96 | L15: =L16-I96 | M15: =M16-J96
K16: =SUBTOTAL(9,K19:K105) | M16: =SUBTOTAL(9,M19:M105)
B17: 날짜 | C17: 내역 | D17: 담당자 | E17: 증빙번호 | F17: 대계정 | G17: 소계정 | H17: 입금 | K17: 출금 | N17: 잔액 | R17: 항목
B18: 날짜 | C18: 내역 | D18: 담당자 | E18: 증빙번호 | F18: 대계정 | G18: 소계정 | H18: CNY | I18: 환산요율 | J18: USD | K18: CNY | L18: 환산요율 | M18: USD | N18: CNY | O18: USD | P18: 비고 | R18: 항목
B19: 45716 | N19: 100829.88 | O19: 13826.37 | S19: 13826.369
B20: 45727 | C20: USD입금 and RMB 환전 | E20: 1 | H20: 346107.95 | J20: 48003 | N20: =N19+H20-K20 | O20: =O19+J20-M20 | P20: 2월 송금
B21: 45727 | C21: 은행수수료 | F21: 해외지사비 | M21: 51 | N21: =N20+H21-K21 | O21: =O20+J21-M21 | P21: 2월 송금
B22: 45733 | C22: 사무실 임대료/전기세 관련 | E22: 2 | F22: 지급임차료 | G22: 사무실 | K22: 25272 | L22: =#REF! | M22: =K22/L22 | N22: =N21+H22-K22 | O22: =O21+J22-M22 | P22: 2월 송금 | S22: =S19-M22+J22
B23: 45733 | C23: 은행수수료 | E23: 3 | F23: 해외지사비 | K23: 7.2 | L23: =#REF! | M23: =K23/L23 | N23: =N22+H23-K23 | O23: =O22+J23-M23 | P23: 2월 송금 | S23: =S22-M23+J23
B24: 45733 | C24: 사무실 주차비 | E24: 4 | F24: 여비교통비 | G24: 해외 | K24: 1600 | L24: =#REF! | M24: =K24/L24 | N24: =N23+H24-K24 | O24: =O23+J24-M24 | P24: 2월 송금 | S24: =S23-M24+J24
B25: 45733 | C25: 은행수수료 | E25: 5 | F25: 해외지사비 | K25: 3.6 | L25: =#REF! | M25: =K25/L25 | N25: =N24+H25-K25 | O25: =O24+J25-M25 | P25: 2월 송금 | S25: =S24-M25+J25
B26: 45737 | C26: 이자 | E26: 6 | F26: 잡이익 | H26: 103.37 | I26: =#REF! | J26: 14.17 | L26: =#REF! | M26: =K26/L26 | N26: =N25+H26-K26 | O26: =O25+J26-M26 | P26: 2월 송금 | S26: =S25-M26+J26
B27: 45737 | C27: 세무대행비 | E27: 7 | F27: 해외지사비 | K27: 1010 | L27: =#REF! | M27: =K27/L27 | N27: =N26+H27-K27 | O27: =O26+J27-M27 | P27: 2월 송금 | S27: =S26-M27+J27
B28: 45737 | C28: 은행수수료 | E28: 8 | F28: 해외지사비 | K28: 3.6 | L28: =#REF! | M28: =K28/L28 | N28: =N27+H28-K28 | O28: =O27+J28-M28 | P28: 2월 송금 | S28: =S27-M28+J28
B29: 45737 | C29: 차량 Rent비 | E29: 9 | F29: 지급임차료 | G29: 차량임차료 | K29: 10500 | L29: =#REF! | M29: =K29/L29 | N29: =N28+H29-K29 | O29: =O28+J29-M29 | P29: 2월 송금 | S29: =S28-M29+J29
B30: 45737 | C30: 차량 기사비 | E30: 9 | F30: 해외지사비 | K30: 6000 | L30: =#REF! | M30: =K30/L30 | N30: =N29+H30-K30 | O30: =O29+J30-M30 | P30: 2월 송금 | S30: =S29-M30+J30
B31: 45737 | C31: 기사 야근비용 | E31: 9 | F31: 해외지사비 | K31: 760 | L31: =#REF! | M31: =K31/L31 | N31: =N30+H31-K31 | O31: =O30+J31-M31 | P31: 2월 송금 | S31: =S30-M31+J31
B32: 45737 | C32: 차량 Rent비 | E32: 9 | F32: 지급임차료 | G32: 차량임차료 | K32: 7000 | L32: =#REF! | M32: =K32/L32 | N32: =N31+H32-K32 | O32: =O31+J32-M32 | P32: 2월 송금 | S32: =S31-M32+J32
B33: 45737 | C33: 차량 기사비 | E33: 9 | F33: 해외지사비 | K33: 6000 | L33: =#REF! | M33: =K33/L33 | N33: =N32+H33-K33 | O33: =O32+J33-M33 | P33: 2월 송금 | S33: =S32-M33+J33
B34: 45737 | C34: 기사 야근비용 | E34: 9 | F34: 해외지사비 | K34: 900 | L34: =#REF! | M34: =K34/L34 | N34: =N33+H34-K34 | O34: =O33+J34-M34 | P34: 2월 송금 | S34: =S33-M34+J34
B35: 45737 | C35: 은행수수료 | E35: 10 | F35: 해외지사비 | K35: 7.2 | L35: =#REF! | M35: =K35/L35 | N35: =N34+H35-K35 | O35: =O34+J35-M35 | P35: 2월 송금 | S35: =S34-M35+J35
B36: 45737 | C36: 신순연_사무실 wfi, 통신비 | E36: 11 | F36: 통신비 | G36: 기타 | K36: 419 | L36: =#REF! | M36: 57.44 | N36: =N35+H36-K36 | O36: =O35+J36-M36 | P36: 2월 송금 | R36: 신순연 | S36: =S35-M36+J36
B37: 45737 | C37: 은행수수료 | E37: 12 | F37: 해외지사비 | K37: 3.6 | L37: =#REF! | M37: =K37/L37 | N37: =N36+H37-K37 | O37: =O36+J37-M37 | P37: 2월 송금 | R37: 신순연 | S37: =S36-M37+J37
B38: 45737 | C38: 시내교통비 | E38: 13 | F38: 여비교통비 | G38: 해외 | K38: 428.18 | L38: =#REF! | M38: =K38/L38 | N38: =N37+H38-K38 | O38: =O37+J38-M38 | P38: 2월 송금 | R38: Pan Shi Qiang | S38: =S37-M38+J38
B39: 45737 | C39: 출장비 | E39: 14 | F39: 여비교통비 | G39: 해외 | K39: 2164.32 | L39: =#REF! | M39: =K39/L39 | N39: =N38+H39-K39 | O39: =O38+J39-M39 | P39: 2월 송금 | R39: Pan Shi Qiang | S39: =S38-M39+J39
B40: 45737 | C40: 택배비 | E40: 15 | F40: 해외지사비 | K40: 142.4 | L40: =#REF! | M40: =K40/L40 | N40: =N39+H40-K40 | O40: =O39+J40-M40 | P40: 2월 송금 | R40: Pan Shi Qiang | S40: =S39-M40+J40
B41: 45737 | C41: 통신비 | E41: 16 | F41: 통신비 | G41: 기타 | K41: 118.8 | L41: =#REF! | M41: =K41/L41 | N41: =N40+H41-K41 | O41: =O40+J41-M41 | P41: 2월 송금 | R41: Pan Shi Qiang | S41: =S40-M41+J41
...

Sheet 내역_25.04
B2: ▶ 25년 4월 전도금 정산 내역 (심천지사)_4000061 (B2F590) | H2: 보증금 입금 내역_1,234.5 (#1900000828 / #1200000234 / #100013313)
B3: 25년 3월 송금_1,446.30 (#) | F3: 1446.3 | H3: 25년 4월 송금_1,482.90 (#) | L3: 1482.9 | X3: 1327.2
B4: 대계정 | C4: 소계정 | D4: 금액 (CNY) | E4: 금액 (USD) | F4: 금액 (KRW) | H4: 대계정 | I4: 소계정 | J4: 금액 (CNY) | K4: 금액 (USD) | L4: 금액 (KRW)
A5: 51131050 | B5: 업무추진비 | C5: 일반 | F5: =ROUND(E5*$F$3,0) | H5: 업무추진비 | I5: 일반 | J5: 19195.4 | K5: 2619.03 | L5: =ROUND(K5*$L$3,0) | M5: =L5+F5 | S5: =F5+L5+R5
A6: 51061030 | B6: 여비교통비 | C6: 해외 | F6: =ROUND(E6*$F$3,0) | H6: 여비교통비 | I6: 해외 | J6: 30648.81 | K6: 4181.74 | L6: =ROUND(K6*$L$3,0) | M6: =L6+F6 | S6: =F6+L6+R6
A7: 51201020 | B7: 지급임차료 | C7: 사무실임차료 | D7: 142.17 | E7: 19.7 | F7: =ROUND(E7*$F$3,0) | H7: 지급임차료 | I7: 사무실임차료 | J7: 24914.83 | K7: 3399.39 | L7: =ROUND(K7*$L$3,0) | M7: =L7+F7 | S7: =F7+L7+R7
A8: 51201030 | B8: 지급임차료 | C8: 차량임차료 | F8: =ROUND(E8*$F$3,0) | H8: 지급임차료 | I8: 차량임차료 | J8: 17500 | K8: 2387.71 | L8: =ROUND(K8*$L$3,0) | M8: =L8+F8 | S8: =F8+L8+R8
A9: 51071700 | B9: 통신비 | C9: 기타 | F9: =ROUND(E9*$F$3,0) | H9: 통신비 | I9: 기타 | J9: 1469.1 | K9: 200.44 | L9: =ROUND(K9*$L$3,0) | M9: =L9+F9 | S9: =F9+L9+R9
A10: 51321010 | B10: 해외지사비 | D10: 52250.88 | E10: 7239.17 | F10: =ROUND(E10*$F$3,0) | H10: 해외지사비 | J10: 265516.81 | K10: 36252.26 | L10: =ROUND(K10*$L$3,0) | M10: =L10+F10 | S10: =F10+L10+R10
A11: 51031020 | B11: 급여(incentive) | C11: 성과급여조정 | G11: =G13/G12 | H11: 급여(incentive) | I11: 포상금 | L11: =ROUND(K11*$L$3,0) | M11: =L11+F11 | S11: =F11+L11+R11
A12: 52981010 | B12: (-)잡이익(50) | C12: (-)잡이익 | F12: =ROUND(E12*$F$3,0) | G12: =E13+Q13+AB13 | H12: (-)잡이익(50) | I12: (-)잡이익 | L12: =ROUND(K12*$L$3,0) | M12: =L12+F12 | S12: =F12+L12+R12
B13: Total | D13: =SUM(D5:D11)-D12 | E13: =SUM(E5:E11)-E12 | F13: =SUM(F5:F11)-F12 | G13: =F13+R13+AC13 | H13: Total | J13: =SUM(J5:J11)-J12 | K13: =SUM(K5:K11)-K12 | L13: =SUM(L5:L11)-L12 | M13: =L13+F13 | S13: =F13+L13+R13 | X13: =F13+R13
J14: =J13+D13+P13 | K14: =K13+E13+Q13 | L14: =L13+F13+R13 | M14: =M16-E12
J15: =J16-#REF! | K15: =K16-#REF! | L15: =L16-#REF! | M15: =M16-#REF!
K16: =SUBTOTAL(9,K19:K105) | M16: =SUBTOTAL(9,M19:M105)
B17: 날짜 | C17: 내역 | D17: 담당자 | E17: 증빙번호 | F17: 대계정 | G17: 소계정 | H17: 입금 | K17: 출금 | N17: 잔액 | R17: 항목
B18: 날짜 | C18: 내역 | D18: 담당자 | E18: 증빙번호 | F18: 대계정 | G18: 소계정 | H18: CNY | I18: 환산요율 | J18: USD | K18: CNY | L18: 환산요율 | M18: USD | N18: CNY | O18: USD | P18: 비고 | R18: 항목
B19: 45747 | N19: 52366.41 | O19: 7258.868 | S19: 7258.8664
B20: 45757 | C20: 1분기 기업 소득세 | E20: 1 | F20: 해외지사비 | K20: 52250.88 | L20: =#REF! | M20: =K20/L20 | N20: =N19+H20-K20 | O20: =O19+J20-M20 | P20: 3월 송금 | S20: =S19-M20+J20
B21: 45757 | C21: USD입금 and RMB 환전 | E21: 2 | H21: 404322.65 | J21: 55191 | N21: =N20+H21-K21 | O21: =O20+J21-M21
B22: 45757 | C22: 은행수수료 | F22: 해외지사비 | M22: 25 | N22: =N21+H22-K22 | O22: =O21+J22-M22 | P22: 4월 송금
B23: 45762 | C23: 사무실 임대료/전기세 관련 | E23: 3 | F23: 지급임차료 | G23: 사무실임차료 | K23: =L23*M23 | L23: =#REF! | M23: 19.696706 | N23: =N22+H23-K23 | O23: =O22+J23-M23 | P23: 3월 송금
B24: 45762 | C24: 사무실 임대료/전기세 관련 | E24: 3 | F24: 지급임차료 | G24: 사무실임차료 | K24: =25057-K23 | L24: =#REF! | M24: =K24/L24 | N24: =N23+H24-K24 | O24: =O23+J24-M24 | P24: 4월 송금 | S24: =55166-M24
B25: 45762 | C25: 은행수수료 | E25: 4 | F25: 해외지사비 | K25: 7.2 | L25: =#REF! | M25: =K25/L25 | N25: =N24+H25-K25 | O25: =O24+J25-M25 | P25: 4월 송금 | S25: =S24-M25+J25
B26: 45762 | C26: 사무실 주차비 | E26: 5 | F26: 여비교통비 | G26: 해외 | K26: 1600 | L26: =#REF! | M26: =K26/L26 | N26: =N25+H26-K26 | O26: =O25+J26-M26 | P26: 4월 송금 | S26: =S25-M26+J26
B27: 45762 | C27: 은행수수료 | E27: 6 | F27: 해외지사비 | K27: 3.6 | L27: =#REF! | M27: =K27/L27 | N27: =N26+H27-K27 | O27: =O26+J27-M27 | P27: 4월 송금 | S27: =S26-M27+J27
B28: 45768 | C28: 세무대행비 | E28: 7 | F28: 해외지사비 | K28: 1010 | L28: =#REF! | M28: =K28/L28 | N28: =N27+H28-K28 | O28: =O27+J28-M28 | P28: 4월 송금 | S28: =S27-M28+J28
B29: 45768 | C29: 은행수수료 | E29: 8 | F29: 해외지사비 | K29: 3.6 | L29: =#REF! | M29: =K29/L29 | N29: =N28+H29-K29 | O29: =O28+J29-M29 | P29: 4월 송금 | S29: =S28-M29+J29
B30: 45768 | C30: 차량 Rent비 | E30: 9 | F30: 지급임차료 | G30: 차량임차료 | K30: 10500 | L30: =#REF! | M30: =K30/L30 | N30: =N29+H30-K30 | O30: =O29+J30-M30 | P30: 4월 송금 | S30: =S29-M30+J30
B31: 45768 | C31: 차량 기사비 | E31: 9 | F31: 해외지사비 | K31: 6000 | L31: =#REF! | M31: =K31/L31 | N31: =N30+H31-K31 | O31: =O30+J31-M31 | P31: 4월 송금 | S31: =S30-M31+J31
B32: 45768 | C32: 기사 야근비용 | E32: 9 | F32: 해외지사비 | K32: 470 | L32: =#REF! | M32: =K32/L32 | N32: =N31+H32-K32 | O32: =O31+J32-M32 | P32: 4월 송금 | S32: =S31-M32+J32
B33: 45768 | C33: 차량 Rent비 | E33: 9 | F33: 지급임차료 | G33: 차량임차료 | K33: 7000 | L33: =#REF! | M33: =K33/L33 | N33: =N32+H33-K33 | O33: =O32+J33-M33 | P33: 4월 송금 | S33: =S32-M33+J33
B34: 45768 | C34: 차량 기사비 | E34: 9 | F34: 해외지사비 | K34: 6000 | L34: =#REF! | M34: =K34/L34 | N34: =N33+H34-K34 | O34: =O33+J34-M34 | P34: 4월 송금 | S34: =S33-M34+J34
B35: 45768 | C35: 기사 야근비용 | E35: 9 | F35: 해외지사비 | K35: 400 | L35: =#REF! | M35: =K35/L35 | N35: =N34+H35-K35 | O35: =O34+J35-M35 | P35: 4월 송금 | S35: =S34-M35+J35
B36: 45768 | C36: 은행수수료 | E36: 10 | F36: 해외지사비 | K36: 7.2 | L36: =#REF! | M36: =K36/L36 | N36: =N35+H36-K36 | O36: =O35+J36-M36 | P36: 4월 송금 | S36: =S35-M36+J36
B37: 45768 | C37: 신순연_사무실 wfi, 통신비 | E37: 11 | F37: 통신비 | G37: 기타 | K37: 418 | L37: =#REF! | M37: =K37/L37 | N37: =N36+H37-K37 | O37: =O36+J37-M37 | P37: 4월 송금 | R37: 신순연 | S37: =S36-M37+J37
B38: 45768 | C38: 은행수수료 | E38: 12 | F38: 해외지사비 | K38: 3.6 | L38: =#REF! | M38: =K38/L38 | N38: =N37+H38-K38 | O38: =O37+J38-M38 | P38: 4월 송금 | R38: 신순연 | S38: =S37-M38+J38
B39: 45768 | C39: Pan Shi Qiang_시내교통비 | E39: 13 | F39: 여비교통비 | G39: 해외 | K39: 128.41 | L39: =#REF! | M39: =K39/L39 | N39: =N38+H39-K39 | O39: =O38+J39-M39 | P39: 4월 송금 | R39: Pan Shi Qiang | S39: =S38-M39+J39
B40: 45768 | C40: Pan Shi Qiang_출장비 | E40: 14 | F40: 여비교통비 | G40: 해외 | K40: 4365.36 | L40: =#REF! | M40: =K40/L40 | N40: =N39+H40-K40 | O40: =O39+J40-M40 | P40: 4월 송금 | R40: Pan Shi Qiang | S40: =S39-M40+J40
B41: 45768 | C41: Pan Shi Qiang_통신비 | E41: 15 | F41: 통신비 | G41: 기타 | K41: 153.6 | L41: =#REF! | M41: =K41/L41 | N41: =N40+H41-K41 | O41: =O40+J41-M41 | P41: 4월 송금 | R41: Pan Shi Qiang | S41: =S40-M41+J41
...

Sheet 내역_25.05
B2: ▶ 25년 5월 전도금 정산 내역 (심천지사)_4000061 (B2F590) | H2: 보증금 입금 내역_1,234.5 (#1900000828 / #1200000234 / #100013313)
B3: 25년 4월 송금_1,482.90 (#) | F3: 1482.9 | H3: 25년 5월 송금_1405.60 (#) | L3: 1405.6 | X3: 1327.2
B4: 대계정 | C4: 소계정 | D4: 금액 (CNY) | E4: 금액 (USD) | F4: 금액 (KRW) | H4: 대계정 | I4: 소계정 | J4: 금액 (CNY) | K4: 금액 (USD) | L4: 금액 (KRW)
A5: 51131050 | B5: 업무추진비 | C5: 일반 | D5: 3161.4 | E5: 431.34 | F5: =ROUND(E5*$F$3,0) | H5: 업무추진비 | I5: 일반 | J5: 14265.08 | K5: 1986.7 | L5: =ROUND(K5*$L$3,0) | M5: =L5+F5 | S5: =F5+L5+R5
A6: 51061030 | B6: 여비교통비 | C6: 해외 | D6: 11847.427 | E6: 1616.47 | F6: =ROUND(E6*$F$3,0) | H6: 여비교통비 | I6: 해외 | J6: 19528.07 | K6: 2719.68 | L6: =ROUND(K6*$L$3,0) | M6: =L6+F6 | S6: =F6+L6+R6
A7: 51201020 | B7: 지급임차료 | C7: 사무실임차료 | D7: 25096 | E7: 3424.11 | F7: =ROUND(E7*$F$3,0) | H7: 지급임차료 | I7: 사무실임차료 | L7: =ROUND(K7*$L$3,0) | M7: =L7+F7 | S7: =F7+L7+R7
A8: 51201030 | B8: 지급임차료 | C8: 차량임차료 | F8: =ROUND(E8*$F$3,0) | H8: 지급임차료 | I8: 차량임차료 | J8: 20596 | K8: 2868.4 | L8: =ROUND(K8*$L$3,0) | M8: =L8+F8 | S8: =F8+L8+R8
A9: 51071700 | B9: 통신비 | C9: 기타 | D9: 2034.12 | E9: 277.54 | F9: =ROUND(E9*$F$3,0) | H9: 통신비 | I9: 기타 | J9: 300 | K9: 41.78 | L9: =ROUND(K9*$L$3,0) | M9: =L9+F9 | S9: =F9+L9+R9
A10: 51321010 | B10: 해외지사비 | D10: 2938.75 | E10: 400.97 | F10: =ROUND(E10*$F$3,0) | H10: 해외지사비 | J10: 247302.52 | K10: 34492.81 | L10: =ROUND(K10*$L$3,0) | M10: =L10+F10 | S10: =F10+L10+R10
A11: 51031020 | B11: 급여(incentive) | C11: 성과급여조정 | G11: =G13/G12 | H11: 급여(incentive) | I11: 포상금 | L11: =ROUND(K11*$L$3,0) | M11: =L11+F11 | S11: =F11+L11+R11
A12: 52981010 | B12: (-)잡이익(50) | C12: (-)잡이익 | F12: =ROUND(E12*$F$3,0) | G12: =E13+Q13+AB13 | H12: (-)잡이익(50) | I12: (-)잡이익 | L12: =ROUND(K12*$L$3,0) | M12: =L12+F12 | S12: =F12+L12+R12
B13: Total | D13: =SUM(D5:D11)-D12 | E13: =SUM(E5:E11)-E12 | F13: =SUM(F5:F11)-F12 | G13: =F13+R13+AC13 | H13: Total | J13: =SUM(J5:J11)-J12 | K13: =SUM(K5:K11)-K12 | L13: =SUM(L5:L11)-L12 | M13: =L13+F13 | S13: =F13+L13+R13 | X13: =F13+R13
J14: =J13+D13+P13 | K14: =K13+E13+Q13 | L14: =L13+F13+R13 | M14: =M16-E12
J15: =J16-#REF! | K15: =K16-#REF! | L15: =L16-#REF! | M15: =M16-#REF!
K16: =SUBTOTAL(9,K19:K111) | M16: =SUBTOTAL(9,M19:M111)
B17: 날짜 | C17: 내역 | D17: 담당자 | E17: 증빙번호 | F17: 대계정 | G17: 소계정 | H17: 입금 | K17: 출금 | N17: 잔액 | R17: 항목
B18: 날짜 | C18: 내역 | D18: 담당자 | E18: 증빙번호 | F18: 대계정 | G18: 소계정 | H18: CNY | I18: 환산요율 | J18: USD | K18: CNY | L18: 환산요율 | M18: USD | N18: CNY | O18: USD | P18: 비고 | R18: 항목
B19: 45777 | N19: 45051.06 | O19: 6150.4268 | S19: 6150.4252
B20: 45790 | C20: USD입금 and RMB 환전 | E20: 1 | H20: 343685.06 | J20: 47916 | N20: =N19+H20-K20 | O20: =O19+J20-M20
B21: 45790 | C21: 은행수수료 | F21: 해외지사비 | M21: 51 | N21: =N20+H21-K21 | O21: =O20+J21-M21
B22: 45792 | C22: 사무실 임대료/전기세 관련 | E22: 2 | F22: 지급임차료 | G22: 사무실임차료 | K22: 25096 | L22: =#REF! | M22: =K22/L22 | N22: =N21+H22-K22 | O22: =O21+J22-M22 | P22: 4월 송금 | S22: =S19-M22+J22
B23: 45792 | C23: 은행수수료 | E23: 3 | F23: 해외지사비 | K23: 7.2 | L23: =#REF! | M23: =K23/L23 | N23: =N22+H23-K23 | O23: =O22+J23-M23 | P23: 4월 송금 | S23: =S22-M23+J23
B24: 45792 | C24: 사무실 주차비 | E24: 4 | F24: 여비교통비 | G24: 해외 | K24: 1600 | L24: =#REF! | M24: =K24/L24 | N24: =N23+H24-K24 | O24: =O23+J24-M24 | P24: 4월 송금 | S24: =S23-M24+J24
B25: 45792 | C25: 은행수수료 | E25: 5 | F25: 해외지사비 | K25: 3.6 | L25: =#REF! | M25: =K25/L25 | N25: =N24+H25-K25 | O25: =O24+J25-M25 | P25: 4월 송금 | S25: =S24-M25+J25
B26: 45796 | C26: 세무대행비 | E26: 6 | F26: 해외지사비 | K26: 1010 | L26: =#REF! | M26: =K26/L26 | N26: =N25+H26-K26 | O26: =O25+J26-M26 | P26: 4월 송금 | S26: =S25-M26+J26
B27: 45796 | C27: 은행수수료 | E27: 7 | F27: 해외지사비 | K27: 3.6 | L27: =#REF! | M27: =K27/L27 | N27: =N26+H27-K27 | O27: =O26+J27-M27 | P27: 4월 송금 | S27: =S26-M27+J27
B28: 45796 | C28: 사무실 WIFI+통신비 | D28: 신순연 | E28: 8 | F28: 통신비 | G28: 기타 | K28: 1018.2 | L28: =#REF! | M28: =K28/L28 | N28: =N27+H28-K28 | O28: =O27+J28-M28 | P28: 4월 송금 | S28: =S27-M28+J28
B29: 45796 | C29: 사무실 운영비 | D29: 신순연 | E29: 9 | F29: 해외지사비 | K29: 676 | L29: =#REF! | M29: =K29/L29 | N29: =N28+H29-K29 | O29: =O28+J29-M29 | P29: 4월 송금 | S29: =S28-M29+J29
B30: 45796 | C30: 수수료 | D30: 신순연 | E30: 10 | F30: 해외지사비 | K30: 3.6 | L30: =#REF! | M30: =K30/L30 | N30: =N29+H30-K30 | O30: =O29+J30-M30 | P30: 4월 송금 | S30: =S29-M30+J30
B31: 45796 | C31: 시내 교통비 | D31: Pan Shi Qiang | E31: 11 | F31: 여비교통비 | G31: 해외 | K31: 419.4 | L31: =#REF! | M31: =K31/L31 | N31: =N30+H31-K31 | O31: =O30+J31-M31 | P31: 4월 송금 | S31: =S30-M31+J31
B32: 45796 | C32: 출장비 | D32: Pan Shi Qiang | E32: 12 | F32: 여비교통비 | G32: 해외 | K32: 628 | L32: =#REF! | M32: =K32/L32 | N32: =N31+H32-K32 | O32: =O31+J32-M32 | P32: 4월 송금 | S32: =S31-M32+J32
B33: 45796 | C33: 통신비 | D33: Pan Shi Qiang | E33: 13 | F33: 통신비 | G33: 기타 | K33: 123.8 | L33: =#REF! | M33: =K33/L33 | N33: =N32+H33-K33 | O33: =O32+J33-M33 | P33: 4월 송금 | S33: =S32-M33+J33
B34: 45796 | C34: 추진비 | D34: Pan Shi Qiang | E34: 14 | F34: 업무추진비 | G34: 일반 | K34: 318.4 | L34: =#REF! | M34: =K34/L34 | N34: =N33+H34-K34 | O34: =O33+J34-M34 | P34: 4월 송금 | S34: =S33-M34+J34
B35: 45796 | C35: 수수료 | D35: Pan Shi Qiang | E35: 15 | F35: 해외지사비 | K35: 3.6 | L35: =#REF! | M35: =K35/L35 | N35: =N34+H35-K35 | O35: =O34+J35-M35 | P35: 4월 송금 | S35: =S34-M35+J35
B36: 45796 | C36: 시내 교통비 | D36: Zhang Liang | E36: 16 | F36: 여비교통비 | G36: 해외 | K36: 536.62 | L36: =#REF! | M36: =K36/L36 | N36: =N35+H36-K36 | O36: =O35+J36-M36 | P36: 4월 송금 | S36: =S35-M36+J36
B37: 45796 | C37: 출장비 | D37: Zhang Liang | E37: 17 | F37: 여비교통비 | G37: 해외 | K37: 5617.81 | L37: =#REF! | M37: =K37/L37 | N37: =N36+H37-K37 | O37: =O36+J37-M37 | P37: 4월 송금 | S37: =S36-M37+J37
B38: 45796 | C38: 통신비 | D38: Zhang Liang | E38: 18 | F38: 통신비 | G38: 기타 | K38: 400 | L38: =#REF! | M38: =K38/L38 | N38: =N37+H38-K38 | O38: =O37+J38-M38 | P38: 4월 송금 | S38: =S37-M38+J38
B39: 45796 | C39: 업무추진비 | D39: Zhang Liang | E39: 19 | F39: 업무추진비 | G39: 일반 | K39: 361 | L39: =#REF! | M39: =K39/L39 | N39: =N38+H39-K39 | O39: =O38+J39-M39 | P39: 4월 송금 | S39: =S38-M39+J39
B40: 45796 | C40: 택배비 | D40: Zhang Liang | E40: 20 | F40: 해외지사비 | K40: 276.6 | L40: =#REF! | M40: =K40/L40 | N40: =N39+H40-K40 | O40: =O39+J40-M40 | P40: 4월 송금 | S40: =S39-M40+J40
B41: 45796 | C41: 사무용픔 | D41: Zhang Liang | E41: 21 | F41: 해외지사비 | K41: 517 | L41: =#REF! | M41: =K41/L41 | N41: =N40+H41-K41 | O41: =O40+J41-M41 | P41: 4월 송금 | S41: =S40-M41+J41
...

Sheet 2026-06
B2: ▶ 00년 00월 전도금 정산 내역 (심천지사)_4000061 (B2F590) | H2: 보증금 입금 내역_1,234.5 (#1900000828 / #1200000234 / #100013313)
B3: 00년 00월 송금_1405.60 (#) | F3: 1405.6 | H3: 00년 00월 송금_1358.90 (#) | L3: 1358.9
B4: 대계정 | C4: 소계정 | D4: 금액 (CNY) | E4: 금액 (USD) | F4: 금액 (KRW) | H4: 대계정 | I4: 소계정 | J4: 금액 (CNY) | K4: 금액 (USD) | L4: 금액 (KRW)
A5: 51131050 | B5: 업무추진비 | C5: 일반 | F5: =ROUND(E5*$F$3,0) | H5: 업무추진비 | I5: 일반 | L5: =ROUND(K5*$L$3,0) | S5: =F5+L5+R5
A6: 51061030 | B6: 여비교통비 | C6: 해외 | F6: =ROUND(E6*$F$3,0) | H6: 여비교통비 | I6: 해외 | L6: =ROUND(K6*$L$3,0) | S6: =F6+L6+R6
A7: 51201020 | B7: 지급임차료 | C7: 사무실임차료 | F7: =ROUND(E7*$F$3,0) | H7: 지급임차료 | I7: 사무실임차료 | L7: =ROUND(K7*$L$3,0) | S7: =F7+L7+R7
A8: 51201030 | B8: 지급임차료 | C8: 차량임차료 | F8: =ROUND(E8*$F$3,0) | H8: 지급임차료 | I8: 차량임차료 | L8: =ROUND(K8*$L$3,0) | S8: =F8+L8+R8
A9: 51071700 | B9: 통신비 | C9: 기타 | F9: =ROUND(E9*$F$3,0) | H9: 통신비 | I9: 기타 | L9: =ROUND(K9*$L$3,0)
A10: 51321010 | B10: 해외지사비 | F10: =ROUND(E10*$F$3,0) | H10: 해외지사비 | L10: =ROUND(K10*$L$3,0)
B11: 세금과공과 | C11: 기타 | F11: =ROUND(E11*$F$3,0) | H11: 세금과공과 | I11: 기타 | L11: =ROUND(K11*$L$3,0)
A12: 51031020 | B12: 급여(incentive) | C12: 성과급여조정 | G12: =G14/G13 | H12: 급여(incentive) | I12: 포상금 | L12: =ROUND(K12*$L$3,0)
A13: 52981010 | B13: (-)잡이익(50) | C13: (-)잡이익 | F13: =ROUND(E13*$F$3,0) | G13: =E14+R14+U14 | H13: (-)잡이익(50) | I13: (-)잡이익 | L13: =ROUND(K13*$L$3,0)
B14: Total | D14: =SUM(D5:D12)-D13 | E14: =SUM(E5:E12)-E13 | F14: =SUM(F5:F12)-F13 | G14: =F14+#REF!+V14 | H14: Total | J14: =SUM(J5:J12)-J13 | K14: =SUM(K5:K12)-K13 | L14: =SUM(L5:L12)-L13
J15: =J14-J13 | K15: =K14-K13 | L15: =L14-L13
I18: =SUBTOTAL(9,J21:J96) | K18: =SUBTOTAL(9,L21:L96) | L18: =SUBTOTAL(9,M21:M96) | M18: =SUBTOTAL(9,O21:O109) | N18: =SUBTOTAL(9,O21:O96)
B19: 날짜 | E19: 내역 | F19: 담당자 | G19: 증빙번호 | H19: 대계정 | I19: 소계정 | J19: 입금 | M19: 출금 | P19: 잔액 | R19: 비고 | S19: 시스템 판독
B20: 출금일자 | C20: 증빙일자 | D20: 증빙번호(FULL) | E20: 내역 | F20: 담당자 | G20: 증빙번호 | H20: 대계정 | I20: 소계정 | J20: CNY | K20: 환산요율 | L20: USD | M20: CNY | N20: 환산요율 | O20: USD | P20: CNY | Q20: USD | R20: 비고 | S20: 시스템 판독
Q21: 0
B22: 2026-06-18 | C22: 2026-06-15 | D22: 26512000002507455621 | E22: 교통비/톨비 | F22: Lin Wei Jian | G22: 1 | H22: 여비교통비 | I22: 교통비 | M22: 1804 | N22: ='통장내역(환율표)'!$D$88 | O22: =M22/N22 | P22: =P21+J22-M22 | Q22: =Q21+L22-O22 | S22: 파표 회사코드 일치
B23: 2026-06-18 | C23: 2026-06-15 | D23: 26442000006669013351 | E23: 교통비/톨비 | F23: Lin Wei Jian | G23: 2 | H23: 여비교통비 | I23: 교통비 | M23: 1824 | N23: ='통장내역(환율표)'!$D$88 | O23: =M23/N23 | P23: =P22+J23-M23 | Q23: =Q22+L23-O23 | S23: 파표 회사코드 일치
B24: 2026-06-18 | C24: 2026-06-15 | D24: 26442000006669091216 | E24: 교통비/톨비 | F24: Lin Wei Jian | G24: 3 | H24: 여비교통비 | I24: 교통비 | M24: 1359 | N24: ='통장내역(환율표)'!$D$88 | O24: =M24/N24 | P24: =P23+J24-M24 | Q24: =Q23+L24-O24 | S24: 파표 회사코드 일치
B25: 2026-06-18 | C25: 2026-06-15 | D25: 26442000006668490571 | E25: 교통비/톨비 | F25: Lin Wei Jian | G25: 4 | H25: 여비교통비 | I25: 교통비 | M25: 1374 | N25: ='통장내역(환율표)'!$D$88 | O25: =M25/N25 | P25: =P24+J25-M25 | Q25: =Q24+L25-O25 | S25: 파표 회사코드 일치
B26: 2026-06-18 | E26: 톨비 | F26: Lin Wei Jian | G26: 5 | H26: 여비교통비 | I26: 교통비 | M26: 543.5 | N26: ='통장내역(환율표)'!$D$88 | O26: =M26/N26 | P26: =P25+J26-M26 | Q26: =Q25+L26-O26
B27: 2026-06-18 | C27: 2026-06-12 | D27: 151002565028 | E27: 톨비 | F27: Lin Wei Jian | G27: 6 | H27: 여비교통비 | I27: 교통비 | M27: 124 | N27: ='통장내역(환율표)'!$D$88 | O27: =M27/N27 | P27: =P26+J27-M27 | Q27: =Q26+L27-O27 | S27: 파표 회사코드 불일치/누락
B28: 2026-06-18 | C28: 2026-06-11 | D28: 26952000002433520066 | E28: 교통비/톨비 | F28: Lin Wei Jian | G28: 7 | H28: 여비교통비 | I28: 교통비 | M28: 880 | N28: ='통장내역(환율표)'!$D$88 | O28: =M28/N28 | P28: =P27+J28-M28 | Q28: =Q27+L28-O28 | S28: 파표 회사코드 일치
B29: 2026-06-18 | C29: 2026-06-15 | D29: 26517000000466701406 | E29: 교통비 | F29: Lin Wei Jian | G29: 8 | H29: 여비교통비 | I29: 교통비 | M29: 394.5 | N29: ='통장내역(환율표)'!$D$88 | O29: =M29/N29 | P29: =P28+J29-M29 | Q29: =Q28+L29-O29 | S29: 파표 회사코드 일치
B30: 2026-06-18 | C30: 2026-06-15 | D30: 26957000000165619116 | E30: 교통비 | F30: Lin Wei Jian | G30: 9 | H30: 여비교통비 | I30: 교통비 | M30: 589.9 | N30: ='통장내역(환율표)'!$D$88 | O30: =M30/N30 | P30: =P29+J30-M30 | Q30: =Q29+L30-O30 | S30: 파표 회사코드 일치
B31: 2026-06-18 | C31: 2026-06-15 | D31: 26447000001222315056 | E31: 교통비 | F31: Lin Wei Jian | G31: 10 | H31: 여비교통비 | I31: 교통비 | M31: 887.8 | N31: ='통장내역(환율표)'!$D$88 | O31: =M31/N31 | P31: =P30+J31-M31 | Q31: =Q30+L31-O31 | S31: 파표 회사코드 일치
B32: 2026-06-18 | C32: 2026-06-15 | D32: 26127000000304975197 | E32: 교통비 | F32: Lin Wei Jian | G32: 11 | H32: 여비교통비 | I32: 교통비 | M32: 81.2 | N32: ='통장내역(환율표)'!$D$88 | O32: =M32/N32 | P32: =P31+J32-M32 | Q32: =Q31+L32-O32 | S32: 파표 회사코드 일치
B33: 2026-06-18 | C33: 2026-06-15 | D33: 45212619 | E33: 화물운송료 | F33: Lin Wei Jian | G33: 12 | H33: 해외지사비 | I33: 운반비 | M33: 132.36 | N33: ='통장내역(환율표)'!$D$88 | O33: =M33/N33 | P33: =P32+J33-M33 | Q33: =Q32+L33-O33 | S33: 파표 회사코드 일치
B34: 2026-06-18 | C34: 2026-06-15 | D34: 26957000000162960397 | E34: 교통비/톨비 | F34: Lin Wei Jian | G34: 13 | H34: 여비교통비 | I34: 교통비 | M34: 300 | N34: ='통장내역(환율표)'!$D$88 | O34: =M34/N34 | P34: =P33+J34-M34 | Q34: =Q33+L34-O34 | S34: 파표 회사코드 불일치/누락
B35: 2026-06-18 | C35: 2026-06-15 | D35: 26327000001122217547 | E35: 교통비/톨비 | F35: Lin Wei Jian | G35: 14 | H35: 여비교통비 | I35: 교통비 | M35: 1073 | N35: ='통장내역(환율표)'!$D$88 | O35: =M35/N35 | P35: =P34+J35-M35 | Q35: =Q34+L35-O35 | S35: 파표 회사코드 일치
B36: 2026-06-18 | C36: 2026-06-15 | D36: 26327000001119045774 | E36: 교통비/톨비 | F36: Lin Wei Jian | G36: 15 | H36: 여비교통비 | I36: 교통비 | M36: 40 | N36: ='통장내역(환율표)'!$D$88 | O36: =M36/N36 | P36: =P35+J36-M36 | Q36: =Q35+L36-O36 | S36: 파표 회사코드 일치
B37: 2026-06-18 | C37: 2026-06-15 | D37: 26327000001122217548 | E37: 교통비/톨비 | F37: Lin Wei Jian | G37: 16 | H37: 여비교통비 | I37: 교통비 | M37: 63 | N37: ='통장내역(환율표)'!$D$88 | O37: =M37/N37 | P37: =P36+J37-M37 | Q37: =Q36+L37-O37 | S37: 파표 회사코드 일치
B38: 2026-06-18 | C38: 2026-06-05 | D38: 26957000000141421480 | E38: 교통비/톨비 | F38: Lin Wei Jian | G38: 17 | H38: 여비교통비 | I38: 교통비 | M38: 176 | N38: ='통장내역(환율표)'!$D$88 | O38: =M38/N38 | P38: =P37+J38-M38 | Q38: =Q37+L38-O38 | S38: 파표 회사코드 일치
... B42: 2026-06-18 | C42: 2026-06-15 | D42: 26957000000150278611 | E42: 교통비/톨비 | F42: Lin Wei Jian | G42: 21 | H42: 여비교통비 | I42: 교통비 | M42: 378 | N42: ='통장내역(환율표)'!$D$88 | O42: =M42/N42 | P42: =P41+J42-M42 | Q42: =Q41+L42-O42 | S42: 파표 회사코드 일치
B43: 2026-06-18 | C43: 2026-06-08 | E43: 교통비 | F43: Lin Wei Jian | G43: 22 | H43: 여비교통비 | I43: 교통비 | M43: 386.4 | N43: ='통장내역(환율표)'!$D$88 | O43: =M43/N43 | P43: =P42+J43-M43 | Q43: =Q42+L43-O43
B44: 2026-06-18 | C44: 2026-05-22 | E44: 교통비 | F44: Lin Wei Jian | G44: 23 | H44: 여비교통비 | I44: 교통비 | M44: 303.3 | N44: ='통장내역(환율표)'!$D$88 | O44: =M44/N44 | P44: =P43+J44-M44 | Q44: =Q43+L44-O44
B45: 2026-06-18 | C45: 2026-06-07 | E45: 교통비 | F45: Lin Wei Jian | G45: 24 | H45: 여비교통비 | I45: 교통비 | M45: 390.4 | N45: ='통장내역(환율표)'!$D$88 | O45: =M45/N45 | P45: =P44+J45-M45 | Q45: =Q44+L45-O45
B46: 2026-06-18 | C46: 2026-06-18 | E46: 은행수수료 | F46: Lin Wei Jian | G46: 25 | H46: 해외지사비 | M46: 7.2 | N46: ='통장내역(환율표)'!$D$88 | O46: =M46/N46 | P46: =P45+J46-M46 | Q46: =Q45+L46-O46 | S46: [불일치 (이체:12405.76 vs 영수증:13676.359999999999)]

Sheet 통장지급내역

Sheet 당월 업무추진비
B2: ▶ 업무추진비 사용 내역
B4: NO | C4: 정산일자 | D4: 사용일자 | E4: 사용자 | F4: 사용처 | G4: 사용금액 | I4: 사용목적(상세 기재) | J4: 고객명 | K4: 참석자
G5: RMB | H5: KRW | K5: 고객 | L5: DBGC
B6: =ROW()-5 | D6: 46133 | E6: xiongfeng | F6: 大师兄餐饮 | G6: 135 | I6: Have coffee with SDPC | J6: SDPC | K6: 魏慧 | L6: xiongfeng/金总
B7: =ROW()-5 | D7: 46134 | E7: xiongfeng | F7: 星巴克 | G7: 68 | I7: Coffee with CSOT | J7: CSOT | K7: 裴娟实 | L7: xiongfeng
B8: =ROW()-5 | D8: 46149 | E8: xiongfeng | F8: 星莹美食店 | G8: 370 | I8: Lunch with CSOT | J8: CSOT | K8: 裴娟实/彩霞 | L8: xiongfeng
B9: =ROW()-5 | D9: 46151 | E9: xiongfeng | F9: 萍乡土菜 | G9: 233 | I9: Lunch with FITI | J9: SDPC | K9: 牛佳兴 | L9: xiongfeng
B10: =ROW()-5 | D10: 46118 | E10: 신순연 | F10: 晶东 | G10: 258 | I10: 고객 업무 추진 및 CRM 유지 | J10: CSOT | K10: Li Xiang Yu | L10: -
B11: =ROW()-5 | D11: 46119 | E11: 신순연 | F11: 郭老二 | G11: 873 | I11: 고객 업무 추진 및 CRM 유지 | J11: TianMa | K11: Mason전문가, Eddie전문가 | L11: 고재홍 상무, 최상신 전문위원, 김기일 프로, 박상현 프로, 황대욱 프로, 변승찬 프로, 권유석 지사장, 김명관 프로, 신순연 프로
B12: =ROW()-5 | D12: 46120 | E12: 신순연 | F12: 韩庭 | G12: 402 | I12: 고객 업무 추진 및 CRM 유지 | J12: TianMa | K12: Mason전문가, Eddie전문가 | L12: 고재홍 상무, 최상신 전문위원, 김기일 프로, 박상현 프로, 황대욱 프로, 변승찬 프로, 신순연 프로
B13: =ROW()-5 | D13: 46120 | E13: 신순연 | F13: 鱼头泡饭 | G13: 800 | I13: 고객 업무 추진 및 CRM 유지 | J13: CSOT | K13: Pan Xiao Dong과장 | L13: 고재홍 상무, 최상신 전문위원, 김기일 프로, 박상현 프로, 황대욱 프로, 변승찬 프로, 신순연 프로
B14: =ROW()-5 | D14: 46128 | E14: 신순연 | F14: 京华楼 | G14: 297 | I14: 고객 업무 추진 및 CRM 유지 | J14: CSOT | K14: Nate전문가 | L14: 권유석 지사장, 이상태 프로, 박미령 프로, Xiong Feng프로, 신순연 프로
B15: =ROW()-5 | D15: 46150 | E15: 신순연 | F15: 河坝 | G15: 693 | I15: 고객 업무 추진 및 CRM 유지 | J15: CSOT | K15: Liu Kai Yu, Jiang Song Lin(대리점) | L15: Zhang Liang, Lin Wei Jian, 신순연
B16: =ROW()-5 | D16: 3월26일 | E16: 권유석 | F16: 스.벅 | G16: 60 | I16: 음료 | J16: CSOT | K16: 조달구매 | L16: 권유석/정겨운
B17: =ROW()-5 | D17: 3월26일 | E17: 권유석 | F17: 소풍 | G17: 281 | I17: 석식 | J17: CSOT | K17: 조달구매 | L17: 권유석/정겨운
B18: =ROW()-5 | D18: 3월31일 | E18: 권유석 | F18: 홍콩반점 | G18: 315 | I18: 석식 | J18: SDC | K18: 구매(신우철 부장) | L18: 권유석/정겨운
B19: =ROW()-5 | D19: 4월2일 | E19: 권유석 | F19: 세븐일레븐 | G19: 100.7 | I19: 음료 | J19: CSOT | K19: 영업/KA | L19: 권유석/신순연
B20: =ROW()-5 | D20: 4월3일 | E20: 권유석 | F20: 홍콩반점 | G20: 255 | I20: 석식 | J20: BOE | K20: 김문청 사장 | L20: 권유석
B21: =ROW()-5 | D21: 4월17일 | E21: 권유석 | F21: 홍콩반점 | G21: 307.8 | I21: 석식 | J21: BOE | K21: 김청길 사장(MTK 대리점) | L21: 권유석
B22: =ROW()-5 | D22: 4월21일 | E22: 권유석 | F22: 전통 찻집 | G22: 260 | I22: 음료 | J22: ESWIN | K22: 구매 책임자/담당자 | L22: 권유석/정겨운
B23: =ROW()-5 | D23: 4월21일 | E23: 권유석 | F23: 订餐卡 | G23: 674 | I23: 중식 | J23: ESWIN | K23: 구매 책임자/담당자 | L23: 권유석/정겨운
B24: =ROW()-5 | D24: 4월21일 | E24: 권유석 | F24: 스타벅스 | G24: 103 | I24: 음료 | J24: ESWIN | K24: 구매 책임자/담당자 | L24: 권유석/정겨운
B25: =ROW()-5 | D25: 46132 | E25: PIAO MEILING | F25: 同盛餐饮 | G25: 246 | I25: CSOT 업무 추진 | J25: CSOT | K25: Liu Wei, Yu Han | L25: 박미령
B26: =ROW()-5 | D26: 46149 | E26: PIAO MEILING | F26: 爱人餐饮 | G26: 140 | I26: CSOT 업무 추진 | J26: CSOT | K26: Fan Xiankun, Yu Han | L26: 박미령
B27: =ROW()-5 | D27: 46109 | E27: zhangliang | F27: SDPC便利店 | G27: 36.04 | I27: SDPC업무 추진 | J27: SDPC | K27: 孙志强 | L27: zhangliang
B28: =ROW()-5 | D28: 46156 | E28: zhangliang | F28: 印尼餐厅 | G28: 1016.12 | I28: HKC업무 추진 | J28: HKC | K28: DK Park、Eddie等 | L28: zhangliang、shenshunyan
B29: =ROW()-5 | D29: 46134 | E29: zhangliang | F29: H1水果店 | G29: 58 | I29: HKC업무 추진 | J29: HKC | K29: 费如涵、陈杰 | L29: zhangliang
B30: =ROW()-5
B31: =ROW()-5
B32: =ROW()-5
B33: =ROW()-5
B34: =ROW()-5
B35: =ROW()-5
B36: =ROW()-5
B37: =ROW()-5
B38: =ROW()-5
B39: =ROW()-5
B40: =ROW()-5
B41: =ROW()-5
... B46: =ROW()-5
...

Sheet 기사 야근 일지
C3: Liu Ming Liang | J3: chen guo liang | Q3: chen feng jun
C4: 일자 | D4: 내용 | E4: 인원 | F4: 시간 | G4: 비용 | H4: 비고 | J4: 일자 | K4: 내용 | L4: 인원 | M4: 시간 | N4: 비용 | O4: 비고 | Q4: 일자 | R4: 내용 | S4: 인원 | T4: 시간 | U4: 비용 | V4: 비고
C5: 46134 | E5: 심천지사 | F5: 6 | G5: =F5*20 | J5: 46135 | L5: 심천지사 | M5: 4 | N5: =M5*20 | Q5: 46134 | S5: 심천지사 | T5: 1 | U5: =T5*20
C6: 46135 | E6: 심천지사 | F6: 3.5 | G6: =F6*20 | J6: 46139 | L6: 심천지사 | M6: 4 | N6: =M6*20 | Q6: 46135 | S6: 심천지사 | T6: 2 | U6: =T6*20
C7: 46136 | E7: 심천지사 | F7: 6.5 | G7: =F7*20 | J7: 46149 | L7: 심천지사 | M7: 3 | N7: =M7*20 | Q7: 46139 | S7: 심천지사 | T7: 3 | U7: =T7*20
C8: 46139 | E8: 심천지사 | F8: 3 | G8: =F8*20 | J8: 46150 | L8: 심천지사 | M8: 3 | N8: =M8*20 | Q8: 46140 | S8: 심천지사 | T8: 1 | U8: =T8*20
C9: 46142 | E9: 심천지사 | F9: 1 | G9: =F9*20 | J9: 46155 | L9: 심천지사 | M9: 5 | N9: =M9*20 | Q9: 46154 | S9: 심천지사 | T9: 3 | U9: =T9*20
C10: 46150 | E10: 심천지사 | F10: 5 | G10: =F10*20 | J10: 46158 | L10: 심천지사 | M10: 16 | N10: =M10*20 | Q10: 46158 | S10: 심천지사 | T10: 5 | U10: =T10*20
C11: 46153 | E11: 심천지사 | F11: 1 | G11: =F11*20 | J11: 46159 | L11: 심천지사 | M11: 3 | N11: =M11*20 | S11: 심천지사 | U11: =T11*20
C12: 46156 | E12: 심천지사 | F12: 3 | G12: =F12*20 | L12: 심천지사 | N12: =M12*20 | S12: 심천지사 | U12: =T12*20
E13: 심천지사 | G13: =F13*20 | L13: 심천지사 | N13: =M13*20 | S13: 심천지사 | U13: =T13*20
E14: 심천지사 | G14: =F14*20 | L14: 심천지사 | N14: =M14*20 | S14: 심천지사 | U14: =T14*20
E15: 심천지사 | G15: =F15*20 | L15: 심천지사 | N15: =M15*20 | S15: 심천지사 | U15: =T15*20
E16: 심천지사 | G16: =F16*20 | L16: 심천지사 | N16: =M16*20 | S16: 심천지사 | U16: =T16*20
E17: 심천지사 | G17: =F17*20 | L17: 심천지사 | N17: =M17*20 | S17: 심천지사 | U17: =T17*20
E18: 심천지사 | G18: =F18*20 | L18: 심천지사 | N18: =M18*20 | S18: 심천지사 | U18: =T18*20
E19: 심천지사 | G19: =F19*20 | L19: 심천지사 | N19: =M19*20 | S19: 심천지사 | U19: =T19*20
E20: 심천지사 | G20: =F20*20 | L20: 심천지사 | N20: =M20*20 | S20: 심천지사 | U20: =T20*20
E21: 심천지사 | G21: =F21*20 | L21: 심천지사 | N21: =M21*20 | S21: 심천지사 | U21: =T21*20
E22: 심천지사 | G22: =F22*20 | L22: 심천지사 | N22: =M22*20 | S22: 심천지사 | U22: =T22*20
E23: 심천지사 | G23: =F23*20 | L23: 심천지사 | N23: =M23*20 | S23: 심천지사 | U23: =T23*20
G24: =SUM(G5:G23) | N24: =SUM(N5:N23) | U24: =SUM(U5:U23)
